Workbook

Sheet Hypotheses
B1: DEBOURSE SEC - DALOTS PROJET CAFE-CACAO (BANGOLO - BLOLEKIN)
B2: Travaux de reprofilage lourd et de traitement de points critiques de routes rurales - Regions du Guemon et du Cavally | Maitre d'ouvrage : Conseil Cafe-Cacao
B4: A. CARACTERISTIQUES GEOMETRIQUES (source : Notes de calcul et Plans d'execution)
B5: Parametre | C5: Dalot 2,00 x 2,00 | D5: Dalot 3,00 x 2,00 | E5: Unite
B6: Ouverture libre par cellule (l0) | C6: 2 | D6: 3 | E6: m
B7: Hauteur libre de la cellule (h0) | C7: 2 | D7: 2 | E7: m
B8: Epaisseur du tablier | C8: 0.25 | D8: 0.3 | E8: m
B9: Epaisseur du radier | C9: 0.25 | D9: 0.3 | E9: m
B10: Epaisseur des piedroits | C10: 0.2 | D10: 0.25 | E10: m
B11: Epaisseur des murs en aile | C11: 0.25 | D11: 0.2 | E11: m
B12: Longueur du corps (sens de l'ecoulement) | C12: 7 | D12: 7 | E12: m
B13: Largeur de chaussee portee | C13: 6.5 | D13: 6.5 | E13: m
B14: Longueur d'un mur en aile | C14: 3.4 | D14: 3.45 | E14: m
B15: Surface d'un mur en aile (relevee/estimee en plan) | C15: 5 | D15: 5.1 | E15: m2
B16: Nombre de murs en aile (2 tetes x 2 ailes) | C16: 4 | D16: 4 | E16: u
B17: Hauteur d'eau normale (crue de projet T=10 ans) | C17: 1.33 | D17: 1.42 | E17: m
B18: Epaisseur remblai + couche de forme sur tablier | C18: 0.6 | D18: 0.6 | E18: m
B20: Largeur structure du corps (l0 + 2 x e_piedroit) - calculee | C20: =C6+2*C10 | D20: =D6+2*D10 | E20: m
B22: B. QUANTITES STRUCTURELLES - BETON ARME ET ACIERS (donnees exactes tirees des plans d'execution)
B23: Element (Nomenclature des aciers / Grille tete) | C23: Dalot 2,00 x 2,00 | D23: Dalot 3,00 x 2,00 | E23: Unite
B24: Beton arme - Corps (tablier + piedroits + radier) | C24: 14 | D24: 21.7 | E24: m3
B25: Beton arme - Tetes (murs en aile + becheS + ferraillage tete) | C25: 13.01 | D25: 15.59 | E25: m3
B26: BETON ARME - TOTAL OUVRAGE | C26: =C24+C25 | D26: =D24+D25 | E26: m3
B27: Aciers HA Fe E500 - Corps | C27: 1529.08 | D27: 2220.148 | E27: kg
B28: Aciers HA Fe E500 - Tetes | C28: 1639.92 | D28: 2020.73 | E28: kg
B29: ACIERS HA - TOTAL OUVRAGE | C29: =C27+C28 | D29: =D27+D28 | E29: kg
B30: Ratio acier / beton (indicatif, cf. plans) | C30: =C29/C26 | D30: =D29/D26 | E30: kg/m3
B32: C. COEFFICIENTS D'ESTIMATION - OUVRAGES ANNEXES (hypotheses d'avant-metre, ajustables)
B33: Coefficient | C33: Valeur | E33: Unite
B34: Epaisseur beton de proprete | C34: 0.1 | E34: m
B35: Largeur moyenne de semelle/pied de mur en aile (~ e_aile) | C35: 0.3 | E35: m
B36: Majoration fouille (irregularites terrain, sur-largeur de travail) | C36: 0.15 | E36: %
B37: Rehausse de fouille pour reglage d'assise (au-dela beton proprete) | C37: 0.2 | E37: m
B38: Coefficient de coffrage (surface coffree par m3 de beton) | C38: 3.2 | E38: m2/m3
B39: Facteur de longueur de protection aval/amont (x hauteur d'eau) | C39: 3 | E39: x h
B40: Epaisseur perre maconne / enrochement | C40: 0.3 | E40: m
B41: Facteur longueur de garde-corps (2 cotes de chaussee) | C41: 2 | E41: x L corps
B43: Largeur moyenne de protection amont/aval | C43: 4.5 | D43: 5.5 | E43: m
B45: NOTE IMPORTANTE : les quantites de la partie D (metre calcule) pour les postes 'ouvrages annexes' (fouilles, beton de proprete, coffrages, remblai technique, protection aval/amont, garde-corps) sont des ESTIMATIONS parametriques etablies a partir de la geometrie des plans d'execution et des coefficients ci-dessus. Elles doivent etre verifiees/affinees par un metre detaille (plans de coffrage complets, profils en travers, reconnaissance geotechnique) avant contractualisation. Les quantites de BETON ARME et d'ACIERS (partie B) sont en revanche des valeurs EXACTES tirees telles quelles des nomenclatures d'acier et cartouches de volume des plans d'execution fournis.
B50: D. METRE CALCULE - QUANTITES PAR OUVRAGE (formules)
...

Sheet DS - Dalot 2.00x2.00
B1: DEBOURSE SEC - DALOT 2,00 x 2,00
B2: Route Bangolo - Bloleguin | Projet Cafe-Cacao | Ouvrage de franchissement hydraulique (dalot-cadre en beton arme)
B5: N° | C5: Designation | D5: Unite | E5: Quantite | F5: Prix Unitaire | G5: Montant (FCFA)
B6: CHAPITRE 1 - INSTALLATION ET PREPARATION DE CHANTIER
B7: 1 | C7: Installation generale de chantier (base-vie, amenee/repli materiel) | D7: Ft | E7: 1 | F7: 500000 | G7: =E7*F7
B8: 2 | C8: Implantation et piquetage topographique de l'ouvrage | D8: Ft | E8: 1 | F8: 150000 | G8: =E8*F8
B9: 3 | C9: Signalisation temporaire et deviation provisoire de chantier | D9: Ft | E9: 1 | F9: 150000 | G9: =E9*F9
B10: SOUS-TOTAL CHAPITRE 1 | G10: =SUM(G7:G9)
B12: CHAPITRE 2 - TERRASSEMENTS
B13: 4 | C13: Fouilles en pleine masse pour fondations (radier, becheS, murs en aile), toute nature de terrain | D13: m3 | E13: ='Hypotheses'!C55 | F13: 3500 | G13: =E13*F13
B14: 5 | C14: Evacuation des deblais excedentaires en depot agree | D14: m3 | E14: ='Hypotheses'!C55 | F14: 2500 | G14: =E14*F14
B15: 6 | C15: Remblai technique compacte (materiau selectionne lateritique), fourniture, mise en oeuvre et compactage par couches | D15: m3 | E15: ='Hypotheses'!C56 | F15: 6500 | G15: =E15*F15
B16: SOUS-TOTAL CHAPITRE 2 | G16: =SUM(G13:G15)
B18: CHAPITRE 3 - BETONS
B19: 7 | C19: Beton de proprete dose a 150 kg/m3 | D19: m3 | E19: ='Hypotheses'!C53 | F19: 75000 | G19: =E19*F19
B20: 8 | C20: Beton arme C25/30 (350 kg/m3) pour corps de l'ouvrage (tablier, piedroits, radier) | D20: m3 | E20: ='Hypotheses'!C24 | F20: 165000 | G20: =E20*F20
B21: 9 | C21: Beton arme C25/30 (350 kg/m3) pour tetes (murs en aile, becheS d'about) | D21: m3 | E21: ='Hypotheses'!C25 | F21: 165000 | G21: =E21*F21
B22: SOUS-TOTAL CHAPITRE 3 | G22: =SUM(G19:G21)
B24: CHAPITRE 4 - ACIERS POUR BETON ARME
B25: 10 | C25: Aciers HA Fe E500 faconnes et poses - Corps de l'ouvrage | D25: kg | E25: ='Hypotheses'!C27 | F25: 1450 | G25: =E25*F25
B26: 11 | C26: Aciers HA Fe E500 faconnes et poses - Tetes (murs en aile) | D26: kg | E26: ='Hypotheses'!C28 | F26: 1450 | G26: =E26*F26
B27: SOUS-TOTAL CHAPITRE 4 | G27: =SUM(G25:G26)
B29: CHAPITRE 5 - COFFRAGES
B30: 12 | C30: Coffrage soigne pour parements vus (tablier, piedroits, murs en aile) | D30: m2 | E30: ='Hypotheses'!C57 | F30: 12500 | G30: =E30*F30
B31: SOUS-TOTAL CHAPITRE 5 | G31: =SUM(G30:G30)
B33: CHAPITRE 6 - PROTECTION ET OUVRAGES ANNEXES
B34: 13 | C34: Perre maconne / enrochement de protection contre l'erosion (amont et aval) | D34: m2 | E34: ='Hypotheses'!C59 | F34: 18000 | G34: =E34*F34
B35: 14 | C35: Garde-corps (type, materiau et implantation a definir et valider par la Mission de Controle) | D35: ml | E35: ='Hypotheses'!C60 | F35: 45000 | G35: =E35*F35
B36: SOUS-TOTAL CHAPITRE 6 | G36: =SUM(G34:G35)
B38: CHAPITRE 7 - CONTROLES ET REPLI DE CHANTIER
B39: 15 | C39: Essais et controles qualite des betons (eprouvettes, essais laboratoire) | D39: Ft | E39: 1 | F39: 300000 | G39: =E39*F39
B40: 16 | C40: Repli de materiel et nettoyage final du site | D40: Ft | E40: 1 | F40: 250000 | G40: =E40*F40
B41: SOUS-TOTAL CHAPITRE 7 | G41: =SUM(G39:G40)
B44: TOTAL DEBOURSE SEC - DALOT 2,00 x 2,00 (HT, hors frais generaux, marge et alea) | G44: =G10+G16+G22+G27+G31+G36+G41
B46: Le Debourse Sec (DS) represente le cout direct des travaux (materiaux, main d'oeuvre, materiel) hors frais de chantier, frais generaux d'entreprise, marge beneficiaire, aleas/imprevus et TVA. Ces elements sont a ajouter lors de l'etablissement du prix de vente (bordereau des prix unitaires). Les prix unitaires (colonnes surlignees en jaune) sont indicatifs et doivent etre ajustes selon les conditions reelles du marche et le bordereau de l'entreprise.

Sheet DS - Dalot 3.00x2.00
B1: DEBOURSE SEC - DALOT 3,00 x 2,00
B2: Route Bangolo - Bloleguin | Projet Cafe-Cacao | Ouvrage de franchissement hydraulique (dalot-cadre en beton arme)
B5: N° | C5: Designation | D5: Unite | E5: Quantite | F5: Prix Unitaire | G5: Montant (FCFA)
B6: CHAPITRE 1 - INSTALLATION ET PREPARATION DE CHANTIER
B7: 1 | C7: Installation generale de chantier (base-vie, amenee/repli materiel) | D7: Ft | E7: 1 | F7: 500000 | G7: =E7*F7
B8: 2 | C8: Implantation et piquetage topographique de l'ouvrage | D8: Ft | E8: 1 | F8: 150000 | G8: =E8*F8
B9: 3 | C9: Signalisation temporaire et deviation provisoire de chantier | D9: Ft | E9: 1 | F9: 150000 | G9: =E9*F9
B10: SOUS-TOTAL CHAPITRE 1 | G10: =SUM(G7:G9)
B12: CHAPITRE 2 - TERRASSEMENTS
B13: 4 | C13: Fouilles en pleine masse pour fondations (radier, becheS, murs en aile), toute nature de terrain | D13: m3 | E13: ='Hypotheses'!D55 | F13: 3500 | G13: =E13*F13
B14: 5 | C14: Evacuation des deblais excedentaires en depot agree | D14: m3 | E14: ='Hypotheses'!D55 | F14: 2500 | G14: =E14*F14
B15: 6 | C15: Remblai technique compacte (materiau selectionne lateritique), fourniture, mise en oeuvre et compactage par couches | D15: m3 | E15: ='Hypotheses'!D56 | F15: 6500 | G15: =E15*F15
B16: SOUS-TOTAL CHAPITRE 2 | G16: =SUM(G13:G15)
B18: CHAPITRE 3 - BETONS
B19: 7 | C19: Beton de proprete dose a 150 kg/m3 | D19: m3 | E19: ='Hypotheses'!D53 | F19: 75000 | G19: =E19*F19
B20: 8 | C20: Beton arme C25/30 (350 kg/m3) pour corps de l'ouvrage (tablier, piedroits, radier) | D20: m3 | E20: ='Hypotheses'!D24 | F20: 165000 | G20: =E20*F20
B21: 9 | C21: Beton arme C25/30 (350 kg/m3) pour tetes (murs en aile, becheS d'about) | D21: m3 | E21: ='Hypotheses'!D25 | F21: 165000 | G21: =E21*F21
B22: SOUS-TOTAL CHAPITRE 3 | G22: =SUM(G19:G21)
B24: CHAPITRE 4 - ACIERS POUR BETON ARME
B25: 10 | C25: Aciers HA Fe E500 faconnes et poses - Corps de l'ouvrage | D25: kg | E25: ='Hypotheses'!D27 | F25: 1450 | G25: =E25*F25
B26: 11 | C26: Aciers HA Fe E500 faconnes et poses - Tetes (murs en aile) | D26: kg | E26: ='Hypotheses'!D28 | F26: 1450 | G26: =E26*F26
B27: SOUS-TOTAL CHAPITRE 4 | G27: =SUM(G25:G26)
B29: CHAPITRE 5 - COFFRAGES
B30: 12 | C30: Coffrage soigne pour parements vus (tablier, piedroits, murs en aile) | D30: m2 | E30: ='Hypotheses'!D57 | F30: 12500 | G30: =E30*F30
B31: SOUS-TOTAL CHAPITRE 5 | G31: =SUM(G30:G30)
B33: CHAPITRE 6 - PROTECTION ET OUVRAGES ANNEXES
B34: 13 | C34: Perre maconne / enrochement de protection contre l'erosion (amont et aval) | D34: m2 | E34: ='Hypotheses'!D59 | F34: 18000 | G34: =E34*F34
B35: 14 | C35: Garde-corps (type, materiau et implantation a definir et valider par la Mission de Controle) | D35: ml | E35: ='Hypotheses'!D60 | F35: 45000 | G35: =E35*F35
B36: SOUS-TOTAL CHAPITRE 6 | G36: =SUM(G34:G35)
B38: CHAPITRE 7 - CONTROLES ET REPLI DE CHANTIER
B39: 15 | C39: Essais et controles qualite des betons (eprouvettes, essais laboratoire) | D39: Ft | E39: 1 | F39: 300000 | G39: =E39*F39
B40: 16 | C40: Repli de materiel et nettoyage final du site | D40: Ft | E40: 1 | F40: 250000 | G40: =E40*F40
B41: SOUS-TOTAL CHAPITRE 7 | G41: =SUM(G39:G40)
B44: TOTAL DEBOURSE SEC - DALOT 3,00 x 2,00 (HT, hors frais generaux, marge et alea) | G44: =G10+G16+G22+G27+G31+G36+G41
B46: Le Debourse Sec (DS) represente le cout direct des travaux (materiaux, main d'oeuvre, materiel) hors frais de chantier, frais generaux d'entreprise, marge beneficiaire, aleas/imprevus et TVA. Ces elements sont a ajouter lors de l'etablissement du prix de vente (bordereau des prix unitaires). Les prix unitaires (colonnes surlignees en jaune) sont indicatifs et doivent etre ajustes selon les conditions reelles du marche et le bordereau de l'entreprise.

Sheet Recapitulatif Projet
B1: RECAPITULATIF PROJET - DEBOURSE SEC DES 2 DALOTS
B2: Maitre d'ouvrage : Conseil Cafe-Cacao | Projet : Travaux de reprofilage lourd et de traitement de points critiques de routes rurales - Guemon et Cavally | Itineraire : Bangolo - Bloleguin
B4: Ouvrage | C4: Localisation | D4: Debourse Sec (FCFA) | E4: Part du total
B5: Dalot simple 2,00 x 2,00 | C5: Itineraire Bangolo - Bloleguin | D5: ='DS - Dalot 2.00x2.00'!G44 | E5: =D5/D7
B6: Dalot simple 3,00 x 2,00 | C6: Itineraire Bangolo - Bloleguin | D6: ='DS - Dalot 3.00x2.00'!G44 | E6: =D6/D7
B7: TOTAL DEBOURSE SEC - 2 DALOTS (HT) | D7: =D5+D6 | E7: 100.0%
B10: REPARTITION PAR CHAPITRE (2 dalots cumules)
B11: Chapitre | D11: Montant cumule (FCFA) | E11: Part du total
B12: Chapitre 1 - Installation et preparation | D12: ='DS - Dalot 2.00x2.00'!G10+'DS - Dalot 3.00x2.00'!G10 | E12: =D12/D7
B13: Chapitre 2 - Terrassements | D13: ='DS - Dalot 2.00x2.00'!G16+'DS - Dalot 3.00x2.00'!G16 | E13: =D13/D7
B14: Chapitre 3 - Betons | D14: ='DS - Dalot 2.00x2.00'!G22+'DS - Dalot 3.00x2.00'!G22 | E14: =D14/D7
B15: Chapitre 4 - Aciers pour beton arme | D15: ='DS - Dalot 2.00x2.00'!G27+'DS - Dalot 3.00x2.00'!G27 | E15: =D15/D7
B16: Chapitre 5 - Coffrages | D16: ='DS - Dalot 2.00x2.00'!G31+'DS - Dalot 3.00x2.00'!G31 | E16: =D16/D7
B17: Chapitre 6 - Protection et ouvrages annexes | D17: ='DS - Dalot 2.00x2.00'!G36+'DS - Dalot 3.00x2.00'!G36 | E17: =D17/D7
B18: Chapitre 7 - Controles et repli de chantier | D18: ='DS - Dalot 2.00x2.00'!G41+'DS - Dalot 3.00x2.00'!G41 | E18: =D18/D7
B20: Le Debourse Sec exclut les frais de chantier generaux, les frais generaux d'entreprise, la marge beneficiaire, les aleas/imprevus et la TVA. Pour obtenir le prix de vente (BPU), appliquer les coefficients habituels de l'entreprise (frais generaux + marge, generalement 15 a 25% selon le contexte) sur ce Debourse Sec.
