Workbook

Sheet ACCUEIL
A1: QUANTITATIF – ESTIMATION – ESQUISSES : BÂTIMENT INDUSTRIEL EN CHARPENTE MÉTALLIQUE
B2: Charpente : EC3 / EC1 (vent, sans neige) · Béton armé et fondations : BAEL 91 mod. 99 / EC2 · Contexte : Côte d'Ivoire – sol latéritique, climat tropical humide · Monnaie : FCFA · TVA 18 %
B4: MODE D'EMPLOI : 1) choisir un gabarit ci-dessous ; 2) ajuster les cellules JAUNES de PARAMÈTRES ; 3) lire les résultats ici, dans le DQE et dans PLANS.
B6: GABARIT (portée × longueur) | D6: 20 × 40 | E6: ← liste déroulante (PERSONNALISÉ : dimensions dans PARAMÈTRES)
B7: Légende : cellule jaune = saisie ; cellule bleu clair = résultat ; rouge = contrôle en alerte
B9: Résumé | D9: Valeur | E9: Unité
B10: Portée | D10: ='PARAMÈTRES'!$C$9 -> 20 | E10: m
B11: Longueur | D11: ='PARAMÈTRES'!$C$10 -> 40 | E11: m
B12: Hauteur sous sablière | D12: ='PARAMÈTRES'!$C$11 -> 6 | E12: m
B13: Hauteur au faîtage | D13: ='PRÉDIMENSIONNEMENT'!$C$34 -> 7.6 | E13: m
B14: Pente | D14: ='PARAMÈTRES'!$C$12 -> 0.16 | E14: %
B15: Système structurel | D15: ='PRÉDIMENSIONNEMENT'!$C$26 -> Portique IPE avec jarrets
B16: Nombre de portiques | D16: ='PRÉDIMENSIONNEMENT'!$C$29 -> 8 | E16: u
B17: Type de façade | D17: ='PARAMÈTRES'!$C$51 -> Bardage bac acier
B18: SURFACE COUVERTE | D18: ='PRÉDIMENSIONNEMENT'!$C$46 -> 800 | E18: m²
B19: TONNAGE ACIER CHARPENTE | D19: ='QUANTITATIF_CHARPENTE'!$I$77 -> 25.987835 | E19: t
B20: Ratio acier | D20: ='QUANTITATIF_CHARPENTE'!$I$78 -> 32.484794 | E20: kg/m²
B21: Tôles de couverture | D21: ='QUANTITATIF_CHARPENTE'!$E$36 -> 816.56792 | E21: m²
B22: BÉTON (propreté + armé) | D22: ='GROS_ŒUVRE'!$E$98 -> 188.0365 | E22: m³
B23: Aciers HA | D23: ='GROS_ŒUVRE'!$I$109 -> 6214.2789 | E23: kg
B24: COÛT TOTAL HT | D24: ='DQE_DEVIS'!$G$64 -> 94639719 | E24: FCFA
B25: TVA 18 % | D25: ='DQE_DEVIS'!$G$65 -> 17035149 | E25: FCFA
B26: COÛT TOTAL TTC | D26: ='DQE_DEVIS'!$G$66 -> 1.1167487e+08 | E26: FCFA
B27: Coût HT au m² | D27: ='DQE_DEVIS'!$G$67 -> 118299.65 | E27: FCFA/m²
B29: Contrôles automatiques
B30: =IF(AND('PARAMÈTRES'!$C$9>30,'PARAMÈTRES'!$C$21="Non"),"ALERTE : portée > 30 m sans poteau intermédiaire – prévoir une file centrale (indispensable au-delà de 40 m sans appui)","OK : portée / appuis") -> OK : portée / appuis
B31: =IF('PARAMÈTRES'!$C$12<0.05,"ALERTE : pente < 5 % – risque de stagnation, revoir la pente","OK : pente ≥ 5 %") -> OK : pente ≥ 5 %
B32: =IF(AND('PARAMÈTRES'!$C$114="15 cm",'PARAMÈTRES'!$C$115="Nappe double"),"ALERTE : dallage 15 cm en nappe double (peu courant)","OK : dallage / ferraillage") -> OK : dallage / ferraillage
B33: =IF(OR('QUANTITATIF_CHARPENTE'!$I$78<18,'QUANTITATIF_CHARPENTE'!$I$78>45),"ALERTE : ratio acier "&FIXED('QUANTITATIF_CHARPENTE'!$I$78,1,TRUE)&" kg/m² hors fourchette 18–45","OK : ratio acier "&FIXED('QUANTITATIF_CHARPENTE'!$I$78,1,TRUE)&" kg/m²") -> OK : ratio acier 32.5 kg/m²
B34: =IF('PARAMÈTRES'!$C$47<0.4,"ALERTE : tôle < 0,40 mm","OK : épaisseur de tôle") -> OK : épaisseur de tôle
B36: Feuilles : PARAMÈTRES (saisies) · BASE_PROFILÉS / BASE_ACIERS (poids) · PRÉDIMENSIONNEMENT · QUANTITATIF_CHARPENTE · GROS_ŒUVRE · DQE_DEVIS · RÉCAP_GABARITS · PLANS (7 esquisses dynamiques).
B37: Les esquisses sont des graphiques Nuage de points alimentés par la feuille masquée COORD_PLANS : aucune macro, compatible Excel mobile (Microsoft 365).
B38: Classeur entièrement modifiable (aucune protection). Saisir de préférence dans les cellules jaunes : les autres cellules contiennent les formules de calcul.
B39: PDF des plans : feuille PLANS > Fichier > Enregistrer sous > PDF, ou générateur Generateur_Plans.html (coller le CODE PLANS ci-dessous puis « Enregistrer en PDF ».
B40: Estimation de prédimensionnement : à confirmer par une note de calcul (EC3 / EC1 / BAEL) avant exécution.
B42: CODE PLANS (copier la cellule D ci-contre et la coller dans Generateur_Plans.html) | D42: ="PLAN1"&";gab="&'ACCUEIL'!$D$6&";B="&FIXED('PARAMÈTRES'!$C$9,4,TRUE)&";L="&FIXED('PARAMÈTRES'!$C$10,4,TRUE)&";H="&FIXED('PARAMÈTRES'!$C$11,4,TRUE)&";p="&FIXED('PARAMÈTRES'!$C$12*100,4,TRUE)&";ep="&FIXED('PARAMÈTRES'!$C$15,4,TRUE)&";epan="&FIXED('PARAMÈTRES'!$C$16,4,TRUE)&";elis="&FIXED('PARAMÈTRES'!$C$17,4,TRUE)&";epp="&FIXED('PARAMÈTRES'!$C$18,4,TRUE)&";deb="&FIXED('PARAMÈTRES'!$C$19,4,TRUE)&";sys="&'PARAMÈTRES'!$C$20&";fint="&'PARAMÈTRES'!$C$21&";rtr="&FIXED('PARAMÈTRES'!$C$22,4,TRUE)&";pas="&FIXED('PARAMÈTRES'!$C$23,4,TRUE)&";rj="&FIXED('PARAMÈTRES'!$C$24*100,4,TRUE)&";nacc="&FIXED('PARAMÈTRES'!$C$25,4,TRUE)&";ppot="&'PRÉDIMENSIONNEMENT'!$E$69&";ptrav="&'PRÉDIMENSIONNEMENT'!$E$70&";pmsup="&'PRÉDIMENSIONNEMENT'!$E$71&";pminf="&'PRÉDIMENSIONNEMENT'!$E$72&";ppp="&'PRÉDIMENSIONNEMENT'!$E$75&";ppanne="&'PRÉDIMENSIONNEMENT'!$E$77&";plisse="&'PRÉDIMENSIONNEMENT'!$E$78&";npc="&FIXED('PARAMÈTRES'!$C$28,4,TRUE)&";lpc="&FIXED('PARAMÈTRES'!$C$29,4,TRUE)&";hpc="&FIXED('PARAMÈTRES'!$C$30,4,TRUE)&";epc="&'PARAMÈTRES'!$C$31&";npt="&FIXED('PARAMÈTRES'!$C$32,4,TRUE)&";lpt="&FIXED('PARAMÈTRES'!$C$33,4,TRUE)&";hpt="&FIXED('PARAMÈTRES'!$C$34,4,TRUE)&";ept="&'PARAMÈTRES'!$C$35&";nsky="&FIXED('PARAMÈTRES'!$C$37,4,TRUE)&";asky="&FIXED('PARAMÈTRES'!$C$38,4,TRUE)&";bsky="&FIXED('PARAMÈTRES'!$C$39,4,TRUE)&";pct="&FIXED('PARAMÈTRES'!$C$45*100,4,TRUE)&";sdesc="&FIXED('PARAMÈTRES'!$C$48,4,TRUE)&";acr="&'PARAMÈTRES'!$C$42&";hacr="&FIXED('PARAMÈTRES'!$C$43,4,TRUE)&";fac="&'PARAMÈTRES'!$C$51&";hs="&FIXED('PARAMÈTRES'!$C$52,4,TRUE)&";D="&FIXED('PARAMÈTRES'!$C$83,4,TRUE)&";eprop="&FIXED('PARAMÈTRES'!$C$88,4,TRUE)&";a1="&FIXED('PARAMÈTRES'!$C$89,4,TRUE)&";hs1="&FIXED('PARAMÈTRES'!$C$90,4,TRUE)&";f1="&FIXED('PARAMÈTRES'!$C$91,4,TRUE)&";a2="&FIXED('PARAMÈTRES'!$C$92,4,TRUE)&";hfut="&FIXED('PARAMÈTRES'!$C$95,4,TRUE)&";bf="&FIXED('PARAMÈTRES'!$C$102,4,TRUE)&";hfil="&FIXED('PARAMÈTRES'!$C$103,4,TRUE)&";hmf="&FIXED('PARAMÈTRES'!$C$111,4,TRUE)&";edal="&'PARAMÈTRES'!$C$114&";erem="&'PARAMÈTRES'!$C$86&";esab="&FIXED('PARAMÈTRES'!$C$87,4,TRUE)&";ferr="&'PARAMÈTRES'!$C$115&";hix="&'PARAMÈTRES'!$C$116&";hiy="&'PARAMÈTRES'!$C$117&";hsx="&'PARAMÈTRES'!$C$118&";hsy="&'PARAMÈTRES'!$C$119&";maille="&'PARAMÈTRES'!$C$120&";hasem="&'PARAMÈTRES'!$C$97&";msem="&FIXED('PARAMÈTRES'!$C$96,4,TRUE)&";nbf="&FIXED('PARAMÈTRES'!$C$99,4,TRUE)&";hafut="&'PARAMÈTRES'!$C$98&";hacad="&'PARAMÈTRES'!$C$100&";ecad="&FIXED('PARAMÈTRES'!$C$101,4,TRUE)&";nfil="&FIXED('PARAMÈTRES'!$C$105,4,TRUE)&";hafil="&'PARAMÈTRES'!$C$104&";harep="&'PARAMÈTRES'!$C$106&";erep="&FIXED('PARAMÈTRES'!$C$107,4,TRUE)&";dtige="&'PARAMÈTRES'!$C$72&";ltige="&FIXED('PARAMÈTRES'!$C$73,4,TRUE)&";bch="&FIXED('PARAMÈTRES'!$C$129,4,TRUE)&";hch="&FIXED('PARAMÈTRES'!$C$130,4,TRUE)&";brd="&FIXED('PARAMÈTRES'!$C$135,4,TRUE)&";nrd="&FIXED('PARAMÈTRES'!$C$136,4,TRUE)&";hachl="&'PARAMÈTRES'!$C$131&";hachc="&'PARAMÈTRES'!$C$133&";echc="&FIXED('PARAMÈTRES'!$C$134,4,TRUE) -> PLAN1;gab=20 × 40;B=20.0000;L=40.0000;H=6.0000;p=16.0000;ep=6.0000;epan=1.3500;elis=1.8000;epp=6.0000;deb=0.3000;sys=IPE renforcé;fint=Non;rtr=30.0000;pas=2.0000;rj=10.0000;nacc=2.0000;ppot=IPE 330;ptrav=IPE 300;pmsup=L 70x7;pminf=L 60x6;ppp=IPE 220;ppanne=Z 200;plisse=C 160;npc=1.0000;lpc=4.0000;hpc=4.5000;epc=Pignon;npt=1.0000;lpt=5.5000;hpt=4.0000;ept=Long-pan;nsky=4.0000;asky=1.2000;bsky=1.2000;pct=10.0000;sdesc=180.0000;acr=Non;hacr=1.0000;fac=Bardage bac acier;hs=1.5000;D=1.2000;eprop=0.0500;a1=1.2000;hs1=0.4000;f1=0.4000;a2=0.8000;hfut=1.2000;bf=0.6000;hfil=0.2000;hmf=1.0000;edal=20 cm;erem=20 cm;esab=0.0500;ferr=Nappe simple;hix=HA10;hiy=HA10;hsx=HA8;hsy=HA8;maille=20 cm;hasem=HA12;msem=0.1500;nbf=4.0000;hafut=HA12;hacad=HA6;ecad=0.1500;nfil=4.0000;hafil=HA10;harep=HA8;erep=0.2000;dtige=Rond 24;ltige=0.6000;bch=0.1500;hch=0.2000;brd=0.1500;nrd=3.0000;hachl=HA10;hachc=HA6;echc=0.2000

Sheet PARAMÈTRES
A1: PARAMÈTRES – toutes les données saisissables
A2: Cellules JAUNES = saisie. Cellules bleu clair = valeurs calculées. Les gabarits prédéfinis utilisent la hauteur et la pente ci-dessous ; PERSONNALISÉ utilise sa propre ligne du tableau (col. G à K).
B4: Paramètre | C4: Valeur | D4: Unité | E4: Plage conseillée / commentaire | G4: Gabarit | H4: Portée (m) | I4: Longueur (m) | J4: Hauteur (m) | K4: Pente
B5: 1. GABARIT ET GÉOMÉTRIE | G5: 10 × 30 | H5: 10 | I5: 30 | J5: =$C$6 -> 6 | K5: =$C$7 -> 0.16
B6: Hauteur sous sablière (gabarits prédéfinis) | C6: 6 | D6: m | E6: 4 à 12 m | G6: 15 × 20 | H6: 15 | I6: 20 | J6: =$C$6 -> 6 | K6: =$C$7 -> 0.16
B7: Pente de toiture (gabarits prédéfinis) | C7: 0.16 | D7: % | E7: 10 à 20 % conseillé ; < 5 % = alerte | G7: 15 × 30 | H7: 15 | I7: 30 | J7: =$C$6 -> 6 | K7: =$C$7 -> 0.16
B8: Gabarit actif (choisi en ACCUEIL) | C8: ='ACCUEIL'!$D$6 -> 20 × 40 | G8: 20 × 20 | H8: 20 | I8: 20 | J8: =$C$6 -> 6 | K8: =$C$7 -> 0.16
B9: Portée active | C9: =INDEX('PARAMÈTRES'!$H$5:$H$12,MATCH('ACCUEIL'!$D$6,'PARAMÈTRES'!$G$5:$G$12,0)) -> 20 | D9: m | E9: Valeur du gabarit actif | G9: 20 × 40 | H9: 20 | I9: 40 | J9: =$C$6 -> 6 | K9: =$C$7 -> 0.16
B10: Longueur active | C10: =INDEX('PARAMÈTRES'!$I$5:$I$12,MATCH('ACCUEIL'!$D$6,'PARAMÈTRES'!$G$5:$G$12,0)) -> 40 | D10: m | E10: Valeur du gabarit actif | G10: 30 × 40 | H10: 30 | I10: 40 | J10: =$C$6 -> 6 | K10: =$C$7 -> 0.16
B11: Hauteur sous sablière active | C11: =INDEX('PARAMÈTRES'!$J$5:$J$12,MATCH('ACCUEIL'!$D$6,'PARAMÈTRES'!$G$5:$G$12,0)) -> 6 | D11: m | E11: Valeur du gabarit actif | G11: 40 × 40 | H11: 40 | I11: 40 | J11: =$C$6 -> 6 | K11: =$C$7 -> 0.16
B12: Pente active | C12: =INDEX('PARAMÈTRES'!$K$5:$K$12,MATCH('ACCUEIL'!$D$6,'PARAMÈTRES'!$G$5:$G$12,0)) -> 0.16 | D12: % | E12: Valeur du gabarit actif | G12: PERSONNALISÉ | H12: 40 | I12: 48 | J12: 6 | K12: 0.16
G13: Ligne PERSONNALISÉ : saisir portée, longueur, hauteur et pente. Valeurs proposées = modèle de référence 40 × 48 m, H 6 m, pente 16 %.
B14: 2. CHARPENTE – TRAMES ET SYSTÈME
B15: Entraxe des portiques | C15: 6 | D15: m | E15: 6 m par défaut
B16: Entraxe des pannes | C16: 1.35 | D16: m | E16: 1,20 à 1,50 m | G16: PLATINES ET PIÈCES PLATES (dimensions modifiables)
B17: Entraxe des lisses de bardage | C17: 1.8 | D17: m | E17: 1,50 à 2,00 m | G17: Pièce | H17: L (m) | I17: l (m) | J17: e (m) | K17: kg/u
B18: Espacement des poteaux de pignon | C18: 6 | D18: m | E18: 5 à 6 m | G18: Platine de pied – poteau de portique | H18: 0.45 | I18: 0.35 | J18: 0.02 | K18: =H18*I18*J18*'PARAMÈTRES'!$C$57 -> 24.7275
B19: Débord des pannes aux pignons | C19: 0.3 | D19: m | G19: Platine de pied – poteau de pignon | H19: 0.3 | I19: 0.25 | J19: 0.015 | K19: =H19*I19*J19*'PARAMÈTRES'!$C$57 -> 8.83125
B20: Système pour portée de 20 à 30 m | C20: IPE renforcé | E20: IPE renforcé ou Ferme treillis | G20: Platine de tête de poteau / about de jarret | H20: 0.55 | I20: 0.25 | J20: 0.02 | K20: =H20*I20*J20*'PARAMÈTRES'!$C$57 -> 21.5875
B21: File de poteaux intermédiaires (file centrale) | C21: Non | E21: Conseillé au-delà de 30 m | G21: Platine de tête – poteau de pignon | H21: 0.25 | I21: 0.2 | J21: 0.012 | K21: =H21*I21*J21*'PARAMÈTRES'!$C$57 -> 4.71
B22: Hauteur de ferme aux appuis = portée / … | C22: 30 | E22: 25 à 35 | G22: Éclisse de faîtage (une plaque) | H22: 0.5 | I22: 0.25 | J22: 0.015 | K22: =H22*I22*J22*'PARAMÈTRES'!$C$57 -> 14.71875
B23: Pas des nœuds du treillis | C23: 2 | D23: m | E23: 1,5 à 2,5 m | G23: Gousset de nœud de treillis | H23: 0.3 | I23: 0.3 | J23: 0.01 | K23: =H23*I23*J23*'PARAMÈTRES'!$C$57 -> 7.065
B24: Longueur de jarret (en % de la portée) | C24: 0.1 | D24: % | E24: 8 à 12 %
B25: Nombre de cornières accolées par membrure | C25: 2 | D25: u | E25: 2 cornières dos à dos
B27: 3. OUVERTURES – SKYDOMES
B28: Portes coulissantes : nombre | C28: 1 | D28: u
B29: Portes coulissantes : largeur | C29: 4 | D29: m
B30: Portes coulissantes : hauteur | C30: 4.5 | D30: m
B31: Portes coulissantes : emplacement | C31: Pignon | E31: Long-pan ou Pignon
B32: Portillons : nombre | C32: 1 | D32: u | E32: Modèle de référence : portillon de 5,50 m en long-pan
B33: Portillons : largeur | C33: 5.5 | D33: m
B34: Portillons : hauteur | C34: 4 | D34: m
B35: Portillons : emplacement | C35: Long-pan | E35: Long-pan ou Pignon
B36: Débord du larmier de porte coulissante | C36: 0.2 | D36: m | E36: ml = largeur + 0,20 m
B37: Nombre de skydomes | C37: 4 | D37: u
B38: Skydome : longueur | C38: 1.2 | D38: m
B39: Skydome : largeur | C39: 1.2 | D39: m
B41: 4. COUVERTURE – BARDAGE – FAÇADE
B42: Présence d'acrotère | C42: Non | E42: Oui / Non
B43: Hauteur d'acrotère | C43: 1 | D43: m
...

Sheet BASE_PROFILÉS
A1: BASE DES PROFILÉS – poids en kg/ml
A2: Valeurs indicatives (catalogues usuels). Recherche par RECHERCHEX dans toutes les feuilles. Ajouter de nouveaux profilés en fin de tableau.
B4: Désignation | C4: Famille | D4: kg/ml | E4: h (mm) | F4: Remarque
B5: IPE 160 | C5: IPE | D5: 15.8 | E5: 160 | F5: Membrures de treillis : poids multiplié par le nombre de cornières accolées
B6: IPE 180 | C6: IPE | D6: 18.8 | E6: 180
B7: IPE 200 | C7: IPE | D7: 22.4 | E7: 200
B8: IPE 220 | C8: IPE | D8: 26.2 | E8: 220
B9: IPE 240 | C9: IPE | D9: 30.7 | E9: 240
B10: IPE 270 | C10: IPE | D10: 36.1 | E10: 270
B11: IPE 300 | C11: IPE | D11: 42.2 | E11: 300
B12: IPE 330 | C12: IPE | D12: 49.1 | E12: 330
B13: IPE 360 | C13: IPE | D13: 57.1 | E13: 360
B14: IPE 400 | C14: IPE | D14: 66.3 | E14: 400
B15: IPE 450 | C15: IPE | D15: 77.6 | E15: 450
B16: IPE 500 | C16: IPE | D16: 90.7 | E16: 500
B17: IPE 550 | C17: IPE | D17: 106 | E17: 550
... B85: Rond 30 | C85: Rond plein (tirants, liernes, tiges) | D85: 5.55 | E85: 30

Sheet BASE_ACIERS
A1: BASE DES ACIERS HA – poids en kg/ml
A2: Aciers à haute adhérence FeE500 – barres commerciales de 12 m
B4: Désignation | C4: Ø (mm) | D4: kg/ml | E4: Section (cm²) | F4: Remarque
B5: HA6 | C5: 6 | D5: 0.222 | E5: =PI()*C5^2/400 -> 0.28274334 | F5: Poids = 7 850 kg/m³ × π Ø² / 4
B6: HA8 | C6: 8 | D6: 0.395 | E6: =PI()*C6^2/400 -> 0.50265482
B7: HA10 | C7: 10 | D7: 0.617 | E7: =PI()*C7^2/400 -> 0.78539816
B8: HA12 | C8: 12 | D8: 0.888 | E8: =PI()*C8^2/400 -> 1.1309734
B9: HA14 | C9: 14 | D9: 1.208 | E9: =PI()*C9^2/400 -> 1.5393804
B10: HA16 | C10: 16 | D10: 1.578 | E10: =PI()*C10^2/400 -> 2.0106193
B11: HA20 | C11: 20 | D11: 2.466 | E11: =PI()*C11^2/400 -> 3.1415927
B12: HA25 | C12: 25 | D12: 3.853 | E12: =PI()*C12^2/400 -> 4.9087385

Sheet PRÉDIMENSIONNEMENT
A1: PRÉDIMENSIONNEMENT – choix automatique des profilés (modifiable en jaune)
A2: Portée ≤ 20 m : portique IPE avec jarrets · 20 à 30 m : IPE renforcé ou ferme treillis · > 30 m : ferme treillis (cornières) + alerte file intermédiaire. Valeurs de prédimensionnement à confirmer par une note de calcul EC3 / EC1 (vent).
B4: A. RÈGLES DE CHOIX SELON LA PORTÉE
B5: Portée ≤ (m) | C5: Système indicatif | D5: Poteau (portique IPE) | E5: Traverse IPE | F5: Poteau (treillis) | G5: Membrure sup. | H5: Membrure inf. | I5: Montants | J5: Diagonales
B6: 10 | C6: Portique IPE + jarrets | D6: IPE 220 | E6: IPE 200 | F6: HEA 180 | G6: L 50x5 | H6: L 45x4.5 | I6: L 40x4 | J6: L 40x4
B7: 15 | C7: Portique IPE + jarrets | D7: IPE 270 | E7: IPE 240 | F7: HEA 200 | G7: L 60x6 | H7: L 50x5 | I7: L 40x4 | J7: L 45x4.5
B8: 20 | C8: Portique IPE + jarrets | D8: IPE 330 | E8: IPE 300 | F8: HEA 220 | G8: L 70x7 | H8: L 60x6 | I8: L 45x4.5 | J8: L 50x5
B9: 25 | C9: IPE renforcé ou treillis | D9: IPE 400 | E9: IPE 360 | F9: HEA 240 | G9: L 70x7 | H9: L 60x6 | I9: L 50x5 | J9: L 50x5
B10: 30 | C10: IPE renforcé ou treillis | D10: IPE 450 | E10: IPE 400 | F10: HEA 260 | G10: L 80x8 | H10: L 70x7 | I10: L 50x5 | J10: L 60x6
B11: 35 | C11: Ferme treillis | D11: IPE 500 | E11: IPE 450 | F11: HEA 280 | G11: L 90x9 | H11: L 80x8 | I11: L 50x5 | J11: L 60x6
B12: 40 | C12: Ferme treillis | D12: IPE 550 | E12: IPE 500 | F12: HEA 300 | G12: L 100x10 | H12: L 90x9 | I12: L 60x6 | J12: L 70x7
B13: 50 | C13: Ferme treillis + file intermédiaire | D13: IPE 600 | E13: IPE 550 | F13: HEA 340 | G13: L 100x10 | H13: L 100x10 | I13: L 60x6 | J13: L 80x8
B14: 1000 | C14: Ferme treillis + file intermédiaire | D14: IPE 600 | E14: IPE 600 | F14: HEA 400 | G14: L 100x10 | H14: L 100x10 | I14: L 70x7 | J14: L 90x9
B16: H faîtage ≤ (m) | C16: Poteau de pignon | F16: Entraxe ≤ (m) | G16: Panne | H16: Lisse
B17: 6 | C17: IPE 180 | F17: 5 | G17: Z 160 | H17: C 140
B18: 8 | C18: IPE 220 | F18: 6 | G18: Z 200 | H18: C 160
B19: 10 | C19: IPE 270 | F19: 7 | G19: Z 220 | H19: C 180
B20: 12 | C20: IPE 300 | F20: 1000 | G20: Z 250 | H20: C 200
B21: 1000 | C21: IPE 360
B23: B. GÉOMÉTRIE ET GRANDEURS CALCULÉES
B24: Grandeur | C24: Valeur | D24: Unité | E24: Règle de calcul
B25: Ligne de règle (selon portée) | C25: =COUNTIF('PRÉDIMENSIONNEMENT'!$B$6:$B$14,"<"&'PARAMÈTRES'!$C$9)+1 -> 3 | E25: Rang de la portée dans le tableau A
B26: Système structurel retenu | C26: =IF('PARAMÈTRES'!$C$9<=20,"Portique IPE avec jarrets",IF('PARAMÈTRES'!$C$9<=30,IF('PARAMÈTRES'!$C$20="Ferme treillis","Ferme treillis","Portique IPE renforcé"),"Ferme treillis")) -> Portique IPE avec jarrets | E26: Selon portée et choix 20–30 m
B27: Ferme treillis (1 = oui) | C27: =IF('PRÉDIMENSIONNEMENT'!$C$26="Ferme treillis",1,0) -> 0
B28: Nombre de travées | C28: =MAX(1,ROUNDUP('PARAMÈTRES'!$C$10/'PARAMÈTRES'!$C$15,0)) -> 7 | D28: u | E28: ARRONDI.SUP(L / entraxe)
B29: Nombre de portiques N | C29: ='PRÉDIMENSIONNEMENT'!$C$28+1 -> 8 | D29: u | E29: N = ARRONDI.SUP(Longueur / entraxe) + 1
B30: Entraxe réel des portiques | C30: ='PARAMÈTRES'!$C$10/'PRÉDIMENSIONNEMENT'!$C$28 -> 5.7142857 | D30: m | E30: L / nombre de travées
B31: Longueur rampante d'un versant | C31: =('PARAMÈTRES'!$C$9/2)/COS(ATAN('PARAMÈTRES'!$C$12)) -> 10.127191 | D31: m | E31: (portée / 2) / cos(arctan(pente))
B32: Hauteur de ferme aux appuis | C32: ='PRÉDIMENSIONNEMENT'!$C$27*'PARAMÈTRES'!$C$9/'PARAMÈTRES'!$C$22 -> 0 | D32: m | E32: portée / ratio (0 si portique IPE)
B33: Hauteur des murs à l'égout | C33: ='PARAMÈTRES'!$C$11+'PRÉDIMENSIONNEMENT'!$C$32 -> 6 | D33: m | E33: H sablière + hauteur de ferme aux appuis
B34: Hauteur au faîtage | C34: ='PRÉDIMENSIONNEMENT'!$C$33+'PARAMÈTRES'!$C$12*'PARAMÈTRES'!$C$9/2 -> 7.6 | D34: m | E34: Hm + pente × portée / 2
B35: Intervalles entre poteaux de pignon (par pignon) | C35: =MAX(1,ROUNDUP('PARAMÈTRES'!$C$9/'PARAMÈTRES'!$C$18,0)) -> 4 | D35: u | E35: ARRONDI.SUP(portée / espacement)
B36: Espacement réel des poteaux de pignon | C36: ='PARAMÈTRES'!$C$9/'PRÉDIMENSIONNEMENT'!$C$35 -> 5 | D36: m
B37: Poteaux de pignon (2 pignons) | C37: =2*('PRÉDIMENSIONNEMENT'!$C$35-1) -> 6 | D37: u | E37: 2 × (intervalles − 1)
B38: Poteaux intermédiaires (file centrale) | C38: =IF('PARAMÈTRES'!$C$21="Oui",'PRÉDIMENSIONNEMENT'!$C$29,0) -> 0 | D38: u | E38: 1 par portique si file centrale
B39: Panneaux du treillis | C39: ='PRÉDIMENSIONNEMENT'!$C$27*2*ROUNDUP('PARAMÈTRES'!$C$9/2/'PARAMÈTRES'!$C$23,0) -> 0 | D39: u | E39: nombre pair ≈ portée / pas
B40: Pannes par versant | C40: =ROUNDUP('PRÉDIMENSIONNEMENT'!$C$31/'PARAMÈTRES'!$C$16,0)+1 -> 9 | D40: u | E40: ARRONDI.SUP(rampant / entraxe) + 1
B41: Entraxe réel des pannes | C41: ='PRÉDIMENSIONNEMENT'!$C$31/('PRÉDIMENSIONNEMENT'!$C$40-1) -> 1.2658989 | D41: m
B42: Longueur des pannes (avec débords) | C42: ='PARAMÈTRES'!$C$10+2*'PARAMÈTRES'!$C$19 -> 40.6 | D42: m | E42: L + 2 × débord
B43: Lignes de liernes par travée | C43: =IF('PRÉDIMENSIONNEMENT'!$C$30>6,2,1) -> 1 | D43: u | E43: mi-portée ; au tiers si entraxe > 6 m
...

Sheet QUANTITATIF_CHARPENTE
A1: QUANTITATIF CHARPENTE MÉTALLIQUE (EC3 / EC1)
A2: Une ligne par élément. Toutes les quantités se recalculent depuis PARAMÈTRES et PRÉDIMENSIONNEMENT.
B4: Désignation | C4: Profilé / section | D4: Unité | E4: Quantité | F4: Long. unitaire (m) | G4: Long. totale (m) | H4: kg/ml ou kg/u | I4: Poids total (kg) | J4: Règle de calcul (aussi en commentaire)
B5: A1. OSSATURE
B6: Poteaux de portiques (2 par portique) | C6: ='PRÉDIMENSIONNEMENT'!$E$69 -> IPE 330 | D6: ml | E6: =2*'PRÉDIMENSIONNEMENT'!$C$29 -> 16 | F6: ='PRÉDIMENSIONNEMENT'!$C$33 -> 6 | G6: ='QUANTITATIF_CHARPENTE'!$E$6*'QUANTITATIF_CHARPENTE'!$F$6 -> 96 | H6: ='PRÉDIMENSIONNEMENT'!$F$69 -> 49.1 | I6: ='QUANTITATIF_CHARPENTE'!$G$6*'QUANTITATIF_CHARPENTE'!$H$6 -> 4713.6 | J6: 2 × N poteaux × hauteur à l'égout (H + hauteur de ferme)
B7: Poteaux de pignon (hauteur variable avec la pente) | C7: ='PRÉDIMENSIONNEMENT'!$E$75 -> IPE 220 | D7: ml | E7: ='PRÉDIMENSIONNEMENT'!$C$37 -> 6 | F7: =IF('QUANTITATIF_CHARPENTE'!$E$7>0,'QUANTITATIF_CHARPENTE'!$G$7/'QUANTITATIF_CHARPENTE'!$E$7,0) -> 7.0666667 | G7: =2*(('PRÉDIMENSIONNEMENT'!$C$35-1)*'PRÉDIMENSIONNEMENT'!$C$33+'PARAMÈTRES'!$C$12*'PRÉDIMENSIONNEMENT'!$C$36*INT('PRÉDIMENSIONNEMENT'!$C$35^2/4)) -> 42.4 | H7: ='PRÉDIMENSIONNEMENT'!$F$75 -> 26.2 | I7: ='QUANTITATIF_CHARPENTE'!$G$7*'QUANTITATIF_CHARPENTE'!$H$7 -> 1110.88 | J7: 2 pignons × Σ (Hm + pente × min(x ; B − x)) ; Σ min = (B / n) × ENT(n² / 4)
B8: Poteaux intermédiaires (file centrale) | C8: ='PRÉDIMENSIONNEMENT'!$E$76 -> HEA 200 | D8: ml | E8: ='PRÉDIMENSIONNEMENT'!$C$38 -> 0 | F8: =IF('PRÉDIMENSIONNEMENT'!$C$27=1,'PARAMÈTRES'!$C$11,'PRÉDIMENSIONNEMENT'!$C$34) -> 7.6 | G8: ='QUANTITATIF_CHARPENTE'!$E$8*'QUANTITATIF_CHARPENTE'!$F$8 -> 0 | H8: ='PRÉDIMENSIONNEMENT'!$F$76 -> 42.3 | I8: ='QUANTITATIF_CHARPENTE'!$G$8*'QUANTITATIF_CHARPENTE'!$H$8 -> 0 | J8: 1 par portique si file centrale = Oui
B9: Traverses de portique (2 versants) | C9: ='PRÉDIMENSIONNEMENT'!$E$70 -> IPE 300 | D9: ml | E9: ='PRÉDIMENSIONNEMENT'!$C$29*(1-'PRÉDIMENSIONNEMENT'!$C$27) -> 8 | F9: =2*'PRÉDIMENSIONNEMENT'!$C$31 -> 20.254382 | G9: ='QUANTITATIF_CHARPENTE'!$E$9*'QUANTITATIF_CHARPENTE'!$F$9 -> 162.03506 | H9: ='PRÉDIMENSIONNEMENT'!$F$70 -> 42.2 | I9: ='QUANTITATIF_CHARPENTE'!$G$9*'QUANTITATIF_CHARPENTE'!$H$9 -> 6837.8794 | J9: Longueur rampante = (portée / 2) / cos(arctan(pente)) × 2
B10: Jarrets (renforts poteau-traverse) | C10: ='PRÉDIMENSIONNEMENT'!$E$70 -> IPE 300 | D10: ml | E10: =2*'PRÉDIMENSIONNEMENT'!$C$29*(1-'PRÉDIMENSIONNEMENT'!$C$27) -> 16 | F10: ='PARAMÈTRES'!$C$24*'PARAMÈTRES'!$C$9 -> 2 | G10: ='QUANTITATIF_CHARPENTE'!$E$10*'QUANTITATIF_CHARPENTE'!$F$10 -> 32 | H10: ='PRÉDIMENSIONNEMENT'!$F$70 -> 42.2 | I10: ='QUANTITATIF_CHARPENTE'!$G$10*'QUANTITATIF_CHARPENTE'!$H$10 -> 1350.4 | J10: 2 par portique, longueur = % × portée, découpés dans le profil de traverse
B11: Ferme treillis – membrures supérieures | C11: ='PRÉDIMENSIONNEMENT'!$E$71 -> L 70x7 | D11: ml | E11: ='PRÉDIMENSIONNEMENT'!$C$29*'PRÉDIMENSIONNEMENT'!$C$27 -> 0 | F11: =2*'PRÉDIMENSIONNEMENT'!$C$31 -> 20.254382 | G11: ='QUANTITATIF_CHARPENTE'!$E$11*'QUANTITATIF_CHARPENTE'!$F$11 -> 0 | H11: ='PRÉDIMENSIONNEMENT'!$F$71 -> 14.76 | I11: ='QUANTITATIF_CHARPENTE'!$G$11*'QUANTITATIF_CHARPENTE'!$H$11 -> 0 | J11: 1 par ferme, longueur = 2 × rampant ; poids × cornières accolées
B12: Ferme treillis – membrures inférieures | C12: ='PRÉDIMENSIONNEMENT'!$E$72 -> L 60x6 | D12: ml | E12: ='PRÉDIMENSIONNEMENT'!$C$29*'PRÉDIMENSIONNEMENT'!$C$27 -> 0 | F12: ='PARAMÈTRES'!$C$9 -> 20 | G12: ='QUANTITATIF_CHARPENTE'!$E$12*'QUANTITATIF_CHARPENTE'!$F$12 -> 0 | H12: ='PRÉDIMENSIONNEMENT'!$F$72 -> 10.84 | I12: ='QUANTITATIF_CHARPENTE'!$G$12*'QUANTITATIF_CHARPENTE'!$H$12 -> 0 | J12: 1 par ferme, longueur = portée
B13: Ferme treillis – montants | C13: ='PRÉDIMENSIONNEMENT'!$E$73 -> L 45x4.5 | D13: ml | E13: ='PRÉDIMENSIONNEMENT'!$C$29*'PRÉDIMENSIONNEMENT'!$C$27*('PRÉDIMENSIONNEMENT'!$C$39+1) -> 0 | F13: =IF('QUANTITATIF_CHARPENTE'!$E$13>0,'QUANTITATIF_CHARPENTE'!$G$13/'QUANTITATIF_CHARPENTE'!$E$13,0) -> 0 | G13: ='PRÉDIMENSIONNEMENT'!$C$29*'PRÉDIMENSIONNEMENT'!$C$27*(('PRÉDIMENSIONNEMENT'!$C$39+1)*'PRÉDIMENSIONNEMENT'!$C$32+'PARAMÈTRES'!$C$12*('PARAMÈTRES'!$C$9/'PRÉDIMENSIONNEMENT'!$C$52)*INT('PRÉDIMENSIONNEMENT'!$C$39^2/4)) -> 0 | H13: ='PRÉDIMENSIONNEMENT'!$F$73 -> 3.06 | I13: ='QUANTITATIF_CHARPENTE'!$G$13*'QUANTITATIF_CHARPENTE'!$H$13 -> 0 | J13: (n + 1) montants par ferme, hauteur h0 + pente × min(x ; B − x)
B14: Ferme treillis – diagonales | C14: ='PRÉDIMENSIONNEMENT'!$E$74 -> L 50x5 | D14: ml | E14: ='PRÉDIMENSIONNEMENT'!$C$29*'PRÉDIMENSIONNEMENT'!$C$27*'PRÉDIMENSIONNEMENT'!$C$39 -> 0 | F14: ='PRÉDIMENSIONNEMENT'!$C$27*SQRT(('PARAMÈTRES'!$C$9/'PRÉDIMENSIONNEMENT'!$C$52)^2+('PRÉDIMENSIONNEMENT'!$C$32+'PARAMÈTRES'!$C$12*'PARAMÈTRES'!$C$9/4)^2) -> 0 | G14: ='QUANTITATIF_CHARPENTE'!$E$14*'QUANTITATIF_CHARPENTE'!$F$14 -> 0 | H14: ='PRÉDIMENSIONNEMENT'!$F$74 -> 3.77 | I14: ='QUANTITATIF_CHARPENTE'!$G$14*'QUANTITATIF_CHARPENTE'!$H$14 -> 0 | J14: n diagonales par ferme, longueur √(pas² + h moyenne²)
B15: Platines de pied – poteaux de portique | C15: ="PL" -> PL | D15: u | E15: =2*'PRÉDIMENSIONNEMENT'!$C$29+'PRÉDIMENSIONNEMENT'!$C$38 -> 16 | H15: ='PARAMÈTRES'!$K$18 -> 24.7275 | I15: ='QUANTITATIF_CHARPENTE'!$E$15*'QUANTITATIF_CHARPENTE'!$H$15 -> 395.64 | J15: 1 par poteau de portique ou intermédiaire
B16: Platines de pied – poteaux de pignon | C16: ="PL" -> PL | D16: u | E16: ='PRÉDIMENSIONNEMENT'!$C$37 -> 6 | H16: ='PARAMÈTRES'!$K$19 -> 8.83125 | I16: ='QUANTITATIF_CHARPENTE'!$E$16*'QUANTITATIF_CHARPENTE'!$H$16 -> 52.9875 | J16: 1 par poteau de pignon
B17: Platines de tête de poteau et d'about de jarret | C17: ="PL" -> PL | D17: u | E17: =IF('PRÉDIMENSIONNEMENT'!$C$27=1,2,4)*'PRÉDIMENSIONNEMENT'!$C$29 -> 32 | H17: ='PARAMÈTRES'!$K$20 -> 21.5875 | I17: ='QUANTITATIF_CHARPENTE'!$E$17*'QUANTITATIF_CHARPENTE'!$H$17 -> 690.8 | J17: Portique : 2 platines par nœud × 2 nœuds ; treillis : 1 platine de tête par poteau
B18: Platines de tête – poteaux de pignon | C18: ="PL" -> PL | D18: u | E18: ='PRÉDIMENSIONNEMENT'!$C$37 -> 6 | H18: ='PARAMÈTRES'!$K$21 -> 4.71 | I18: ='QUANTITATIF_CHARPENTE'!$E$18*'QUANTITATIF_CHARPENTE'!$H$18 -> 28.26 | J18: 1 par poteau de pignon
B19: Goussets de nœuds de treillis | C19: ="PL" -> PL | D19: u | E19: ='PRÉDIMENSIONNEMENT'!$C$29*'PRÉDIMENSIONNEMENT'!$C$27*(2*'PRÉDIMENSIONNEMENT'!$C$39+2) -> 0 | H19: ='PARAMÈTRES'!$K$23 -> 7.065 | I19: ='QUANTITATIF_CHARPENTE'!$E$19*'QUANTITATIF_CHARPENTE'!$H$19 -> 0 | J19: 2 (n + 1) nœuds par ferme
B20: Éclisses de faîtage (paires de plaques) | C20: ="PL" -> PL | D20: u | E20: ='PRÉDIMENSIONNEMENT'!$C$29 -> 8 | H20: =2*'PARAMÈTRES'!$K$22 -> 29.4375 | I20: ='QUANTITATIF_CHARPENTE'!$E$20*'QUANTITATIF_CHARPENTE'!$H$20 -> 235.5 | J20: 1 paire par portique
B21: Éclisses de pannes (à chaque raboutage) | C21: ="PL" -> PL | D21: u | E21: =2*'PRÉDIMENSIONNEMENT'!$C$40*MAX(0,ROUNDUP('PRÉDIMENSIONNEMENT'!$C$42/'PARAMÈTRES'!$C$58,0)-1) -> 54 | H21: ='PARAMÈTRES'!$C$62 -> 2.5 | I21: ='QUANTITATIF_CHARPENTE'!$E$21*'QUANTITATIF_CHARPENTE'!$H$21 -> 135 | J21: Pannes × (ARRONDI.SUP(longueur / 12 m) − 1)
B23: A2. STABILITÉ
B24: Contreventements verticaux – croix de Saint-André (long-pans) | C24: ='PRÉDIMENSIONNEMENT'!$E$79 -> L 70x7 | D24: ml | E24: ='PRÉDIMENSIONNEMENT'!$C$44*2*2 -> 12 | F24: =SQRT('PRÉDIMENSIONNEMENT'!$C$30^2+'PRÉDIMENSIONNEMENT'!$C$33^2) -> 8.2857143 | G24: ='QUANTITATIF_CHARPENTE'!$E$24*'QUANTITATIF_CHARPENTE'!$F$24 -> 99.428571 | H24: ='PRÉDIMENSIONNEMENT'!$F$79 -> 7.38 | I24: ='QUANTITATIF_CHARPENTE'!$G$24*'QUANTITATIF_CHARPENTE'!$H$24 -> 733.78286 | J24: Travées d'extrémité + 1 sur 5 ; 2 long-pans × 2 diagonales
B25: Contreventements de couverture – poutre au vent | C25: ='PRÉDIMENSIONNEMENT'!$E$80 -> L 60x6 | D25: ml | E25: ='PRÉDIMENSIONNEMENT'!$C$44*2*'PRÉDIMENSIONNEMENT'!$C$45*2 -> 24 | F25: =SQRT('PRÉDIMENSIONNEMENT'!$C$30^2+('PRÉDIMENSIONNEMENT'!$C$31/'PRÉDIMENSIONNEMENT'!$C$45)^2) -> 7.6349893 | G25: ='QUANTITATIF_CHARPENTE'!$E$25*'QUANTITATIF_CHARPENTE'!$F$25 -> 183.23974 | H25: ='PRÉDIMENSIONNEMENT'!$F$80 -> 5.42 | I25: ='QUANTITATIF_CHARPENTE'!$G$25*'QUANTITATIF_CHARPENTE'!$H$25 -> 993.1594 | J25: Mêmes travées ; 2 versants × panneaux × 2 diagonales
B26: Liernes de pannes | C26: ='PRÉDIMENSIONNEMENT'!$E$81 -> Rond 12 | D26: ml | E26: ='PRÉDIMENSIONNEMENT'!$C$28*'PRÉDIMENSIONNEMENT'!$C$43*2*('PRÉDIMENSIONNEMENT'!$C$40-1) -> 112 | F26: ='PRÉDIMENSIONNEMENT'!$C$41 -> 1.2658989 | G26: ='QUANTITATIF_CHARPENTE'!$E$26*'QUANTITATIF_CHARPENTE'!$F$26 -> 141.78068 | H26: ='PRÉDIMENSIONNEMENT'!$F$81 -> 0.888 | I26: ='QUANTITATIF_CHARPENTE'!$G$26*'QUANTITATIF_CHARPENTE'!$H$26 -> 125.90124 | J26: À mi-portée (au tiers si entraxe > 6 m), entre pannes successives
B27: Bretelles de faîtage | C27: ='PRÉDIMENSIONNEMENT'!$E$81 -> Rond 12 | D27: ml | E27: ='PRÉDIMENSIONNEMENT'!$C$28*'PRÉDIMENSIONNEMENT'!$C$43*2 -> 14 | F27: =SQRT(('PRÉDIMENSIONNEMENT'!$C$30/('PRÉDIMENSIONNEMENT'!$C$43+1))^2+'PRÉDIMENSIONNEMENT'!$C$41^2) -> 3.1250224 | G27: ='QUANTITATIF_CHARPENTE'!$E$27*'QUANTITATIF_CHARPENTE'!$F$27 -> 43.750314 | H27: ='PRÉDIMENSIONNEMENT'!$F$81 -> 0.888 | I27: ='QUANTITATIF_CHARPENTE'!$G$27*'QUANTITATIF_CHARPENTE'!$H$27 -> 38.850279 | J27: 2 par ligne de liernes au faîtage
B28: Liernes de lisses – long-pans | C28: ='PRÉDIMENSIONNEMENT'!$E$81 -> Rond 12 | D28: ml | E28: ='PRÉDIMENSIONNEMENT'!$C$28*'PRÉDIMENSIONNEMENT'!$C$43*2*'PRÉDIMENSIONNEMENT'!$C$59 -> 56 | F28: =IF('PRÉDIMENSIONNEMENT'!$C$59>0,('PRÉDIMENSIONNEMENT'!$C$33-'PRÉDIMENSIONNEMENT'!$C$49)/'PRÉDIMENSIONNEMENT'!$C$59,0) -> 1.5 | G28: ='QUANTITATIF_CHARPENTE'!$E$28*'QUANTITATIF_CHARPENTE'!$F$28 -> 84 | H28: ='PRÉDIMENSIONNEMENT'!$F$81 -> 0.888 | I28: ='QUANTITATIF_CHARPENTE'!$G$28*'QUANTITATIF_CHARPENTE'!$H$28 -> 74.592 | J28: Par ligne de liernes : hauteur bardée ; 0 en façade agglos
B29: Liernes de lisses – pignons | C29: ='PRÉDIMENSIONNEMENT'!$E$81 -> Rond 12 | D29: ml | E29: ='PRÉDIMENSIONNEMENT'!$C$50*2*'PRÉDIMENSIONNEMENT'!$C$35 -> 8 | F29: =IF('QUANTITATIF_CHARPENTE'!$E$29>0,'QUANTITATIF_CHARPENTE'!$G$29/'QUANTITATIF_CHARPENTE'!$E$29,0) -> 6.8 | G29: ='PRÉDIMENSIONNEMENT'!$C$50*2*'PRÉDIMENSIONNEMENT'!$C$35*(('PRÉDIMENSIONNEMENT'!$C$33-'PRÉDIMENSIONNEMENT'!$C$49)+'PARAMÈTRES'!$C$12*'PARAMÈTRES'!$C$9/4) -> 54.4 | H29: ='PRÉDIMENSIONNEMENT'!$F$81 -> 0.888 | I29: ='QUANTITATIF_CHARPENTE'!$G$29*'QUANTITATIF_CHARPENTE'!$H$29 -> 48.3072 | J29: 1 par intervalle de pignon, hauteur moyenne
B31: A3. COUVERTURE
B32: Pannes | C32: ='PRÉDIMENSIONNEMENT'!$E$77 -> Z 200 | D32: ml | E32: =2*'PRÉDIMENSIONNEMENT'!$C$40 -> 18 | F32: ='PRÉDIMENSIONNEMENT'!$C$42 -> 40.6 | G32: ='QUANTITATIF_CHARPENTE'!$E$32*'QUANTITATIF_CHARPENTE'!$F$32 -> 730.8 | H32: ='PRÉDIMENSIONNEMENT'!$F$77 -> 5.2 | I32: ='QUANTITATIF_CHARPENTE'!$G$32*'QUANTITATIF_CHARPENTE'!$H$32 -> 3800.16 | J32: Par versant : ARRONDI.SUP(rampant / entraxe) + 1 ; longueur = L + débords
B33: Échantignoles (taquets de pannes) | C33: ="Taquet" -> Taquet | D33: u | E33: =2*'PRÉDIMENSIONNEMENT'!$C$40*'PRÉDIMENSIONNEMENT'!$C$29 -> 144 | H33: ='PARAMÈTRES'!$C$61 -> 1.8 | I33: ='QUANTITATIF_CHARPENTE'!$E$33*'QUANTITATIF_CHARPENTE'!$H$33 -> 259.2 | J33: 1 par panne et par portique
B34: Chevêtres de skydomes | C34: ='PRÉDIMENSIONNEMENT'!$E$82 -> L 60x6 | D34: ml | E34: ='PARAMÈTRES'!$C$37 -> 4 | F34: =2*('PARAMÈTRES'!$C$38+'PARAMÈTRES'!$C$39) -> 4.8 | G34: ='QUANTITATIF_CHARPENTE'!$E$34*'QUANTITATIF_CHARPENTE'!$F$34 -> 19.2 | H34: ='PRÉDIMENSIONNEMENT'!$F$82 -> 5.42 | I34: ='QUANTITATIF_CHARPENTE'!$G$34*'QUANTITATIF_CHARPENTE'!$H$34 -> 104.064 | J34: 1 cadre par skydome
B35: Baïonnettes d'acrotère | C35: ='PRÉDIMENSIONNEMENT'!$E$83 -> L 50x5 | D35: ml | E35: =IF('PARAMÈTRES'!$C$42="Oui",ROUNDUP('PRÉDIMENSIONNEMENT'!$C$47/'PARAMÈTRES'!$C$44,0),0) -> 0 | F35: ='PARAMÈTRES'!$C$43 -> 1 | G35: ='QUANTITATIF_CHARPENTE'!$E$35*'QUANTITATIF_CHARPENTE'!$F$35 -> 0 | H35: ='PRÉDIMENSIONNEMENT'!$F$83 -> 3.77 | I35: ='QUANTITATIF_CHARPENTE'!$G$35*'QUANTITATIF_CHARPENTE'!$H$35 -> 0 | J35: 1 tous les 1,0 à 1,5 m de périmètre si acrotère
B36: Tôles bac acier (ép. selon paramètre) | C36: ="Bac acier "&FIXED('PARAMÈTRES'!$C$47,2,TRUE)&" mm" -> Bac acier 0.45 mm | D36: m² | E36: ='PRÉDIMENSIONNEMENT'!$C$63*(1+'PARAMÈTRES'!$C$46)-'PARAMÈTRES'!$C$45*'PRÉDIMENSIONNEMENT'!$C$63-'PARAMÈTRES'!$C$37*'PARAMÈTRES'!$C$38*'PARAMÈTRES'!$C$39 -> 816.56792 | J36: rampant × longueur × 2 × (1 + recouvrement) − translucides − skydomes
B37: Panneaux sandwich translucides | C37: ="Translucide" -> Translucide | D37: m² | E37: ='PARAMÈTRES'!$C$45*'PRÉDIMENSIONNEMENT'!$C$63 -> 82.232792 | J37: % × surface de couverture
B38: Faîtières | C38: ="Faîtière" -> Faîtière | D38: ml | E38: ='PRÉDIMENSIONNEMENT'!$C$42 -> 40.6 | J38: Longueur couverte
B39: Rives | C39: ="Rive" -> Rive | D39: ml | E39: =4*'PRÉDIMENSIONNEMENT'!$C$31 -> 40.508764 | J39: 2 pignons × 2 versants × rampant
B40: Larmiers / bavettes de couverture | C40: ="Bavette" -> Bavette | D40: ml | E40: =2*'PRÉDIMENSIONNEMENT'!$C$42 -> 81.2 | J40: 2 égouts
B41: Chéneaux d'eau (2 côtés) | C41: ="Chéneau" -> Chéneau | D41: ml | E41: =2*'PARAMÈTRES'!$C$10 -> 80 | J41: 2 × longueur
B42: Naissances EP | C42: ="Naissance" -> Naissance | D42: u | E42: ='PRÉDIMENSIONNEMENT'!$C$64 -> 6 | J42: 1 descente pour 150 à 200 m² de toiture
B43: Descentes EP | C43: ="PVC Ø110" -> PVC Ø110 | D43: ml | E43: ='PRÉDIMENSIONNEMENT'!$C$64*'PRÉDIMENSIONNEMENT'!$C$33 -> 36 | J43: Nombre × hauteur
...

Sheet GROS_ŒUVRE
A1: GROS ŒUVRE ET FONDATIONS (BAEL 91 mod. 99 / EC2)
A2: Sol latéritique : remblai en latérite compactée à 95 % OPM. Ciment CPJ 42.5. Aciers : longueurs avec recouvrement de 40 Ø et barres de 12 m.
B4: Désignation | C4: Profilé / section | D4: Unité | E4: Quantité | F4: Long. unitaire (m) | G4: Long. totale (m) | H4: kg/ml ou kg/u | I4: Poids total (kg) | J4: Règle de calcul (aussi en commentaire)
B5: B0. DONNÉES DE CALCUL
B6: Épaisseur du dallage | D6: m | E6: =VALUE(LEFT('PARAMÈTRES'!$C$114,2))/100 -> 0.2 | J6: Liste 15 / 20 cm
B7: Épaisseur du remblai compacté | D7: m | E7: =VALUE(LEFT('PARAMÈTRES'!$C$86,2))/100 -> 0.2 | J7: Liste 20 / 40 cm
B8: Maille du dallage | D8: m | E8: =VALUE(LEFT('PARAMÈTRES'!$C$120,2))/100 -> 0.2 | J8: Liste 15 / 20 / 25 cm
B9: Nappe double (1 = oui) | E9: =IF('PARAMÈTRES'!$C$115="Nappe double",1,0) -> 0
B10: Semelles isolées 1 (poteaux de portique et file centrale) | D10: u | E10: =2*'PRÉDIMENSIONNEMENT'!$C$29+'PRÉDIMENSIONNEMENT'!$C$38 -> 16
B11: Semelles isolées 2 (poteaux de pignon) | D11: u | E11: ='PRÉDIMENSIONNEMENT'!$C$37 -> 6
B12: Longueur de semelle filante | D12: m | E12: =MAX(0,'PRÉDIMENSIONNEMENT'!$C$47-2*'PRÉDIMENSIONNEMENT'!$C$29*'PARAMÈTRES'!$C$89-'PRÉDIMENSIONNEMENT'!$C$37*'PARAMÈTRES'!$C$92) -> 96 | J12: Périmètre − largeur des semelles isolées traversées
B13: Dallage : longueur intérieure (sens X) | D13: m | E13: ='PARAMÈTRES'!$C$10-'PARAMÈTRES'!$C$85 -> 39.85 | J13: L − épaisseur de mur
B14: Dallage : largeur intérieure (sens Y) | D14: m | E14: ='PARAMÈTRES'!$C$9-'PARAMÈTRES'!$C$85 -> 19.85 | J14: B − épaisseur de mur
B15: Surface intérieure | D15: m² | E15: ='GROS_ŒUVRE'!$E$13*'GROS_ŒUVRE'!$E$14 -> 791.0225
B16: Hauteur de maçonnerie d'élévation | D16: m | E16: ='PRÉDIMENSIONNEMENT'!$C$49 -> 0 | J16: selon type de façade
B17: Nombre de chaînages horizontaux | D17: u | E17: =IF('PRÉDIMENSIONNEMENT'!$C$48="Agglos 15 creux",3,IF('PRÉDIMENSIONNEMENT'!$C$48="Mixte",2,0)) -> 0 | J17: Agglos : bas, intermédiaire, haut · Mixte : bas et haut
B18: Panneaux de maçonnerie (travées du périmètre) | D18: u | E18: ='PRÉDIMENSIONNEMENT'!$C$51*(2*'PRÉDIMENSIONNEMENT'!$C$28+2*'PRÉDIMENSIONNEMENT'!$C$35) -> 0
B19: Coût matériaux d'1 m³ de béton armé | D19: FCFA/m³ | E19: ='PARAMÈTRES'!$C$143/'PARAMÈTRES'!$C$145*'PARAMÈTRES'!$C$185+'PARAMÈTRES'!$C$146*'PARAMÈTRES'!$C$186+'PARAMÈTRES'!$C$147*'PARAMÈTRES'!$C$187+'PARAMÈTRES'!$C$148*'PARAMÈTRES'!$C$188 -> 59900
B20: Coût matériaux d'1 m³ de mortier | D20: FCFA/m³ | E20: ='PARAMÈTRES'!$C$144/'PARAMÈTRES'!$C$145*'PARAMÈTRES'!$C$185+'PARAMÈTRES'!$C$149*'PARAMÈTRES'!$C$186 -> 46200
B22: B1. TERRASSEMENTS
B23: Décapage de l'emprise | D23: m² | E23: =('PARAMÈTRES'!$C$9+2*'PARAMÈTRES'!$C$81)*('PARAMÈTRES'!$C$10+2*'PARAMÈTRES'!$C$81) -> 924 | J23: (B + 2 débords) × (L + 2 débords)
B24: Fouilles en puits – semelles isolées 1 | D24: m³ | E24: ='GROS_ŒUVRE'!$E$10*('PARAMÈTRES'!$C$89+2*'PARAMÈTRES'!$C$82)^2*'PARAMÈTRES'!$C$83 -> 37.632 | J24: n × (a + 2 surlargeurs)² × profondeur 1,20 m
B25: Fouilles en puits – semelles isolées 2 | D25: m³ | E25: ='GROS_ŒUVRE'!$E$11*('PARAMÈTRES'!$C$92+2*'PARAMÈTRES'!$C$82)^2*'PARAMÈTRES'!$C$83 -> 7.2 | J25: n × (a + 2 surlargeurs)² × profondeur
B26: Fouilles en rigole – semelles filantes | D26: m³ | E26: ='GROS_ŒUVRE'!$E$12*('PARAMÈTRES'!$C$102+2*'PARAMÈTRES'!$C$82)*'PARAMÈTRES'!$C$83 -> 92.16 | J26: Longueur filante × (b + 2 surlargeurs) × profondeur
B27: Remblai latérite compactée sous dallage (approvisionnement) | D27: m³ | E27: ='GROS_ŒUVRE'!$E$15*'GROS_ŒUVRE'!$E$7*'PARAMÈTRES'!$C$84 -> 197.75563 | J27: Surface intérieure × épaisseur × foisonnement 1,25 (95 % OPM)
B28: Lit de sable de réglage (nid de sable) | D28: m³ | E28: ='GROS_ŒUVRE'!$E$15*'PARAMÈTRES'!$C$87 -> 39.551125 | J28: Surface × 5 cm
B29: Évacuation des déblais | D29: m³ | E29: =('GROS_ŒUVRE'!$E$23*'PARAMÈTRES'!$C$80+'GROS_ŒUVRE'!$E$24+'GROS_ŒUVRE'!$E$25+'GROS_ŒUVRE'!$E$26)*'PARAMÈTRES'!$C$84 -> 402.24 | J29: (décapage + fouilles) × foisonnement
B31: B2. SEMELLES ISOLÉES – POTEAUX DE PORTIQUE (120 × 120)
B32: Béton de propreté (5 cm) | D32: m³ | E32: ='GROS_ŒUVRE'!$E$10*'PARAMÈTRES'!$C$89^2*'PARAMÈTRES'!$C$88 -> 1.152 | J32: n × a² × 5 cm
B33: Béton armé – semelles | D33: m³ | E33: ='GROS_ŒUVRE'!$E$10*'PARAMÈTRES'!$C$89^2*'PARAMÈTRES'!$C$90 -> 9.216 | J33: n × a² × h
B34: Béton armé – fûts (amorces) | D34: m³ | E34: ='GROS_ŒUVRE'!$E$10*'PARAMÈTRES'!$C$91^2*'PARAMÈTRES'!$C$95 -> 3.072 | J34: n × côté² × hauteur du fût (1,20 m)
B35: Coffrage semelles et fûts | D35: m² | E35: ='GROS_ŒUVRE'!$E$10*(4*'PARAMÈTRES'!$C$89*'PARAMÈTRES'!$C$90+4*'PARAMÈTRES'!$C$91*'PARAMÈTRES'!$C$95) -> 61.44 | J35: n × (4 a h + 4 côté × h fût)
B36: Aciers – quadrillage inférieur | C36: ='PARAMÈTRES'!$C$97 -> HA12 | D36: barres | E36: ='GROS_ŒUVRE'!$E$10*2*(ROUNDDOWN(('PARAMÈTRES'!$C$89-2*'PARAMÈTRES'!$C$108)/'PARAMÈTRES'!$C$96,0)+1) -> 256 | F36: ='PARAMÈTRES'!$C$89-2*'PARAMÈTRES'!$C$108+2*'PARAMÈTRES'!$C$109 -> 1.4 | G36: ='GROS_ŒUVRE'!$E$36*'GROS_ŒUVRE'!$F$36 -> 358.4 | H36: =IFERROR(_xlfn.XLOOKUP('PARAMÈTRES'!$C$97,'BASE_ACIERS'!$B$5:$B$20,'BASE_ACIERS'!$D$5:$D$20),IFERROR(INDEX('BASE_ACIERS'!$D$5:$D$20,MATCH('PARAMÈTRES'!$C$97,'BASE_ACIERS'!$B$5:$B$20,0)),0)) -> 0.888 | I36: ='GROS_ŒUVRE'!$G$36*'GROS_ŒUVRE'!$H$36 -> 318.2592 | J36: 2 sens × (ENT((a − 2c) / maille) + 1) barres ; L = a − 2c + 2 retours
B37: Aciers – fûts (barres longitudinales) | C37: ='PARAMÈTRES'!$C$98 -> HA12 | D37: barres | E37: ='GROS_ŒUVRE'!$E$10*'PARAMÈTRES'!$C$99 -> 64 | F37: ='PARAMÈTRES'!$C$95+'PARAMÈTRES'!$C$90-'PARAMÈTRES'!$C$108+'PARAMÈTRES'!$C$109 -> 1.7 | G37: ='GROS_ŒUVRE'!$E$37*'GROS_ŒUVRE'!$F$37 -> 108.8 | H37: =IFERROR(_xlfn.XLOOKUP('PARAMÈTRES'!$C$98,'BASE_ACIERS'!$B$5:$B$20,'BASE_ACIERS'!$D$5:$D$20),IFERROR(INDEX('BASE_ACIERS'!$D$5:$D$20,MATCH('PARAMÈTRES'!$C$98,'BASE_ACIERS'!$B$5:$B$20,0)),0)) -> 0.888 | I37: ='GROS_ŒUVRE'!$G$37*'GROS_ŒUVRE'!$H$37 -> 96.6144 | J37: 4 barres par fût, ancrées dans la semelle
B38: Aciers – cadres des fûts | C38: ='PARAMÈTRES'!$C$100 -> HA6 | D38: barres | E38: ='GROS_ŒUVRE'!$E$10*(ROUNDDOWN('PARAMÈTRES'!$C$95/'PARAMÈTRES'!$C$101,0)+1) -> 144 | F38: =4*('PARAMÈTRES'!$C$91-2*'PARAMÈTRES'!$C$108)+2*'PARAMÈTRES'!$C$110 -> 1.4 | G38: ='GROS_ŒUVRE'!$E$38*'GROS_ŒUVRE'!$F$38 -> 201.6 | H38: =IFERROR(_xlfn.XLOOKUP('PARAMÈTRES'!$C$100,'BASE_ACIERS'!$B$5:$B$20,'BASE_ACIERS'!$D$5:$D$20),IFERROR(INDEX('BASE_ACIERS'!$D$5:$D$20,MATCH('PARAMÈTRES'!$C$100,'BASE_ACIERS'!$B$5:$B$20,0)),0)) -> 0.222 | I38: ='GROS_ŒUVRE'!$G$38*'GROS_ŒUVRE'!$H$38 -> 44.7552 | J38: Cadres tous les 15 cm
B40: B3. SEMELLES ISOLÉES – POTEAUX DE PIGNON (80 × 80)
B41: Béton de propreté (5 cm) | D41: m³ | E41: ='GROS_ŒUVRE'!$E$11*'PARAMÈTRES'!$C$92^2*'PARAMÈTRES'!$C$88 -> 0.192 | J41: n × a² × 5 cm
B42: Béton armé – semelles | D42: m³ | E42: ='GROS_ŒUVRE'!$E$11*'PARAMÈTRES'!$C$92^2*'PARAMÈTRES'!$C$93 -> 1.152 | J42: n × a² × h
B43: Béton armé – fûts (amorces) | D43: m³ | E43: ='GROS_ŒUVRE'!$E$11*'PARAMÈTRES'!$C$94^2*'PARAMÈTRES'!$C$95 -> 0.648 | J43: n × côté² × hauteur du fût (1,20 m)
B44: Coffrage semelles et fûts | D44: m² | E44: ='GROS_ŒUVRE'!$E$11*(4*'PARAMÈTRES'!$C$92*'PARAMÈTRES'!$C$93+4*'PARAMÈTRES'!$C$94*'PARAMÈTRES'!$C$95) -> 14.4 | J44: n × (4 a h + 4 côté × h fût)
...

Sheet DQE_DEVIS
A1: DÉTAIL QUANTITATIF ET ESTIMATIF (DQE) – DEVIS
A2: Montants en FCFA HT. Prix unitaires saisis dans PARAMÈTRES (section 10). TVA 18 %.
B4: N° | C4: Désignation | D4: Unité | E4: Quantité | F4: PU (FCFA) | G4: Montant (FCFA)
B6: LOT 1 – CHARPENTE MÉTALLIQUE
B7: 1.1 | C7: Fourniture et fabrication de la charpente (profilés, platines, boulonnerie, chutes) | D7: kg | E7: ='QUANTITATIF_CHARPENTE'!$I$76 -> 25987.835 | F7: ='PARAMÈTRES'!$C$158 -> 1150 | G7: ='DQE_DEVIS'!$E$7*'DQE_DEVIS'!$F$7 -> 29886011
B8: 1.2 | C8: Transport et montage de la charpente | D8: kg | E8: ='QUANTITATIF_CHARPENTE'!$I$76 -> 25987.835 | F8: ='PARAMÈTRES'!$C$159 -> 250 | G8: ='DQE_DEVIS'!$E$8*'DQE_DEVIS'!$F$8 -> 6496958.9
B9: 1.3 | C9: Protection anticorrosion (galvanisation ou peinture, climat tropical humide) | D9: =IF('PARAMÈTRES'!$C$59="Galvanisation à chaud","kg","m²") -> kg | E9: =IF('PARAMÈTRES'!$C$59="Galvanisation à chaud",'QUANTITATIF_CHARPENTE'!$I$79,'QUANTITATIF_CHARPENTE'!$I$80) -> 24287.697 | F9: =IF('PARAMÈTRES'!$C$59="Galvanisation à chaud",'PARAMÈTRES'!$C$160,'PARAMÈTRES'!$C$161) -> 450 | G9: ='DQE_DEVIS'!$E$9*'DQE_DEVIS'!$F$9 -> 10929464
B10: 1.4 | C10: Tiges d'ancrage avec écrous et rondelles | D10: u | E10: ='QUANTITATIF_CHARPENTE'!$E$64+'QUANTITATIF_CHARPENTE'!$E$65 -> 76 | F10: ='PARAMÈTRES'!$C$162 -> 6000 | G10: ='DQE_DEVIS'!$E$10*'DQE_DEVIS'!$F$10 -> 456000
B11: 1.5 | C11: Gabarits de pose des tiges d'ancrage | D11: u | E11: ='QUANTITATIF_CHARPENTE'!$E$68 -> 22 | F11: ='PARAMÈTRES'!$C$163 -> 7500 | G11: ='DQE_DEVIS'!$E$11*'DQE_DEVIS'!$F$11 -> 165000
C12: Sous-total LOT 1 | G12: ='DQE_DEVIS'!$G$7+'DQE_DEVIS'!$G$8+'DQE_DEVIS'!$G$9+'DQE_DEVIS'!$G$10+'DQE_DEVIS'!$G$11 -> 47933433
B14: LOT 2 – COUVERTURE
B15: 2.1 | C15: Couverture en tôles bac acier | D15: m² | E15: ='QUANTITATIF_CHARPENTE'!$E$36 -> 816.56792 | F15: ='PARAMÈTRES'!$C$164 -> 6500 | G15: ='DQE_DEVIS'!$E$15*'DQE_DEVIS'!$F$15 -> 5307691.5
B16: 2.2 | C16: Panneaux translucides | D16: m² | E16: ='QUANTITATIF_CHARPENTE'!$E$37 -> 82.232792 | F16: ='PARAMÈTRES'!$C$165 -> 12000 | G16: ='DQE_DEVIS'!$E$16*'DQE_DEVIS'!$F$16 -> 986793.5
B17: 2.3 | C17: Faîtières | D17: ml | E17: ='QUANTITATIF_CHARPENTE'!$E$38 -> 40.6 | F17: ='PARAMÈTRES'!$C$166 -> 4500 | G17: ='DQE_DEVIS'!$E$17*'DQE_DEVIS'!$F$17 -> 182700
B18: 2.4 | C18: Rives | D18: ml | E18: ='QUANTITATIF_CHARPENTE'!$E$39 -> 40.508764 | F18: ='PARAMÈTRES'!$C$167 -> 3500 | G18: ='DQE_DEVIS'!$E$18*'DQE_DEVIS'!$F$18 -> 141780.68
B19: 2.5 | C19: Larmiers et bavettes de couverture | D19: ml | E19: ='QUANTITATIF_CHARPENTE'!$E$40 -> 81.2 | F19: ='PARAMÈTRES'!$C$168 -> 3000 | G19: ='DQE_DEVIS'!$E$19*'DQE_DEVIS'!$F$19 -> 243600
B20: 2.6 | C20: Chéneaux d'eau | D20: ml | E20: ='QUANTITATIF_CHARPENTE'!$E$41 -> 80 | F20: ='PARAMÈTRES'!$C$169 -> 15000 | G20: ='DQE_DEVIS'!$E$20*'DQE_DEVIS'!$F$20 -> 1200000
B21: 2.7 | C21: Naissances EP | D21: u | E21: ='QUANTITATIF_CHARPENTE'!$E$42 -> 6 | F21: ='PARAMÈTRES'!$C$170 -> 7500 | G21: ='DQE_DEVIS'!$E$21*'DQE_DEVIS'!$F$21 -> 45000
B22: 2.8 | C22: Descentes EP PVC Ø110 | D22: ml | E22: ='QUANTITATIF_CHARPENTE'!$E$43 -> 36 | F22: ='PARAMÈTRES'!$C$171 -> 6000 | G22: ='DQE_DEVIS'!$E$22*'DQE_DEVIS'!$F$22 -> 216000
B23: 2.9 | C23: Skydomes avec chevêtres | D23: u | E23: ='QUANTITATIF_CHARPENTE'!$E$44 -> 4 | F23: ='PARAMÈTRES'!$C$172 -> 150000 | G23: ='DQE_DEVIS'!$E$23*'DQE_DEVIS'!$F$23 -> 600000
B24: 2.10 | C24: Vis autoforeuses | D24: u | E24: ='QUANTITATIF_CHARPENTE'!$E$69 -> 10093 | F24: ='PARAMÈTRES'!$C$173 -> 75 | G24: ='DQE_DEVIS'!$E$24*'DQE_DEVIS'!$F$24 -> 756975
B25: 2.11 | C25: Rivets de chéneaux | D25: u | E25: ='QUANTITATIF_CHARPENTE'!$E$45 -> 400 | F25: ='PARAMÈTRES'!$C$174 -> 25 | G25: ='DQE_DEVIS'!$E$25*'DQE_DEVIS'!$F$25 -> 10000
C26: Sous-total LOT 2 | G26: ='DQE_DEVIS'!$G$15+'DQE_DEVIS'!$G$16+'DQE_DEVIS'!$G$17+'DQE_DEVIS'!$G$18+'DQE_DEVIS'!$G$19+'DQE_DEVIS'!$G$20+'DQE_DEVIS'!$G$21+'DQE_DEVIS'!$G$22+'DQE_DEVIS'!$G$23+'DQE_DEVIS'!$G$24+'DQE_DEVIS'!$G$25 -> 9690540.7
B28: LOT 3 – BARDAGE ET MENUISERIES MÉTALLIQUES
B29: 3.1 | C29: Bardage en bac acier | D29: m² | E29: ='QUANTITATIF_CHARPENTE'!$E$52 -> 783.2 | F29: ='PARAMÈTRES'!$C$175 -> 6000 | G29: ='DQE_DEVIS'!$E$29*'DQE_DEVIS'!$F$29 -> 4699200
B30: 3.2 | C30: Larmiers de bardage (pied et angles) | D30: ml | E30: ='QUANTITATIF_CHARPENTE'!$E$55 -> 134.5 | F30: ='PARAMÈTRES'!$C$176 -> 3000 | G30: ='DQE_DEVIS'!$E$30*'DQE_DEVIS'!$F$30 -> 403500
B31: 3.3 | C31: Larmiers de portes coulissantes | D31: ml | E31: ='QUANTITATIF_CHARPENTE'!$E$53 -> 4.2 | F31: ='PARAMÈTRES'!$C$177 -> 3500 | G31: ='DQE_DEVIS'!$E$31*'DQE_DEVIS'!$F$31 -> 14700
B32: 3.4 | C32: Rails hauts de portes coulissantes | D32: ml | E32: ='QUANTITATIF_CHARPENTE'!$E$54 -> 8 | F32: ='PARAMÈTRES'!$C$178 -> 15000 | G32: ='DQE_DEVIS'!$E$32*'DQE_DEVIS'!$F$32 -> 120000
B33: 3.5 | C33: Portes coulissantes | D33: m² | E33: ='PARAMÈTRES'!$C$28*'PARAMÈTRES'!$C$29*'PARAMÈTRES'!$C$30 -> 18 | F33: ='PARAMÈTRES'!$C$179 -> 45000 | G33: ='DQE_DEVIS'!$E$33*'DQE_DEVIS'!$F$33 -> 810000
B34: 3.6 | C34: Portillons | D34: m² | E34: ='PARAMÈTRES'!$C$32*'PARAMÈTRES'!$C$33*'PARAMÈTRES'!$C$34 -> 22 | F34: ='PARAMÈTRES'!$C$180 -> 50000 | G34: ='DQE_DEVIS'!$E$34*'DQE_DEVIS'!$F$34 -> 1100000
C35: Sous-total LOT 3 | G35: ='DQE_DEVIS'!$G$29+'DQE_DEVIS'!$G$30+'DQE_DEVIS'!$G$31+'DQE_DEVIS'!$G$32+'DQE_DEVIS'!$G$33+'DQE_DEVIS'!$G$34 -> 7147400
B37: LOT 4 – TERRASSEMENTS
B38: 4.1 | C38: Décapage de l'emprise | D38: m² | E38: ='GROS_ŒUVRE'!$E$23 -> 924 | F38: ='PARAMÈTRES'!$C$181 -> 500 | G38: ='DQE_DEVIS'!$E$38*'DQE_DEVIS'!$F$38 -> 462000
B39: 4.2 | C39: Fouilles en puits et en rigole (profondeur 1,20 m) | D39: m³ | E39: ='GROS_ŒUVRE'!$E$24+'GROS_ŒUVRE'!$E$25+'GROS_ŒUVRE'!$E$26 -> 136.992 | F39: ='PARAMÈTRES'!$C$182 -> 4500 | G39: ='DQE_DEVIS'!$E$39*'DQE_DEVIS'!$F$39 -> 616464
B40: 4.3 | C40: Remblai en latérite compactée à 95 % OPM | D40: m³ | E40: ='GROS_ŒUVRE'!$E$27 -> 197.75563 | F40: ='PARAMÈTRES'!$C$183 -> 9000 | G40: ='DQE_DEVIS'!$E$40*'DQE_DEVIS'!$F$40 -> 1779800.6
B41: 4.4 | C41: Évacuation des déblais | D41: m³ | E41: ='GROS_ŒUVRE'!$E$29 -> 402.24 | F41: ='PARAMÈTRES'!$C$184 -> 3500 | G41: ='DQE_DEVIS'!$E$41*'DQE_DEVIS'!$F$41 -> 1407840
C42: Sous-total LOT 4 | G42: ='DQE_DEVIS'!$G$38+'DQE_DEVIS'!$G$39+'DQE_DEVIS'!$G$40+'DQE_DEVIS'!$G$41 -> 4266104.6
B44: LOT 5 – GROS ŒUVRE (matériaux et main d'œuvre)
B45: 5.1 | C45: Ciment CPJ 42.5 (sacs de 50 kg) | D45: sacs | E45: ='GROS_ŒUVRE'!$E$99 -> 1311 | F45: ='PARAMÈTRES'!$C$185 -> 5500 | G45: ='DQE_DEVIS'!$E$45*'DQE_DEVIS'!$F$45 -> 7210500
B46: 5.2 | C46: Sable | D46: m³ | E46: ='GROS_ŒUVRE'!$E$100 -> 116.74572 | F46: ='PARAMÈTRES'!$C$186 -> 12000 | G46: ='DQE_DEVIS'!$E$46*'DQE_DEVIS'!$F$46 -> 1400948.7
...

Sheet RÉCAP_GABARITS
A1: RÉCAPITULATIF COMPARATIF DES 7 GABARITS
A2: Calculé avec les paramètres en vigueur (hauteur, pente, prix…) et les profilés automatiques. Façades : variante bardage bac acier et variante agglos 15 creux.
B4: Gabarit | C4: Système | D4: Surface (m²) | E4: Tonnage acier (t) | F4: kg/m² | G4: Tôles (m²) | H4: Béton (m³) | I4: Aciers HA (kg) | J4: Coût HT (FCFA) | K4: Coût HT / m² | L4: Coût façade bardage | M4: Coût façade agglos
B5: 10 × 30 | C5: ='CALC_GABARITS'!$D$11 -> Portique IPE avec jarrets | D5: ='CALC_GABARITS'!$D$31 -> 300 | E5: ='CALC_GABARITS'!$D$356 -> 10.270178 | F5: ='CALC_GABARITS'!$D$357 -> 34.233927 | G5: ='CALC_GABARITS'!$D$256 -> 304.13205 | H5: ='CALC_GABARITS'!$D$531 -> 79.1485 | I5: ='CALC_GABARITS'!$D$548 -> 2576.5903 | J5: ='CALC_GABARITS'!$D$688 -> 42081885 | K5: ='CALC_GABARITS'!$D$691 -> 140272.95 | L5: ='CALC_GABARITS'!$E$693 -> 5896757.3 | M5: ='CALC_GABARITS'!$F$693 -> 7329355.2
B6: 15 × 20 | C6: ='CALC_GABARITS'!$G$11 -> Portique IPE avec jarrets | D6: ='CALC_GABARITS'!$G$31 -> 300 | E6: ='CALC_GABARITS'!$G$356 -> 11.543299 | F6: ='CALC_GABARITS'!$G$357 -> 38.477663 | G6: ='CALC_GABARITS'!$G$256 -> 307.17021 | H6: ='CALC_GABARITS'!$G$531 -> 76.9025 | I6: ='CALC_GABARITS'!$G$548 -> 2539.4625 | J6: ='CALC_GABARITS'!$G$688 -> 43222389 | K6: ='CALC_GABARITS'!$G$691 -> 144074.63 | L6: ='CALC_GABARITS'!$H$693 -> 5020447 | M6: ='CALC_GABARITS'!$I$693 -> 6780431.7
B7: 15 × 30 | C7: ='CALC_GABARITS'!$J$11 -> Portique IPE avec jarrets | D7: ='CALC_GABARITS'!$J$31 -> 450 | E7: ='CALC_GABARITS'!$J$356 -> 14.307908 | F7: ='CALC_GABARITS'!$J$357 -> 31.795351 | G7: ='CALC_GABARITS'!$J$256 -> 459.07807 | H7: ='CALC_GABARITS'!$J$531 -> 110.9225 | I7: ='CALC_GABARITS'!$J$548 -> 3663.0847 | J7: ='CALC_GABARITS'!$J$688 -> 56330713 | K7: ='CALC_GABARITS'!$J$691 -> 125179.36 | L7: ='CALC_GABARITS'!$K$693 -> 6758131.9 | M7: ='CALC_GABARITS'!$L$693 -> 8434210.9
B8: 20 × 20 | C8: ='CALC_GABARITS'!$M$11 -> Portique IPE avec jarrets | D8: ='CALC_GABARITS'!$M$31 -> 400 | E8: ='CALC_GABARITS'!$M$356 -> 16.051438 | F8: ='CALC_GABARITS'!$M$357 -> 40.128595 | G8: ='CALC_GABARITS'!$M$256 -> 411.48027 | H8: ='CALC_GABARITS'!$M$531 -> 98.6765 | I8: ='CALC_GABARITS'!$M$548 -> 3256.6824 | J8: ='CALC_GABARITS'!$M$688 -> 56397658 | K8: ='CALC_GABARITS'!$M$691 -> 140994.14 | L8: ='CALC_GABARITS'!$N$693 -> 5902975.5 | M8: ='CALC_GABARITS'!$O$693 -> 7916598.7
B9: 20 × 40 | C9: ='CALC_GABARITS'!$P$11 -> Portique IPE avec jarrets | D9: ='CALC_GABARITS'!$P$31 -> 800 | E9: ='CALC_GABARITS'!$P$356 -> 25.987835 | F9: ='CALC_GABARITS'!$P$357 -> 32.484794 | G9: ='CALC_GABARITS'!$P$256 -> 816.56792 | H9: ='CALC_GABARITS'!$P$531 -> 188.0365 | I9: ='CALC_GABARITS'!$P$548 -> 6214.2789 | J9: ='CALC_GABARITS'!$P$688 -> 94639719 | K9: ='CALC_GABARITS'!$P$691 -> 118299.65 | L9: ='CALC_GABARITS'!$Q$693 -> 9270590.1 | M9: ='CALC_GABARITS'!$R$693 -> 11463852
B10: 30 × 40 | C10: ='CALC_GABARITS'!$S$11 -> Portique IPE renforcé | D10: ='CALC_GABARITS'!$S$31 -> 1200 | E10: ='CALC_GABARITS'!$S$356 -> 44.985603 | F10: ='CALC_GABARITS'!$S$357 -> 37.488002 | G10: ='CALC_GABARITS'!$S$256 -> 1227.7319 | H10: ='CALC_GABARITS'!$S$531 -> 271.1605 | I10: ='CALC_GABARITS'!$S$548 -> 8993.1874 | J10: ='CALC_GABARITS'!$S$688 -> 1.466907e+08 | K10: ='CALC_GABARITS'!$S$691 -> 122242.25 | L10: ='CALC_GABARITS'!$T$693 -> 11206036 | M10: ='CALC_GABARITS'!$U$693 -> 13590953
B11: 40 × 40 | C11: ='CALC_GABARITS'!$V$11 -> Ferme treillis | D11: ='CALC_GABARITS'!$V$31 -> 1600 | E11: ='CALC_GABARITS'!$V$356 -> 62.380658 | F11: ='CALC_GABARITS'!$V$357 -> 38.987911 | G11: ='CALC_GABARITS'!$V$256 -> 1638.8958 | H11: ='CALC_GABARITS'!$V$531 -> 354.7085 | I11: ='CALC_GABARITS'!$V$548 -> 11800.033 | J11: ='CALC_GABARITS'!$V$688 -> 1.9767797e+08 | K11: ='CALC_GABARITS'!$V$691 -> 123548.73 | L11: ='CALC_GABARITS'!$W$693 -> 16079603 | M11: ='CALC_GABARITS'!$X$693 -> 18483818
B13: Contrôle de cohérence (gabarit actif) : écart entre le moteur et le DQE | H13: =IFERROR(IF(ABS(INDEX('CALC_GABARITS'!$D$688:$X$688,1,(MATCH('ACCUEIL'!$D$6,'PARAMÈTRES'!$G$5:$G$11,0)-1)*3+1)-'DQE_DEVIS'!$G$64)<1,"OK (écart nul)","ÉCART : vérifier les forçages de profilés"),"PERSONNALISÉ : sans objet") -> OK (écart nul)
B14: Le comparatif utilise les profilés automatiques : un forçage en PRÉDIMENSIONNEMENT ne s'applique qu'au gabarit actif. Coûts façade = bardage + lisses + liernes + larmiers, ou agglos + chaînages + raidisseurs + linteaux (+ enduit), main d'œuvre comprise.

Sheet PLANS
B1: PLANCHE 1 / 7 – VUE EN PLAN – IMPLANTATION
B28: VUE EN PLAN – IMPLANTATION | J28: Planche n° 1 / 7 | L28: Date : | M28: =TODAY() -> 46301
B29: ="Gabarit "&'ACCUEIL'!$D$6&" : portée "&FIXED('PARAMÈTRES'!$C$9,2,TRUE)&" m × longueur "&FIXED('PARAMÈTRES'!$C$10,2,TRUE)&" m – H sablière "&FIXED('PARAMÈTRES'!$C$11,2,TRUE)&" m – pente "&FIXED('PARAMÈTRES'!$C$12*100,1,TRUE)&" % – "&'PRÉDIMENSIONNEMENT'!$C$26&" – façade : "&'PARAMÈTRES'!$C$51 -> Gabarit 20 × 40 : portée 20.00 m × longueur 40.00 m – H sablière 6.00 m – pente 16.0 % – Portique IPE avec jarrets – façade : Bardage bac acier | J29: ESQUISSE NON CONTRACTUELLE
B30: Couleurs : charpente en bleu · contreventements en orange · béton en gris · aciers en rouge · maçonnerie en marron clair · cotes et baies en noir · translucides en bleu clair · remblai en latérite | J30: BON POUR ACCORD
B31: ="Poteaux de portique ■ "&'PRÉDIMENSIONNEMENT'!$E$69&" sur semelles "&'PARAMÈTRES'!$C$89*100&" × "&'PARAMÈTRES'!$C$89*100&" ; poteaux de pignon ● "&'PRÉDIMENSIONNEMENT'!$E$75&" sur semelles "&'PARAMÈTRES'!$C$92*100&" × "&'PARAMÈTRES'!$C$92*100&" ; semelles filantes en pointillés." -> Poteaux de portique ■ IPE 330 sur semelles 120 × 120 ; poteaux de pignon ● IPE 220 sur semelles 80 × 80 ; semelles filantes en pointillés. | J31: Date :
J32: Signature :
B33: Échelle : automatique (même échelle en X et en Y) – cotes en mètres
B37: PLANCHE 2 / 7 – COUPE TRANSVERSALE – PORTIQUE TYPE
B64: COUPE TRANSVERSALE – PORTIQUE TYPE | J64: Planche n° 2 / 7 | L64: Date : | M64: =TODAY() -> 46301
B65: ="Gabarit "&'ACCUEIL'!$D$6&" : portée "&FIXED('PARAMÈTRES'!$C$9,2,TRUE)&" m × longueur "&FIXED('PARAMÈTRES'!$C$10,2,TRUE)&" m – H sablière "&FIXED('PARAMÈTRES'!$C$11,2,TRUE)&" m – pente "&FIXED('PARAMÈTRES'!$C$12*100,1,TRUE)&" % – "&'PRÉDIMENSIONNEMENT'!$C$26&" – façade : "&'PARAMÈTRES'!$C$51 -> Gabarit 20 × 40 : portée 20.00 m × longueur 40.00 m – H sablière 6.00 m – pente 16.0 % – Portique IPE avec jarrets – façade : Bardage bac acier | J65: ESQUISSE NON CONTRACTUELLE
B66: Couleurs : charpente en bleu · contreventements en orange · béton en gris · aciers en rouge · maçonnerie en marron clair · cotes et baies en noir · translucides en bleu clair · remblai en latérite | J66: BON POUR ACCORD
B67: ="Croix de Saint-André dans les travées d'extrémité et une travée sur 5 ("&'PRÉDIMENSIONNEMENT'!$C$44&" travées). "&IF('PRÉDIMENSIONNEMENT'!$C$50=1,"Lisses "&'PRÉDIMENSIONNEMENT'!$E$78&" e = "&FIXED('PARAMÈTRES'!$C$17,2,TRUE)&" m","Façade maçonnée : lisses sans objet")&IF('PRÉDIMENSIONNEMENT'!$C$51=1," ; maçonnerie agglos 15 creux sur "&FIXED('PRÉDIMENSIONNEMENT'!$C$49,2,TRUE)&" m avec chaînages gris.",".") -> Croix de Saint-André dans les travées d'extrémité et une travée sur 5 (3 travées). Lisses C 160 e = 1.80 m. | J67: Date :
J68: Signature :
B69: Échelle : automatique (même échelle en X et en Y) – cotes en mètres
B73: PLANCHE 3 / 7 – ÉLÉVATION LONG-PAN
B100: ÉLÉVATION LONG-PAN | J100: Planche n° 3 / 7 | L100: Date : | M100: =TODAY() -> 46301
B101: ="Gabarit "&'ACCUEIL'!$D$6&" : portée "&FIXED('PARAMÈTRES'!$C$9,2,TRUE)&" m × longueur "&FIXED('PARAMÈTRES'!$C$10,2,TRUE)&" m – H sablière "&FIXED('PARAMÈTRES'!$C$11,2,TRUE)&" m – pente "&FIXED('PARAMÈTRES'!$C$12*100,1,TRUE)&" % – "&'PRÉDIMENSIONNEMENT'!$C$26&" – façade : "&'PARAMÈTRES'!$C$51 -> Gabarit 20 × 40 : portée 20.00 m × longueur 40.00 m – H sablière 6.00 m – pente 16.0 % – Portique IPE avec jarrets – façade : Bardage bac acier | J101: ESQUISSE NON CONTRACTUELLE
B102: Couleurs : charpente en bleu · contreventements en orange · béton en gris · aciers en rouge · maçonnerie en marron clair · cotes et baies en noir · translucides en bleu clair · remblai en latérite | J102: BON POUR ACCORD
B103: ="Croix de Saint-André dans les travées d'extrémité et une travée sur 5 ("&'PRÉDIMENSIONNEMENT'!$C$44&" travées). "&IF('PRÉDIMENSIONNEMENT'!$C$50=1,"Lisses "&'PRÉDIMENSIONNEMENT'!$E$78&" e = "&FIXED('PARAMÈTRES'!$C$17,2,TRUE)&" m","Façade maçonnée : lisses sans objet")&IF('PRÉDIMENSIONNEMENT'!$C$51=1," ; maçonnerie agglos 15 creux sur "&FIXED('PRÉDIMENSIONNEMENT'!$C$49,2,TRUE)&" m avec chaînages gris.",".") -> Croix de Saint-André dans les travées d'extrémité et une travée sur 5 (3 travées). Lisses C 160 e = 1.80 m. | J103: Date :
J104: Signature :
B105: Échelle : automatique (même échelle en X et en Y) – cotes en mètres
B109: PLANCHE 4 / 7 – ÉLÉVATION PIGNON
B136: ÉLÉVATION PIGNON | J136: Planche n° 4 / 7 | L136: Date : | M136: =TODAY() -> 46301
B137: ="Gabarit "&'ACCUEIL'!$D$6&" : portée "&FIXED('PARAMÈTRES'!$C$9,2,TRUE)&" m × longueur "&FIXED('PARAMÈTRES'!$C$10,2,TRUE)&" m – H sablière "&FIXED('PARAMÈTRES'!$C$11,2,TRUE)&" m – pente "&FIXED('PARAMÈTRES'!$C$12*100,1,TRUE)&" % – "&'PRÉDIMENSIONNEMENT'!$C$26&" – façade : "&'PARAMÈTRES'!$C$51 -> Gabarit 20 × 40 : portée 20.00 m × longueur 40.00 m – H sablière 6.00 m – pente 16.0 % – Portique IPE avec jarrets – façade : Bardage bac acier | J137: ESQUISSE NON CONTRACTUELLE
B138: Couleurs : charpente en bleu · contreventements en orange · béton en gris · aciers en rouge · maçonnerie en marron clair · cotes et baies en noir · translucides en bleu clair · remblai en latérite | J138: BON POUR ACCORD
B139: ="Croix de Saint-André dans les travées d'extrémité et une travée sur 5 ("&'PRÉDIMENSIONNEMENT'!$C$44&" travées). "&IF('PRÉDIMENSIONNEMENT'!$C$50=1,"Lisses "&'PRÉDIMENSIONNEMENT'!$E$78&" e = "&FIXED('PARAMÈTRES'!$C$17,2,TRUE)&" m","Façade maçonnée : lisses sans objet")&IF('PRÉDIMENSIONNEMENT'!$C$51=1," ; maçonnerie agglos 15 creux sur "&FIXED('PRÉDIMENSIONNEMENT'!$C$49,2,TRUE)&" m avec chaînages gris.",".") -> Croix de Saint-André dans les travées d'extrémité et une travée sur 5 (3 travées). Lisses C 160 e = 1.80 m. | J139: Date :
J140: Signature :
B141: Échelle : automatique (même échelle en X et en Y) – cotes en mètres
B145: PLANCHE 5 / 7 – VUE EN PLAN TOITURE – CALEPINAGE
B172: VUE EN PLAN TOITURE – CALEPINAGE | J172: Planche n° 5 / 7 | L172: Date : | M172: =TODAY() -> 46301
B173: ="Gabarit "&'ACCUEIL'!$D$6&" : portée "&FIXED('PARAMÈTRES'!$C$9,2,TRUE)&" m × longueur "&FIXED('PARAMÈTRES'!$C$10,2,TRUE)&" m – H sablière "&FIXED('PARAMÈTRES'!$C$11,2,TRUE)&" m – pente "&FIXED('PARAMÈTRES'!$C$12*100,1,TRUE)&" % – "&'PRÉDIMENSIONNEMENT'!$C$26&" – façade : "&'PARAMÈTRES'!$C$51 -> Gabarit 20 × 40 : portée 20.00 m × longueur 40.00 m – H sablière 6.00 m – pente 16.0 % – Portique IPE avec jarrets – façade : Bardage bac acier | J173: ESQUISSE NON CONTRACTUELLE
B174: Couleurs : charpente en bleu · contreventements en orange · béton en gris · aciers en rouge · maçonnerie en marron clair · cotes et baies en noir · translucides en bleu clair · remblai en latérite | J174: BON POUR ACCORD
B175: ="Translucides : "&FIXED('PARAMÈTRES'!$C$45*100,0,TRUE)&" % – skydomes : "&'PARAMÈTRES'!$C$37&" – descentes EP : "&'PRÉDIMENSIONNEMENT'!$C$64&" – poutre au vent : "&'PRÉDIMENSIONNEMENT'!$C$44&" travées – liernes : "&'PRÉDIMENSIONNEMENT'!$C$43&" ligne(s) par travée." -> Translucides : 10 % – skydomes : 4 – descentes EP : 6 – poutre au vent : 3 travées – liernes : 1 ligne(s) par travée. | J175: Date :
J176: Signature :
B177: Échelle : automatique (même échelle en X et en Y) – cotes en mètres
B181: PLANCHE 6 / 7 – COUPE DE FONDATION ET DALLAGE (DÉTAIL)
B208: COUPE DE FONDATION ET DALLAGE (DÉTAIL) | J208: Planche n° 6 / 7 | L208: Date : | M208: =TODAY() -> 46301
B209: ="Gabarit "&'ACCUEIL'!$D$6&" : portée "&FIXED('PARAMÈTRES'!$C$9,2,TRUE)&" m × longueur "&FIXED('PARAMÈTRES'!$C$10,2,TRUE)&" m – H sablière "&FIXED('PARAMÈTRES'!$C$11,2,TRUE)&" m – pente "&FIXED('PARAMÈTRES'!$C$12*100,1,TRUE)&" % – "&'PRÉDIMENSIONNEMENT'!$C$26&" – façade : "&'PARAMÈTRES'!$C$51 -> Gabarit 20 × 40 : portée 20.00 m × longueur 40.00 m – H sablière 6.00 m – pente 16.0 % – Portique IPE avec jarrets – façade : Bardage bac acier | J209: ESQUISSE NON CONTRACTUELLE
B210: Couleurs : charpente en bleu · contreventements en orange · béton en gris · aciers en rouge · maçonnerie en marron clair · cotes et baies en noir · translucides en bleu clair · remblai en latérite | J210: BON POUR ACCORD
