Workbook
Name p_L: 'Paramètres'!$C$6
Name p_B: 'Paramètres'!$C$7
Name p_ESP: 'Paramètres'!$C$8
Name p_PENTE: 'Paramètres'!$C$9
Name p_H: 'Paramètres'!$C$10
Name p_HFOND: 'Paramètres'!$C$11
Name p_EP: 'Paramètres'!$C$12
Name p_PL: 'Paramètres'!$C$13
Name p_PH: 'Paramètres'!$C$14
Name p_NPIL: 'Paramètres'!$C$15
Name p_APO: 'Paramètres'!$C$16
Name p_NPO: 'Paramètres'!$C$17
Name p_BIPE: 'Paramètres'!$C$18
Name p_BPIL: 'Paramètres'!$C$19
Name p_BCH: 'Paramètres'!$C$20
Name p_HCH: 'Paramètres'!$C$21
Name p_ZCHI: 'Paramètres'!$C$22
Name p_LINH: 'Paramètres'!$C$23
Name p_FRL: 'Paramètres'!$C$25
Name p_FRH: 'Paramètres'!$C$26
Name p_PROP: 'Paramètres'!$C$27
Name p_SFB: 'Paramètres'!$C$28
Name p_SFH: 'Paramètres'!$C$29
Name p_SIA: 'Paramètres'!$C$30
Name p_SIH: 'Paramètres'!$C$31
Name p_FPA: 'Paramètres'!$C$32
Name p_ESI: 'Paramètres'!$C$33
Name p_AFUT: 'Paramètres'!$C$34
Name p_NTIG: 'Paramètres'!$C$35
Name p_FOIS: 'Paramètres'!$C$36
Name p_EPDAL: 'Paramètres'!$C$38
Name p_EDAL: 'Paramètres'!$C$39
Name p_NNAP: 'Paramètres'!$C$40
Name p_RDAL: 'Paramètres'!$C$41
Name p_NCHA: 'Paramètres'!$C$42
Name p_EPLAT: 'Paramètres'!$C$43
Name p_COUCHE: 'Paramètres'!$C$44
Name p_KGIPE: 'Paramètres'!$C$46
Name p_KGPLA: 'Paramètres'!$C$47
Name p_KGCOR: 'Paramètres'!$C$48
Name p_NPAL: 'Paramètres'!$C$49
Name p_NPV: 'Paramètres'!$C$50
Name p_GOUS: 'Paramètres'!$C$51
Name p_KG6: 'Paramètres'!$C$53
Name p_KG10: 'Paramètres'!$C$54
Name p_KG12: 'Paramètres'!$C$55
Name p_CHUTES: 'Paramètres'!$C$56
Name p_RCH: 'Paramètres'!$C$58
Name p_EPAN: 'Paramètres'!$C$59
Name p_KGZ: 'Paramètres'!$C$60
Name p_DEB: 'Paramètres'!$C$61
Name p_PO: 'Paramètres'!$C$63
Name p_FC: 'Paramètres'!$C$64
Name p_FG: 'Paramètres'!$C$65
Name p_ALEA: 'Paramètres'!$C$66
Name p_BEN: 'Paramètres'!$C$67
Name p_TVA: 'Paramètres'!$C$68
Name p_K: 'Paramètres'!$C$69
Name p_P: 'Paramètres'!$C$71
Name p_FL: 'Paramètres'!$C$72

Sheet Lisez-moi
A1: ASSEYA SILVER CONSTRUCTION - Construction métallique et bâtiment - Bouaké - Tél : 07 08 39 02 66 / 05 05 10 76 82 - Email : asseyasilver@gmail.com
A2: Notice du classeur - Bâtiment industriel 30,00 x 10,00 m - 04/10/2026 - établi par Moulo Jean Claude, Technicien Génie Civil BTP - BAEL 91 mod. 99 / EC2
B4: ENTREPRISE
B5: Raison sociale | C5: ASSEYA SILVER CONSTRUCTION (ASC) - Construction métallique et bâtiment
B6: Siège | C6: Bouaké
B7: Téléphone | C7: 07 08 39 02 66 / 05 05 10 76 82
B8: Email | C8: asseyasilver@gmail.com
B9: N° CC / RCCM | C9: 2245191 D / CI-BKE-01-2022-B13-00153
B10: Banque | C10: Bank of Africa - compte n° 004619070000
B11: Régime fiscal | C11: TEE - Bouaké 1
B13: Objet | C13: Métré, déboursé sec et devis quantitatif et estimatif (DQE) d'un bâtiment industriel 30 x 10 m, murs en agglos 15 pleins, piliers IPE 220 tous les 5 m encadrés de 2 poteaux BA, contreventements en cornières 50x50x5, entrée 6 m, toiture 2 versants à 20 %, dallage BA 20 cm double nappe HA10, semelles isolées 80 x 80 x 30 en HA12 avec tiges d'ancrage.
B14: Auteur | C14: Moulo Jean Claude - Technicien Génie Civil BTP - Abidjan
B15: Date | C15: 04/10/2026 - prix du marché d'Abidjan à confirmer par cotations fournisseurs
B17: COMMENT MODIFIER
B18: Cellules bleues sur fond jaune | C18: Données modifiables : dimensions, épaisseurs, prix unitaires, rendements, coefficients. Tout le reste se recalcule automatiquement.
B19: Texte noir | C19: Formules - ne pas écraser.
B20: Sol de bonne portance | C20: Feuille « Paramètres » : mettre p_EPLAT = 0,20 (une seule couche de latérite) au lieu de 0,40.
B21: Changer un prix | C21: Feuille « Prix » colonne D : la modification se répercute sur tous les sous-détails, le DS et le DQE.
B22: Changer un rendement | C22: Feuille « Sous-détails » colonne F (quantité par unité d'ouvrage).
B24: FEUILLES
B25: Paramètres | C25: Dimensions, hypothèses, coefficients K et TVA, grandeurs calculées (noms p_...).
B26: Prix | C26: Prix de base : matériaux, main-d'œuvre (h.j), matériel (noms px_...).
B27: Aciers | C27: Nomenclature des aciers HA6 / HA10 / HA12 par lot, nombre de barres de 12 m.
B28: Métré | C28: Avant-métré : formule de chaque quantité (noms q_...).
B29: Sous-détails | C29: Décomposition matériaux / main-d'œuvre / matériel de chaque prix unitaire.
B30: Déboursé sec | C30: Déboursé sec par article et par lot, répartition par nature.
B31: DQE | C31: Devis quantitatif et estimatif : PU = DS x K arrondi à 5 FCFA, récapitulatif HT / TVA 18 % / TTC.
B32: Matériaux et MO | C32: Liste de commande des matériaux et besoins en main-d'œuvre et matériel.
B34: HYPOTHÈSES CLÉS
B35: Piliers | C35: 17 piliers en IPE 220 (S235) de ±0,00 à +6,00 sur platine 15 mm et 4 tiges d'ancrage M20 ; 2 poteaux BA 15x15 (4 HA10, cadres HA6 e = 15) de part et d'autre de chaque IPE.
B36: Contreventements | C36: Cornières 50x50x5 : 4 palées verticales en croix (travées d'extrémité des long pans) et poutre au vent dans 2 travées de toiture.
B37: Semelles isolées | C37: 80 x 80 x 30 cm, fond de fouille à -1,20 m, nappe HA12 e = 15 cm dans les 2 sens, fût BA 40 x 40 (4 HA12) jusqu'à ±0,00 recevant les 4 tiges d'ancrage M20 de la platine de l'IPE.
B38: Dallage | C38: 20 cm, béton dosé à 350 kg/m³, double nappe HA10 e = 20 cm, chaises HA10, polyane, joints sciés maille 5 m.
B39: Forme | C39: Purge et rechargement en latérite par couches de 20 cm compactées à 95 % OPM : 40 cm si mauvaise portance (valeur par défaut), 20 cm sinon.
B40: Options | C40: Lots 6 à 8 (enduits, fermes + pannes Z 120x2 + tôles bacs 5 ondes, portail) chiffrés séparément.

Sheet Paramètres
A1: ASSEYA SILVER CONSTRUCTION - Construction métallique et bâtiment - Bouaké - Tél : 07 08 39 02 66 / 05 05 10 76 82 - Email : asseyasilver@gmail.com
A2: Paramètres et hypothèses - Bâtiment industriel 30,00 x 10,00 m - 04/10/2026 - établi par Moulo Jean Claude, Technicien Génie Civil BTP - BAEL 91 mod. 99 / EC2
A4: Nom | B4: Désignation | C4: Valeur | D4: Unité | E4: Commentaire / source
A5: GÉOMÉTRIE
A6: p_L | B6: Longueur du bâtiment entre axes | C6: 30 | D6: m | E6: Donnée du maître d'ouvrage
A7: p_B | B7: Largeur du bâtiment entre axes | C7: 10 | D7: m | E7: Donnée du maître d'ouvrage
A8: p_ESP | B8: Espacement des piliers | C8: 5 | D8: m | E8: Donnée du maître d'ouvrage
A9: p_PENTE | B9: Pente de la toiture (2 versants) | C9: 0.2 | D9: - | E9: Donnée : 20 %
A10: p_H | B10: Hauteur élévation (TN → dessus chaînage haut) | C10: 6 | D10: m | E10: Donnée : 6 m
A11: p_HFOND | B11: Hauteur maçonnerie agglos en fondation | C11: 1 | D11: m | E11: Donnée : 1 m
A12: p_EP | B12: Épaisseur des murs (agglos 15 pleins) | C12: 0.15 | D12: m | E12: Donnée
A13: p_PL | B13: Largeur de l'entrée | C13: 6 | D13: m | E13: Donnée : 6 m
A14: p_PH | B14: Hauteur du portail | C14: 4.5 | D14: m | E14: Hypothèse
A15: p_NPIL | B15: Nombre de piliers IPE 220 | C15: =2*(p_L/p_ESP+1)+3 -> 17 | D15: u | E15: 7 par long pan + 1 pignon Ouest + 2 encadrement entrée
A16: p_APO | B16: Poteaux BA de part et d'autre des IPE : côté | C16: 0.15 | D16: m | E16: 2 poteaux 15x15 par pilier
A17: p_NPO | B17: Nombre de poteaux BA par pilier | C17: 2 | D17: u | E17: Donnée : deux poteaux autour de chaque pilier
A18: p_BIPE | B18: Largeur d'aile IPE 220 | C18: 0.11 | D18: m | E18: IPE 220 : h = 220 mm, b = 110 mm
A19: p_BPIL | B19: Emprise d'un pilier dans le mur (poteau + IPE + poteau) | C19: =p_NPO*p_APO+p_BIPE -> 0.41 | D19: m
A20: p_BCH | B20: Chaînages : largeur | C20: 0.15 | D20: m
A21: p_HCH | B21: Chaînages : hauteur | C21: 0.2 | D21: m | E21: Chaînages bas, intermédiaire et haut 15x20
A22: p_ZCHI | B22: Niveau du chaînage intermédiaire | C22: 3 | D22: m | E22: Hypothèse : mi-hauteur
A23: p_LINH | B23: Hauteur du linteau d'entrée | C23: 0.4 | D23: m | E23: Linteau 15x40
A24: FONDATIONS
A25: p_FRL | B25: Largeur des fouilles en rigole | C25: 0.6 | D25: m
A26: p_FRH | B26: Profondeur des fouilles (rigoles et puits) | C26: 1.2 | D26: m | E26: Donnée : 120 cm
A27: p_PROP | B27: Épaisseur béton de propreté | C27: 0.05 | D27: m
A28: p_SFB | B28: Semelle filante : largeur | C28: 0.4 | D28: m
A29: p_SFH | B29: Semelle filante : hauteur | C29: 0.15 | D29: m
A30: p_SIA | B30: Semelle isolée : côté | C30: 0.8 | D30: m | E30: Donnée : 80 x 80 cm
A31: p_SIH | B31: Semelle isolée : hauteur | C31: 0.3 | D31: m | E31: Hypothèse (≥ (A-a)/4 = 0,16 m)
A32: p_FPA | B32: Fouille en puits : côté | C32: =p_SIA+0.20 -> 1 | D32: m | E32: 10 cm de jeu de chaque côté
A33: p_ESI | B33: Semelle isolée : espacement des HA12 | C33: 0.15 | D33: m
A34: p_AFUT | B34: Fût BA sous platine : côté | C34: 0.4 | D34: m | E34: Fût 40x40 de -0,85 à ±0,00, 4 HA12
A35: p_NTIG | B35: Tiges d'ancrage M20 par pilier | C35: 4 | D35: u | E35: L = 600 mm coudées, écrous + rondelles
A36: p_FOIS | B36: Coefficient de foisonnement des terres | C36: 1.25 | D36: -
A37: DALLAGE
A38: p_EPDAL | B38: Épaisseur du dallage | C38: 0.2 | D38: m | E38: Donnée : 20 cm
A39: p_EDAL | B39: Maille des armatures du dallage | C39: 0.2 | D39: m | E39: HA10 e = 20 cm dans les 2 sens
A40: p_NNAP | B40: Nombre de nappes | C40: 2 | D40: u | E40: Donnée : double nappe HA10
A41: p_RDAL | B41: Majoration recouvrements dallage | C41: 1.1 | D41: -
...

Sheet Prix
A1: ASSEYA SILVER CONSTRUCTION - Construction métallique et bâtiment - Bouaké - Tél : 07 08 39 02 66 / 05 05 10 76 82 - Email : asseyasilver@gmail.com
A2: Prix de base - Bâtiment industriel 30,00 x 10,00 m - 04/10/2026 - établi par Moulo Jean Claude, Technicien Génie Civil BTP - BAEL 91 mod. 99 / EC2
A4: Code | B4: Désignation | C4: Unité | D4: Prix unitaire (FCFA) | E4: Catégorie
A5: MATÉRIAUX
A6: ciment | B6: Ciment CPJ 42,5 (sac 50 kg) | C6: sac | D6: 5800 | E6: Matériaux
A7: sable | B7: Sable lavé | C7: m³ | D7: 12000 | E7: Matériaux
A8: gravier | B8: Gravier concassé 5/15 - 15/25 | C8: m³ | D8: 25000 | E8: Matériaux
A9: eau | B9: Eau | C9: m³ | D9: 1000 | E9: Matériaux
A10: agglo | B10: Agglo 15 plein 40x20x15 rendu chantier | C10: u | D10: 500 | E10: Matériaux
A11: ha6 | B11: Acier HA6 FeE500 (barre 12 m = 2,66 kg à 2 300) | C11: kg | D11: 865 | E11: Matériaux
A12: ha10 | B12: Acier HA10 FeE500 (barre 12 m = 7,40 kg à 6 000) | C12: kg | D12: 810 | E12: Matériaux
A13: ha12 | B13: Acier HA12 FeE500 (barre 12 m = 10,66 kg à 8 500) | C13: kg | D13: 800 | E13: Matériaux
A14: fil | B14: Fil recuit | C14: kg | D14: 1500 | E14: Matériaux
A15: bois | B15: Bois de coffrage (amorti 3 emplois) | C15: m² | D15: 1800 | E15: Matériaux
A16: pointes | B16: Pointes | C16: kg | D16: 1500 | E16: Matériaux
A17: huile | B17: Huile de décoffrage | C17: L | D17: 1000 | E17: Matériaux
... A36: ff_portail | B36: Portail : tubes, tôle 15/10, rail, roulettes, peinture | C36: ft | D36: 1600000 | E36: Matériaux
A37: MAIN-D'ŒUVRE
A38: mo_macon | B38: Maçon | C38: h.j | D38: 10000 | E38: Main-d'œuvre
A39: mo_ferr | B39: Ferrailleur | C39: h.j | D39: 10000 | E39: Main-d'œuvre
A40: mo_coff | B40: Coffreur | C40: h.j | D40: 10000 | E40: Main-d'œuvre
A41: mo_soud | B41: Soudeur / couvreur | C41: h.j | D41: 15000 | E41: Main-d'œuvre
A42: mo_tech | B42: Technicien | C42: h.j | D42: 15000 | E42: Main-d'œuvre
A43: mo_man | B43: Manœuvre | C43: h.j | D43: 5000 | E43: Main-d'œuvre
A44: MATÉRIEL
A45: mt_bet | B45: Bétonnière 350 L (location) | C45: j | D45: 25000 | E45: Matériel
A46: mt_vib | B46: Vibreur (location) | C46: j | D46: 15000 | E46: Matériel
A47: mt_dame | B47: Dame sauteuse (location) | C47: j | D47: 20000 | E47: Matériel
A48: mt_plaque | B48: Compacteur à plaque vibrante / rouleau 1 t (location) | C48: j | D48: 60000 | E48: Matériel
A49: mt_cam | B49: Camion benne 10 m³ | C49: voyage | D49: 25000 | E49: Matériel
A50: mt_scie | B50: Scie à sol (location) | C50: j | D50: 30000 | E50: Matériel
A51: mt_niveau | B51: Niveau / théodolite (location) | C51: j | D51: 15000 | E51: Matériel
A52: mt_branch | B52: Branchements provisoires eau et électricité | C52: ft | D52: 100000 | E52: Matériel
A53: mt_ch | B53: Poste à souder, meuleuse, levage (charpente) | C53: kg | D53: 100 | E53: Matériel
A54: mt_echaf | B54: Échafaudage (location) | C54: m² | D54: 150 | E54: Matériel
A55: mt_portail | B55: Poste à souder, meuleuse (portail) | C55: ft | D55: 150000 | E55: Matériel
B57: Source : estimation du marché d'Abidjan, octobre 2026 - à actualiser avec les cotations des fournisseurs.

Sheet Aciers
A1: ASSEYA SILVER CONSTRUCTION - Construction métallique et bâtiment - Bouaké - Tél : 07 08 39 02 66 / 05 05 10 76 82 - Email : asseyasilver@gmail.com
A2: Nomenclature des aciers - Bâtiment industriel 30,00 x 10,00 m - 04/10/2026 - établi par Moulo Jean Claude, Technicien Génie Civil BTP - BAEL 91 mod. 99 / EC2
A4: Lot | B4: Élément | C4: Nuance | D4: Longueur (m) | E4: kg/m | F4: Poids (kg)
A5: 2 | B5: Semelles isolées 80x80 : 2 sens x n HA12 e=15 (L = A - 0,10 + 2 retours 0,20) | C5: HA12 | D5: =p_NPIL*2*(ROUNDUP((p_SIA-0.10)/p_ESI,0)+1)*(p_SIA-0.10+2*0.20) -> 224.4 | E5: =p_KG12 -> 0.888 | F5: =D5*E5 -> 199.2672
A6: 2 | B6: Fûts 40x40 sous platines : 4 HA12 en L (hauteur + retour 0,40) | C6: HA12 | D6: =p_NPIL*4*(p_HENT+0.40) -> 85 | E6: =p_KG12 -> 0.888 | F6: =D6*E6 -> 75.48
A7: 2 | B7: Fûts 40x40 : cadres HA6 e=15 (L = 1,40 m) | C7: HA6 | D7: =p_NPIL*(ROUNDUP(p_HENT/0.15,0)+1)*1.40 -> 166.6 | E7: =p_KG6 -> 0.222 | F7: =D7*E7 -> 36.9852
A8: 2 | B8: Semelle filante : 4 HA10 filants (x1,05 recouvrements) | C8: HA10 | D8: =4*p_P*1.05 -> 336 | E8: =p_KG10 -> 0.617 | F8: =D8*E8 -> 207.312
A9: 2 | B9: Semelle filante : répartiteurs HA6 e=20 | C9: HA6 | D9: =p_P/0.20*(p_SFB+0.05) -> 180 | E9: =p_KG6 -> 0.222 | F9: =D9*E9 -> 39.96
A10: 2 | B10: Chaînage bas : 4 HA10 (x1,10 recouvrements et angles) | C10: HA10 | D10: =4*p_P*1.10 -> 352 | E10: =p_KG10 -> 0.617 | F10: =D10*E10 -> 217.184
A11: 2 | B11: Chaînage bas : cadres HA6 15x20 e=20 (L = 0,60 m) | C11: HA6 | D11: =p_P/0.20*0.60 -> 240 | E11: =p_KG6 -> 0.222 | F11: =D11*E11 -> 53.28
A12: 3 | B12: Poteaux BA 15x15 (2 par pilier) : 4 HA10 (retour 0,30 en semelle + ancrage 0,40) | C12: HA10 | D12: =p_NPIL*p_NPO*4*(p_HPO+0.70)+p_NPO*4*p_FL -> 1034.8 | E12: =p_KG10 -> 0.617 | F12: =D12*E12 -> 638.4716
A13: 3 | B13: Poteaux BA 15x15 : cadres HA6 e=15 (L = 0,50 m) | C13: HA6 | D13: =p_NPIL*p_NPO*(ROUNDUP(p_HPO/0.15,0)+1)*0.50 -> 799 | E13: =p_KG6 -> 0.222 | F13: =D13*E13 -> 177.378
A14: 3 | B14: Chaînage intermédiaire : 4 HA10 (interrompu à l'entrée) | C14: HA10 | D14: =4*(p_P-p_PL)*1.10 -> 325.6 | E14: =p_KG10 -> 0.617 | F14: =D14*E14 -> 200.8952
A15: 3 | B15: Chaînage intermédiaire : cadres HA6 e=20 | C15: HA6 | D15: =(p_P-p_PL)/0.20*0.60 -> 222 | E15: =p_KG6 -> 0.222 | F15: =D15*E15 -> 49.284
A16: 3 | B16: Chaînage haut : 4 HA10 | C16: HA10 | D16: =4*p_P*1.10 -> 352 | E16: =p_KG10 -> 0.617 | F16: =D16*E16 -> 217.184
A17: 3 | B17: Chaînage haut : cadres HA6 e=20 | C17: HA6 | D17: =p_P/0.20*0.60 -> 240 | E17: =p_KG6 -> 0.222 | F17: =D17*E17 -> 53.28
A18: 3 | B18: Linteau 15x40 : 2 lits 3 HA10 + 2 HA10 haut | C18: HA10 | D18: =8*(p_PL+0.80) -> 54.4 | E18: =p_KG10 -> 0.617 | F18: =D18*E18 -> 33.5648
A19: 3 | B19: Linteau : cadres HA6 15x40 e=15 (L = 1,00 m) | C19: HA6 | D19: =ROUNDUP((p_PL+0.80)/0.15,0)*1.00 -> 46 | E19: =p_KG6 -> 0.222 | F19: =D19*E19 -> 10.212
A20: 3 | B20: Chaînages rampants 15x15 : 4 HA10 | C20: HA10 | D20: =16*p_RAMP*1.10 -> 89.742743 | E20: =p_KG10 -> 0.617 | F20: =D20*E20 -> 55.371273
A21: 3 | B21: Chaînages rampants : cadres HA6 e=20 (L = 0,50 m) | C21: HA6 | D21: =4*p_RAMP/0.20*0.50 -> 50.990195 | E21: =p_KG6 -> 0.222 | F21: =D21*E21 -> 11.319823
A22: 5 | B22: Dallage : double nappe HA10 e=20 dans les 2 sens | C22: HA10 | D22: =p_SINT*p_NNAP*2/p_EDAL*p_RDAL -> 6468.495 | E22: =p_KG10 -> 0.617 | F22: =D22*E22 -> 3991.0614
A23: 5 | B23: Dallage : chaises HA10 (L = 0,80 m) | C23: HA10 | D23: =p_SINT*p_NCHA*0.80 -> 235.218 | E23: =p_KG10 -> 0.617 | F23: =D23*E23 -> 145.12951
A25: Lot | B25: Récapitulatif | C25: Nuance | D25: Poids net (kg) | E25: Chutes | F25: Poids à commander (kg) | G25: Barres de 12 m
A26: 2 | B26: Lot 2 | C26: HA12 | D26: =SUMIFS('Aciers'!$F$5:$F$23,'Aciers'!$A$5:$A$23,A26,'Aciers'!$C$5:$C$23,C26) -> 274.7472 | E26: =p_CHUTES -> 1.05 | F26: =D26*E26 -> 288.48456 | G26: =ROUNDUP(F26/(12*p_KG12),0) -> 28
A27: 2 | B27: Lot 2 | C27: HA10 | D27: =SUMIFS('Aciers'!$F$5:$F$23,'Aciers'!$A$5:$A$23,A27,'Aciers'!$C$5:$C$23,C27) -> 424.496 | E27: =p_CHUTES -> 1.05 | F27: =D27*E27 -> 445.7208 | G27: =ROUNDUP(F27/(12*p_KG10),0) -> 61
A28: 2 | B28: Lot 2 | C28: HA6 | D28: =SUMIFS('Aciers'!$F$5:$F$23,'Aciers'!$A$5:$A$23,A28,'Aciers'!$C$5:$C$23,C28) -> 130.2252 | E28: =p_CHUTES -> 1.05 | F28: =D28*E28 -> 136.73646 | G28: =ROUNDUP(F28/(12*p_KG6),0) -> 52
A29: 3 | B29: Lot 3 | C29: HA10 | D29: =SUMIFS('Aciers'!$F$5:$F$23,'Aciers'!$A$5:$A$23,A29,'Aciers'!$C$5:$C$23,C29) -> 1145.4869 | E29: =p_CHUTES -> 1.05 | F29: =D29*E29 -> 1202.7612 | G29: =ROUNDUP(F29/(12*p_KG10),0) -> 163
A30: 3 | B30: Lot 3 | C30: HA6 | D30: =SUMIFS('Aciers'!$F$5:$F$23,'Aciers'!$A$5:$A$23,A30,'Aciers'!$C$5:$C$23,C30) -> 301.47382 | E30: =p_CHUTES -> 1.05 | F30: =D30*E30 -> 316.54751 | G30: =ROUNDUP(F30/(12*p_KG6),0) -> 119
A31: 5 | B31: Lot 5 | C31: HA10 | D31: =SUMIFS('Aciers'!$F$5:$F$23,'Aciers'!$A$5:$A$23,A31,'Aciers'!$C$5:$C$23,C31) -> 4136.1909 | E31: =p_CHUTES -> 1.05 | F31: =D31*E31 -> 4343.0005 | G31: =ROUNDUP(F31/(12*p_KG10),0) -> 587
B32: TOTAL HA12 | C32: HA12 | D32: =SUMIFS('Aciers'!$F$5:$F$23,'Aciers'!$C$5:$C$23,C32) -> 274.7472 | E32: =p_CHUTES -> 1.05 | F32: =D32*E32 -> 288.48456 | G32: =ROUNDUP(F32/(12*p_KG12),0) -> 28
B33: TOTAL HA10 | C33: HA10 | D33: =SUMIFS('Aciers'!$F$5:$F$23,'Aciers'!$C$5:$C$23,C33) -> 5706.1738 | E33: =p_CHUTES -> 1.05 | F33: =D33*E33 -> 5991.4825 | G33: =ROUNDUP(F33/(12*p_KG10),0) -> 810
B34: TOTAL HA6 | C34: HA6 | D34: =SUMIFS('Aciers'!$F$5:$F$23,'Aciers'!$C$5:$C$23,C34) -> 431.69902 | E34: =p_CHUTES -> 1.05 | F34: =D34*E34 -> 453.28397 | G34: =ROUNDUP(F34/(12*p_KG6),0) -> 171

Sheet Métré
A1: ASSEYA SILVER CONSTRUCTION - Construction métallique et bâtiment - Bouaké - Tél : 07 08 39 02 66 / 05 05 10 76 82 - Email : asseyasilver@gmail.com
A2: Avant-métré - Bâtiment industriel 30,00 x 10,00 m - 04/10/2026 - établi par Moulo Jean Claude, Technicien Génie Civil BTP - BAEL 91 mod. 99 / EC2
A4: N° | B4: Lot | C4: Désignation | D4: U | E4: Formule (noms de la feuille Paramètres) | F4: Quantité
A5: LOT 0 | C5: INSTALLATION DE CHANTIER ET TRAVAUX PRÉPARATOIRES
A6: 0.1 | B6: 0 | C6: Installation et repli de chantier (magasin, clôture provisoire, eau, électricité, panneau) | D6: ft | E6: 1 | F6: =1 -> 1
A7: 0.2 | B7: 0 | C7: Débroussaillage et décapage de la terre végétale ép. 10 cm | D7: m² | E7: (p_L+4)*(p_B+4) | F7: =(p_L+4)*(p_B+4) -> 476
A8: 0.3 | B8: 0 | C8: Implantation du bâtiment (chaises, cordeaux, axes et niveaux) | D8: ft | E8: 1 | F8: =1 -> 1
A9: LOT 1 | C9: TERRASSEMENTS
A10: 1.1 | B10: 1 | C10: Fouilles en rigole 0,60 x 1,20 m en terrain latéritique | D10: m³ | E10: p_VRIG | F10: =p_VRIG -> 57.6
A11: 1.2 | B11: 1 | C11: Fouilles en puits 1,00 x 1,00 x 1,20 m pour semelles isolées 80x80 (complément) | D11: m³ | E11: p_VPUI | F11: =p_VPUI -> 8.16
A12: 1.3 | B12: 1 | C12: Remblai des fouilles avec les terres extraites, compacté par couches de 20 cm | D12: m³ | E12: p_VRIG+p_VPUI-p_VENT | F12: =p_VRIG+p_VPUI-p_VENT -> 41.85525
A13: 1.4 | B13: 1 | C13: Évacuation des terres excédentaires des fouilles | D13: m³ | E13: p_VENT*p_FOIS | F13: =p_VENT*p_FOIS -> 29.880938
A14: 1.5 | B14: 1 | C14: Traitement anti-termites des fonds de fouilles | D14: m² | E14: p_P*p_FRL+p_NPIL*(p_FPA*p_FPA-p_FRL*p_FPA) | F14: =p_P*p_FRL+p_NPIL*(p_FPA*p_FPA-p_FRL*p_FPA) -> 54.8
A15: LOT 2 | C15: FONDATIONS
A16: 2.1 | B16: 2 | C16: Béton de propreté dosé à 150 kg/m³, ép. 5 cm | D16: m³ | E16: p_VPROP | F16: =p_VPROP -> 2.74
A17: 2.2 | B17: 2 | C17: Béton armé dosé à 350 kg/m³ pour semelles isolées 0,80 x 0,80 x 0,30 | D17: m³ | E17: p_VSI | F17: =p_VSI -> 3.264
A18: 2.3 | B18: 2 | C18: Béton armé dosé à 350 kg/m³ pour fûts 40 x 40 sous platines des IPE (de -0,85 à ±0,00) | D18: m³ | E18: p_NPIL*p_AFUT*p_AFUT*p_HENT | F18: =p_NPIL*p_AFUT*p_AFUT*p_HENT -> 2.312
A19: 2.4 | B19: 2 | C19: Fourniture et scellement des tiges d'ancrage M20 des IPE (gabarit de pose, 4 par pilier) | D19: u | E19: p_NPIL*p_NTIG | F19: =p_NPIL*p_NTIG -> 68
A20: 2.5 | B20: 2 | C20: Béton armé dosé à 350 kg/m³ pour semelle filante 0,40 x 0,15 | D20: m³ | E20: p_VSF | F20: =p_VSF -> 3.984
A21: 2.6 | B21: 2 | C21: Maçonnerie d'agglos 15 pleins en fondation h = 1,00 m, mortier dosé à 300 kg/m³ | D21: m² | E21: p_LNET*p_HFOND | F21: =p_LNET*p_HFOND -> 73.03
A22: 2.7 | B22: 2 | C22: Béton armé dosé à 350 kg/m³ pour chaînage bas 15 x 20 | D22: m³ | E22: p_LNET*p_BCH*p_HCH | F22: =p_LNET*p_BCH*p_HCH -> 2.1909
A23: 2.8 | B23: 2 | C23: Chape d'arase étanche (mortier dosé à 400 kg/m³ + hydrofuge) ép. 3 cm | D23: m² | E23: p_LNET*p_EP | F23: =p_LNET*p_EP -> 10.9545
A24: 2.9 | B24: 2 | C24: Coffrage en bois ordinaire (semelles isolées, fûts, chaînage bas) | D24: m² | E24: p_NPIL*4*(p_SIA*p_SIH+p_AFUT*p_HENT)+2*p_HCH*p_LNET | F24: =p_NPIL*4*(p_SIA*p_SIH+p_AFUT*p_HENT)+2*p_HCH*p_LNET -> 68.652
A25: 2.10 | B25: 2 | C25: Armatures HA12 FeE500 - semelles isolées 80x80 et fûts | D25: kg | E25: Nomenclature des aciers - lot 2 - HA12 (y compris chutes) | F25: ='Aciers'!$F$26 -> 288.48456
A26: 2.11 | B26: 2 | C26: Armatures HA10 FeE500 - fondations | D26: kg | E26: Nomenclature des aciers - lot 2 - HA10 (y compris chutes) | F26: ='Aciers'!$F$27 -> 445.7208
A27: 2.12 | B27: 2 | C27: Armatures HA6 FeE500 - fondations | D27: kg | E27: Nomenclature des aciers - lot 2 - HA6 (y compris chutes) | F27: ='Aciers'!$F$28 -> 136.73646
A28: LOT 3 | C28: ÉLÉVATION (MAÇONNERIE ET BÉTON ARMÉ)
A29: 3.1 | B29: 3 | C29: Maçonnerie d'agglos 15 pleins en élévation, mortier dosé à 300 kg/m³ (y compris pignons) | D29: m² | E29: p_LCHI*p_HM+p_PL*((p_H-p_HCH)-(p_PH+p_LINH))+2*p_PIGN | F29: =p_LCHI*p_HM+p_PL*((p_H-p_HCH)-(p_PH+p_LINH))+2*p_PIGN -> 373.89259
A30: 3.2 | B30: 3 | C30: Béton armé dosé à 350 kg/m³ pour poteaux 15 x 15 (2 par pilier IPE), de -0,85 à +6,00 | D30: m³ | E30: p_NPIL*p_NPO*p_APO*p_APO*p_HPO+p_NPO*p_APO*p_APO*p_FL | F30: =p_NPIL*p_NPO*p_APO*p_APO*p_HPO+p_NPO*p_APO*p_APO*p_FL -> 5.28525
A31: 3.3 | B31: 3 | C31: Béton armé dosé à 350 kg/m³ pour chaînage intermédiaire 15 x 20 à +3,00 | D31: m³ | E31: p_LCHI*p_BCH*p_HCH | F31: =p_LCHI*p_BCH*p_HCH -> 2.0109
A32: 3.4 | B32: 3 | C32: Béton armé dosé à 350 kg/m³ pour chaînage haut 15 x 20 | D32: m³ | E32: p_LNET*p_BCH*p_HCH | F32: =p_LNET*p_BCH*p_HCH -> 2.1909
A33: 3.5 | B33: 3 | C33: Béton armé dosé à 350 kg/m³ pour linteau de l'entrée 15 x 40 | D33: m³ | E33: p_PL*p_BCH*p_LINH | F33: =p_PL*p_BCH*p_LINH -> 0.36
A34: 3.6 | B34: 3 | C34: Béton armé dosé à 350 kg/m³ pour chaînages rampants 15 x 15 (pente 20 %) | D34: m³ | E34: 4*(p_RAMP-0.20)*0.15*0.15 | F34: =4*(p_RAMP-0.20)*0.15*0.15 -> 0.44091176
A35: 3.7 | B35: 3 | C35: Coffrage en bois ordinaire (poteaux, chaînages, linteau, rampants) | D35: m² | E35: 3*p_APO*p_NPO*(p_NPIL*p_HPO+p_FL)+2*p_HCH*(p_LCHI+p_LNET)+(2*p_LINH+p_BCH)*p_PL+2*0.15*4*(p_RAMP-0.20) | F35: =3*p_APO*p_NPO*(p_NPIL*p_HPO+p_FL)+2*p_HCH*(p_LCHI+p_LNET)+(2*p_LINH+p_BCH)*p_PL+2*0.15*4*(p_RAMP-0.20) -> 173.30782
A36: 3.8 | B36: 3 | C36: Armatures HA10 FeE500 - élévation | D36: kg | E36: Nomenclature des aciers - lot 3 - HA10 (y compris chutes) | F36: ='Aciers'!$F$29 -> 1202.7612
A37: 3.9 | B37: 3 | C37: Armatures HA6 FeE500 - élévation | D37: kg | E37: Nomenclature des aciers - lot 3 - HA6 (y compris chutes) | F37: ='Aciers'!$F$30 -> 316.54751
A38: LOT 4 | C38: STRUCTURE MÉTALLIQUE : PILIERS IPE 220 ET CONTREVENTEMENTS
A39: 4.1 | B39: 4 | C39: Piliers en IPE 220 (S235) de ±0,00 à +6,00, fournis, fabriqués, peints et posés | D39: kg | E39: p_LIPE*p_KGIPE | F39: =p_LIPE*p_KGIPE -> 2698.6
A40: 4.2 | B40: 4 | C40: Platines de pied et de tête 15 mm + raidisseurs, soudées | D40: kg | E40: p_NPIL*p_KGPLA | F40: =p_NPIL*p_KGPLA -> 255
A41: 4.3 | B41: 4 | C41: Calage et scellement des platines au mortier sans retrait | D41: u | E41: p_NPIL | F41: =p_NPIL -> 17
...

Sheet Sous-détails
A1: ASSEYA SILVER CONSTRUCTION - Construction métallique et bâtiment - Bouaké - Tél : 07 08 39 02 66 / 05 05 10 76 82 - Email : asseyasilver@gmail.com
A2: Sous-détails de prix (déboursé sec unitaire) - Bâtiment industriel 30,00 x 10,00 m - 04/10/2026 - établi par Moulo Jean Claude, Technicien Génie Civil BTP - BAEL 91 mod. 99 / EC2
A4: N° | B4: Nature | C4: Composante | D4: Code prix | E4: U | F4: Qté / unité | G4: P.U. (FCFA) | H4: Montant / unité | I4: Qté ouvrage | J4: Qté totale | K4: Option
B5: Article 0.1 - Installation et repli de chantier (magasin, clôture provisoire, eau, électricité, panneau) (unité : ft)
A6: Art. 0.1 | B6: Matériaux | C6: Magasin, clôture provisoire, panneau de chantier | D6: ff_install | E6: ft | F6: =1 -> 1 | G6: =px_ff_install -> 300000 | H6: =F6*G6 -> 300000 | I6: =q_0_1 -> 1 | J6: =F6*I6 -> 1 | K6: NON
A7: Art. 0.1 | B7: Main-d'œuvre | C7: Manœuvres (montage / repli) | D7: mo_man | E7: h.j | F7: =20 -> 20 | G7: =px_mo_man -> 5000 | H7: =F7*G7 -> 100000 | I7: =q_0_1 -> 1 | J7: =F7*I7 -> 20 | K7: NON
A8: Art. 0.1 | B8: Matériel | C8: Branchements provisoires eau et électricité | D8: mt_branch | E8: ft | F8: =1 -> 1 | G8: =px_mt_branch -> 100000 | H8: =F8*G8 -> 100000 | I8: =q_0_1 -> 1 | J8: =F8*I8 -> 1 | K8: NON
A9: Art. 0.1 | B9: Matériel | C9: Petit outillage (% de la main-d'œuvre) | E9: % | F9: =p_PO -> 0.03 | G9: =SUMIFS(H6:H8,B6:B8,"Main-d'œuvre") -> 100000 | H9: =F9*G9 -> 3000
C10: DÉBOURSÉ SEC UNITAIRE / ft | H10: =SUM(H6:H9) -> 503000
B12: Article 0.2 - Débroussaillage et décapage de la terre végétale ép. 10 cm (unité : m²)
A13: Art. 0.2 | B13: Main-d'œuvre | C13: Manœuvre (60 m²/j) | D13: mo_man | E13: h.j | F13: =1/60 -> 0.016666667 | G13: =px_mo_man -> 5000 | H13: =F13*G13 -> 83.333333 | I13: =q_0_2 -> 476 | J13: =F13*I13 -> 7.9333333 | K13: NON
A14: Art. 0.2 | B14: Matériel | C14: Petit outillage (% de la main-d'œuvre) | E14: % | F14: =p_PO -> 0.03 | G14: =SUMIFS(H13:H13,B13:B13,"Main-d'œuvre") -> 83.333333 | H14: =F14*G14 -> 2.5
C15: DÉBOURSÉ SEC UNITAIRE / m² | H15: =SUM(H13:H14) -> 85.833333
B17: Article 0.3 - Implantation du bâtiment (chaises, cordeaux, axes et niveaux) (unité : ft)
A18: Art. 0.3 | B18: Matériaux | C18: Bois de chaises, cordeau, peinture | D18: ff_implant | E18: ft | F18: =1 -> 1 | G18: =px_ff_implant -> 40000 | H18: =F18*G18 -> 40000 | I18: =q_0_3 -> 1 | J18: =F18*I18 -> 1 | K18: NON
A19: Art. 0.3 | B19: Main-d'œuvre | C19: Technicien | D19: mo_tech | E19: h.j | F19: =2 -> 2 | G19: =px_mo_tech -> 15000 | H19: =F19*G19 -> 30000 | I19: =q_0_3 -> 1 | J19: =F19*I19 -> 2 | K19: NON
A20: Art. 0.3 | B20: Main-d'œuvre | C20: Manœuvre | D20: mo_man | E20: h.j | F20: =4 -> 4 | G20: =px_mo_man -> 5000 | H20: =F20*G20 -> 20000 | I20: =q_0_3 -> 1 | J20: =F20*I20 -> 4 | K20: NON
A21: Art. 0.3 | B21: Matériel | C21: Niveau / théodolite (location) | D21: mt_niveau | E21: j | F21: =2 -> 2 | G21: =px_mt_niveau -> 15000 | H21: =F21*G21 -> 30000 | I21: =q_0_3 -> 1 | J21: =F21*I21 -> 2 | K21: NON
A22: Art. 0.3 | B22: Matériel | C22: Petit outillage (% de la main-d'œuvre) | E22: % | F22: =p_PO -> 0.03 | G22: =SUMIFS(H18:H21,B18:B21,"Main-d'œuvre") -> 50000 | H22: =F22*G22 -> 1500
C23: DÉBOURSÉ SEC UNITAIRE / ft | H23: =SUM(H18:H22) -> 121500
B25: Article 1.1 - Fouilles en rigole 0,60 x 1,20 m en terrain latéritique (unité : m³)
A26: Art. 1.1 | B26: Main-d'œuvre | C26: Manœuvre (1,5 m³/j en latérite compacte) | D26: mo_man | E26: h.j | F26: =1/1.5 -> 0.66666667 | G26: =px_mo_man -> 5000 | H26: =F26*G26 -> 3333.3333 | I26: =q_1_1 -> 57.6 | J26: =F26*I26 -> 38.4 | K26: NON
A27: Art. 1.1 | B27: Matériel | C27: Petit outillage (% de la main-d'œuvre) | E27: % | F27: =p_PO -> 0.03 | G27: =SUMIFS(H26:H26,B26:B26,"Main-d'œuvre") -> 3333.3333 | H27: =F27*G27 -> 100
C28: DÉBOURSÉ SEC UNITAIRE / m³ | H28: =SUM(H26:H27) -> 3433.3333
B30: Article 1.2 - Fouilles en puits 1,00 x 1,00 x 1,20 m pour semelles isolées 80x80 (complément) (unité : m³)
A31: Art. 1.2 | B31: Main-d'œuvre | C31: Manœuvre (1,5 m³/j) | D31: mo_man | E31: h.j | F31: =1/1.5 -> 0.66666667 | G31: =px_mo_man -> 5000 | H31: =F31*G31 -> 3333.3333 | I31: =q_1_2 -> 8.16 | J31: =F31*I31 -> 5.44 | K31: NON
A32: Art. 1.2 | B32: Matériel | C32: Petit outillage (% de la main-d'œuvre) | E32: % | F32: =p_PO -> 0.03 | G32: =SUMIFS(H31:H31,B31:B31,"Main-d'œuvre") -> 3333.3333 | H32: =F32*G32 -> 100
C33: DÉBOURSÉ SEC UNITAIRE / m³ | H33: =SUM(H31:H32) -> 3433.3333
B35: Article 1.3 - Remblai des fouilles avec les terres extraites, compacté par couches de 20 cm (unité : m³)
A36: Art. 1.3 | B36: Main-d'œuvre | C36: Manœuvre (4 m³/j) | D36: mo_man | E36: h.j | F36: =1/4 -> 0.25 | G36: =px_mo_man -> 5000 | H36: =F36*G36 -> 1250 | I36: =q_1_3 -> 41.85525 | J36: =F36*I36 -> 10.463812 | K36: NON
A37: Art. 1.3 | B37: Matériel | C37: Dame sauteuse (20 m³/j) | D37: mt_dame | E37: j | F37: =1/20 -> 0.05 | G37: =px_mt_dame -> 20000 | H37: =F37*G37 -> 1000 | I37: =q_1_3 -> 41.85525 | J37: =F37*I37 -> 2.0927625 | K37: NON
A38: Art. 1.3 | B38: Matériel | C38: Petit outillage (% de la main-d'œuvre) | E38: % | F38: =p_PO -> 0.03 | G38: =SUMIFS(H36:H37,B36:B37,"Main-d'œuvre") -> 1250 | H38: =F38*G38 -> 37.5
C39: DÉBOURSÉ SEC UNITAIRE / m³ | H39: =SUM(H36:H38) -> 2287.5
B41: Article 1.4 - Évacuation des terres excédentaires des fouilles (unité : m³)
A42: Art. 1.4 | B42: Main-d'œuvre | C42: Manœuvre - chargement (5 m³/j) | D42: mo_man | E42: h.j | F42: =1/5 -> 0.2 | G42: =px_mo_man -> 5000 | H42: =F42*G42 -> 1000 | I42: =q_1_4 -> 29.880938 | J42: =F42*I42 -> 5.9761875 | K42: NON
A43: Art. 1.4 | B43: Matériel | C43: Camion benne 10 m³ (voyage) | D43: mt_cam | E43: voyage | F43: =1/10 -> 0.1 | G43: =px_mt_cam -> 25000 | H43: =F43*G43 -> 2500 | I43: =q_1_4 -> 29.880938 | J43: =F43*I43 -> 2.9880938 | K43: NON
A44: Art. 1.4 | B44: Matériel | C44: Petit outillage (% de la main-d'œuvre) | E44: % | F44: =p_PO -> 0.03 | G44: =SUMIFS(H42:H43,B42:B43,"Main-d'œuvre") -> 1000 | H44: =F44*G44 -> 30
C45: DÉBOURSÉ SEC UNITAIRE / m³ | H45: =SUM(H42:H44) -> 3530
B47: Article 1.5 - Traitement anti-termites des fonds de fouilles (unité : m²)
A48: Art. 1.5 | B48: Matériaux | C48: Produit anti-termites (dilué) | D48: termite | E48: m² | F48: =1 -> 1 | G48: =px_termite -> 1200 | H48: =F48*G48 -> 1200 | I48: =q_1_5 -> 54.8 | J48: =F48*I48 -> 54.8 | K48: NON
...

Sheet Déboursé sec
A1: ASSEYA SILVER CONSTRUCTION - Construction métallique et bâtiment - Bouaké - Tél : 07 08 39 02 66 / 05 05 10 76 82 - Email : asseyasilver@gmail.com
A2: Déboursé sec - Bâtiment industriel 30,00 x 10,00 m - 04/10/2026 - établi par Moulo Jean Claude, Technicien Génie Civil BTP - BAEL 91 mod. 99 / EC2
A4: N° | B4: Désignation | C4: U | D4: Quantité | E4: Matériaux / u | F4: Main-d'œuvre / u | G4: Matériel / u | H4: DS unitaire | I4: Matériaux total | J4: Main-d'œuvre total | K4: Matériel total | L4: DS total (FCFA) | M4: Option
A5: LOT 0 | B5: INSTALLATION DE CHANTIER ET TRAVAUX PRÉPARATOIRES
A6: 0.1 | B6: Installation et repli de chantier (magasin, clôture provisoire, eau, électricité, panneau) | C6: ft | D6: =q_0_1 -> 1 | E6: =SUMIFS('Sous-détails'!$H$5:$H$407,'Sous-détails'!$A$5:$A$407,"Art. "&$A6,'Sous-détails'!$B$5:$B$407,"Matériaux") -> 300000 | F6: =SUMIFS('Sous-détails'!$H$5:$H$407,'Sous-détails'!$A$5:$A$407,"Art. "&$A6,'Sous-détails'!$B$5:$B$407,"Main-d'œuvre") -> 100000 | G6: =SUMIFS('Sous-détails'!$H$5:$H$407,'Sous-détails'!$A$5:$A$407,"Art. "&$A6,'Sous-détails'!$B$5:$B$407,"Matériel") -> 103000 | H6: =E6+F6+G6 -> 503000 | I6: =$D6*E6 -> 300000 | J6: =$D6*F6 -> 100000 | K6: =$D6*G6 -> 103000 | L6: =$D6*H6 -> 503000 | M6: NON
A7: 0.2 | B7: Débroussaillage et décapage de la terre végétale ép. 10 cm | C7: m² | D7: =q_0_2 -> 476 | E7: =SUMIFS('Sous-détails'!$H$5:$H$407,'Sous-détails'!$A$5:$A$407,"Art. "&$A7,'Sous-détails'!$B$5:$B$407,"Matériaux") -> 0 | F7: =SUMIFS('Sous-détails'!$H$5:$H$407,'Sous-détails'!$A$5:$A$407,"Art. "&$A7,'Sous-détails'!$B$5:$B$407,"Main-d'œuvre") -> 83.333333 | G7: =SUMIFS('Sous-détails'!$H$5:$H$407,'Sous-détails'!$A$5:$A$407,"Art. "&$A7,'Sous-détails'!$B$5:$B$407,"Matériel") -> 2.5 | H7: =E7+F7+G7 -> 85.833333 | I7: =$D7*E7 -> 0 | J7: =$D7*F7 -> 39666.667 | K7: =$D7*G7 -> 1190 | L7: =$D7*H7 -> 40856.667 | M7: NON
A8: 0.3 | B8: Implantation du bâtiment (chaises, cordeaux, axes et niveaux) | C8: ft | D8: =q_0_3 -> 1 | E8: =SUMIFS('Sous-détails'!$H$5:$H$407,'Sous-détails'!$A$5:$A$407,"Art. "&$A8,'Sous-détails'!$B$5:$B$407,"Matériaux") -> 40000 | F8: =SUMIFS('Sous-détails'!$H$5:$H$407,'Sous-détails'!$A$5:$A$407,"Art. "&$A8,'Sous-détails'!$B$5:$B$407,"Main-d'œuvre") -> 50000 | G8: =SUMIFS('Sous-détails'!$H$5:$H$407,'Sous-détails'!$A$5:$A$407,"Art. "&$A8,'Sous-détails'!$B$5:$B$407,"Matériel") -> 31500 | H8: =E8+F8+G8 -> 121500 | I8: =$D8*E8 -> 40000 | J8: =$D8*F8 -> 50000 | K8: =$D8*G8 -> 31500 | L8: =$D8*H8 -> 121500 | M8: NON
B9: Sous-total déboursé sec lot 0 | I9: =SUM(I6:I8) -> 340000 | J9: =SUM(J6:J8) -> 189666.67 | K9: =SUM(K6:K8) -> 135690 | L9: =SUM(L6:L8) -> 665356.67
A11: LOT 1 | B11: TERRASSEMENTS
A12: 1.1 | B12: Fouilles en rigole 0,60 x 1,20 m en terrain latéritique | C12: m³ | D12: =q_1_1 -> 57.6 | E12: =SUMIFS('Sous-détails'!$H$5:$H$407,'Sous-détails'!$A$5:$A$407,"Art. "&$A12,'Sous-détails'!$B$5:$B$407,"Matériaux") -> 0 | F12: =SUMIFS('Sous-détails'!$H$5:$H$407,'Sous-détails'!$A$5:$A$407,"Art. "&$A12,'Sous-détails'!$B$5:$B$407,"Main-d'œuvre") -> 3333.3333 | G12: =SUMIFS('Sous-détails'!$H$5:$H$407,'Sous-détails'!$A$5:$A$407,"Art. "&$A12,'Sous-détails'!$B$5:$B$407,"Matériel") -> 100 | H12: =E12+F12+G12 -> 3433.3333 | I12: =$D12*E12 -> 0 | J12: =$D12*F12 -> 192000 | K12: =$D12*G12 -> 5760 | L12: =$D12*H12 -> 197760 | M12: NON
A13: 1.2 | B13: Fouilles en puits 1,00 x 1,00 x 1,20 m pour semelles isolées 80x80 (complément) | C13: m³ | D13: =q_1_2 -> 8.16 | E13: =SUMIFS('Sous-détails'!$H$5:$H$407,'Sous-détails'!$A$5:$A$407,"Art. "&$A13,'Sous-détails'!$B$5:$B$407,"Matériaux") -> 0 | F13: =SUMIFS('Sous-détails'!$H$5:$H$407,'Sous-détails'!$A$5:$A$407,"Art. "&$A13,'Sous-détails'!$B$5:$B$407,"Main-d'œuvre") -> 3333.3333 | G13: =SUMIFS('Sous-détails'!$H$5:$H$407,'Sous-détails'!$A$5:$A$407,"Art. "&$A13,'Sous-détails'!$B$5:$B$407,"Matériel") -> 100 | H13: =E13+F13+G13 -> 3433.3333 | I13: =$D13*E13 -> 0 | J13: =$D13*F13 -> 27200 | K13: =$D13*G13 -> 816 | L13: =$D13*H13 -> 28016 | M13: NON
A14: 1.3 | B14: Remblai des fouilles avec les terres extraites, compacté par couches de 20 cm | C14: m³ | D14: =q_1_3 -> 41.85525 | E14: =SUMIFS('Sous-détails'!$H$5:$H$407,'Sous-détails'!$A$5:$A$407,"Art. "&$A14,'Sous-détails'!$B$5:$B$407,"Matériaux") -> 0 | F14: =SUMIFS('Sous-détails'!$H$5:$H$407,'Sous-détails'!$A$5:$A$407,"Art. "&$A14,'Sous-détails'!$B$5:$B$407,"Main-d'œuvre") -> 1250 | G14: =SUMIFS('Sous-détails'!$H$5:$H$407,'Sous-détails'!$A$5:$A$407,"Art. "&$A14,'Sous-détails'!$B$5:$B$407,"Matériel") -> 1037.5 | H14: =E14+F14+G14 -> 2287.5 | I14: =$D14*E14 -> 0 | J14: =$D14*F14 -> 52319.062 | K14: =$D14*G14 -> 43424.822 | L14: =$D14*H14 -> 95743.884 | M14: NON
A15: 1.4 | B15: Évacuation des terres excédentaires des fouilles | C15: m³ | D15: =q_1_4 -> 29.880938 | E15: =SUMIFS('Sous-détails'!$H$5:$H$407,'Sous-détails'!$A$5:$A$407,"Art. "&$A15,'Sous-détails'!$B$5:$B$407,"Matériaux") -> 0 | F15: =SUMIFS('Sous-détails'!$H$5:$H$407,'Sous-détails'!$A$5:$A$407,"Art. "&$A15,'Sous-détails'!$B$5:$B$407,"Main-d'œuvre") -> 1000 | G15: =SUMIFS('Sous-détails'!$H$5:$H$407,'Sous-détails'!$A$5:$A$407,"Art. "&$A15,'Sous-détails'!$B$5:$B$407,"Matériel") -> 2530 | H15: =E15+F15+G15 -> 3530 | I15: =$D15*E15 -> 0 | J15: =$D15*F15 -> 29880.938 | K15: =$D15*G15 -> 75598.772 | L15: =$D15*H15 -> 105479.71 | M15: NON
A16: 1.5 | B16: Traitement anti-termites des fonds de fouilles | C16: m² | D16: =q_1_5 -> 54.8 | E16: =SUMIFS('Sous-détails'!$H$5:$H$407,'Sous-détails'!$A$5:$A$407,"Art. "&$A16,'Sous-détails'!$B$5:$B$407,"Matériaux") -> 1200 | F16: =SUMIFS('Sous-détails'!$H$5:$H$407,'Sous-détails'!$A$5:$A$407,"Art. "&$A16,'Sous-détails'!$B$5:$B$407,"Main-d'œuvre") -> 200 | G16: =SUMIFS('Sous-détails'!$H$5:$H$407,'Sous-détails'!$A$5:$A$407,"Art. "&$A16,'Sous-détails'!$B$5:$B$407,"Matériel") -> 6 | H16: =E16+F16+G16 -> 1406 | I16: =$D16*E16 -> 65760 | J16: =$D16*F16 -> 10960 | K16: =$D16*G16 -> 328.8 | L16: =$D16*H16 -> 77048.8 | M16: NON
B17: Sous-total déboursé sec lot 1 | I17: =SUM(I12:I16) -> 65760 | J17: =SUM(J12:J16) -> 312360 | K17: =SUM(K12:K16) -> 125928.39 | L17: =SUM(L12:L16) -> 504048.39
A19: LOT 2 | B19: FONDATIONS
A20: 2.1 | B20: Béton de propreté dosé à 150 kg/m³, ép. 5 cm | C20: m³ | D20: =q_2_1 -> 2.74 | E20: =SUMIFS('Sous-détails'!$H$5:$H$407,'Sous-détails'!$A$5:$A$407,"Art. "&$A20,'Sous-détails'!$B$5:$B$407,"Matériaux") -> 44250 | F20: =SUMIFS('Sous-détails'!$H$5:$H$407,'Sous-détails'!$A$5:$A$407,"Art. "&$A20,'Sous-détails'!$B$5:$B$407,"Main-d'œuvre") -> 5000 | G20: =SUMIFS('Sous-détails'!$H$5:$H$407,'Sous-détails'!$A$5:$A$407,"Art. "&$A20,'Sous-détails'!$B$5:$B$407,"Matériel") -> 5150 | H20: =E20+F20+G20 -> 54400 | I20: =$D20*E20 -> 121245 | J20: =$D20*F20 -> 13700 | K20: =$D20*G20 -> 14111 | L20: =$D20*H20 -> 149056 | M20: NON
A21: 2.2 | B21: Béton armé dosé à 350 kg/m³ pour semelles isolées 0,80 x 0,80 x 0,30 | C21: m³ | D21: =q_2_2 -> 3.264 | E21: =SUMIFS('Sous-détails'!$H$5:$H$407,'Sous-détails'!$A$5:$A$407,"Art. "&$A21,'Sous-détails'!$B$5:$B$407,"Matériaux") -> 67450 | F21: =SUMIFS('Sous-détails'!$H$5:$H$407,'Sous-détails'!$A$5:$A$407,"Art. "&$A21,'Sous-détails'!$B$5:$B$407,"Main-d'œuvre") -> 8000 | G21: =SUMIFS('Sous-détails'!$H$5:$H$407,'Sous-détails'!$A$5:$A$407,"Art. "&$A21,'Sous-détails'!$B$5:$B$407,"Matériel") -> 8240 | H21: =E21+F21+G21 -> 83690 | I21: =$D21*E21 -> 220156.8 | J21: =$D21*F21 -> 26112 | K21: =$D21*G21 -> 26895.36 | L21: =$D21*H21 -> 273164.16 | M21: NON
A22: 2.3 | B22: Béton armé dosé à 350 kg/m³ pour fûts 40 x 40 sous platines des IPE (de -0,85 à ±0,00) | C22: m³ | D22: =q_2_3 -> 2.312 | E22: =SUMIFS('Sous-détails'!$H$5:$H$407,'Sous-détails'!$A$5:$A$407,"Art. "&$A22,'Sous-détails'!$B$5:$B$407,"Matériaux") -> 67450 | F22: =SUMIFS('Sous-détails'!$H$5:$H$407,'Sous-détails'!$A$5:$A$407,"Art. "&$A22,'Sous-détails'!$B$5:$B$407,"Main-d'œuvre") -> 10000 | G22: =SUMIFS('Sous-détails'!$H$5:$H$407,'Sous-détails'!$A$5:$A$407,"Art. "&$A22,'Sous-détails'!$B$5:$B$407,"Matériel") -> 10300 | H22: =E22+F22+G22 -> 87750 | I22: =$D22*E22 -> 155944.4 | J22: =$D22*F22 -> 23120 | K22: =$D22*G22 -> 23813.6 | L22: =$D22*H22 -> 202878 | M22: NON
A23: 2.4 | B23: Fourniture et scellement des tiges d'ancrage M20 des IPE (gabarit de pose, 4 par pilier) | C23: u | D23: =q_2_4 -> 68 | E23: =SUMIFS('Sous-détails'!$H$5:$H$407,'Sous-détails'!$A$5:$A$407,"Art. "&$A23,'Sous-détails'!$B$5:$B$407,"Matériaux") -> 6180 | F23: =SUMIFS('Sous-détails'!$H$5:$H$407,'Sous-détails'!$A$5:$A$407,"Art. "&$A23,'Sous-détails'!$B$5:$B$407,"Main-d'œuvre") -> 1250 | G23: =SUMIFS('Sous-détails'!$H$5:$H$407,'Sous-détails'!$A$5:$A$407,"Art. "&$A23,'Sous-détails'!$B$5:$B$407,"Matériel") -> 37.5 | H23: =E23+F23+G23 -> 7467.5 | I23: =$D23*E23 -> 420240 | J23: =$D23*F23 -> 85000 | K23: =$D23*G23 -> 2550 | L23: =$D23*H23 -> 507790 | M23: NON
A24: 2.5 | B24: Béton armé dosé à 350 kg/m³ pour semelle filante 0,40 x 0,15 | C24: m³ | D24: =q_2_5 -> 3.984 | E24: =SUMIFS('Sous-détails'!$H$5:$H$407,'Sous-détails'!$A$5:$A$407,"Art. "&$A24,'Sous-détails'!$B$5:$B$407,"Matériaux") -> 67450 | F24: =SUMIFS('Sous-détails'!$H$5:$H$407,'Sous-détails'!$A$5:$A$407,"Art. "&$A24,'Sous-détails'!$B$5:$B$407,"Main-d'œuvre") -> 6666.6667 | G24: =SUMIFS('Sous-détails'!$H$5:$H$407,'Sous-détails'!$A$5:$A$407,"Art. "&$A24,'Sous-détails'!$B$5:$B$407,"Matériel") -> 6866.6667 | H24: =E24+F24+G24 -> 80983.333 | I24: =$D24*E24 -> 268720.8 | J24: =$D24*F24 -> 26560 | K24: =$D24*G24 -> 27356.8 | L24: =$D24*H24 -> 322637.6 | M24: NON
A25: 2.6 | B25: Maçonnerie d'agglos 15 pleins en fondation h = 1,00 m, mortier dosé à 300 kg/m³ | C25: m² | D25: =q_2_6 -> 73.03 | E25: =SUMIFS('Sous-détails'!$H$5:$H$407,'Sous-détails'!$A$5:$A$407,"Art. "&$A25,'Sous-détails'!$B$5:$B$407,"Matériaux") -> 7802.5 | F25: =SUMIFS('Sous-détails'!$H$5:$H$407,'Sous-détails'!$A$5:$A$407,"Art. "&$A25,'Sous-détails'!$B$5:$B$407,"Main-d'œuvre") -> 1500 | G25: =SUMIFS('Sous-détails'!$H$5:$H$407,'Sous-détails'!$A$5:$A$407,"Art. "&$A25,'Sous-détails'!$B$5:$B$407,"Matériel") -> 45 | H25: =E25+F25+G25 -> 9347.5 | I25: =$D25*E25 -> 569816.57 | J25: =$D25*F25 -> 109545 | K25: =$D25*G25 -> 3286.35 | L25: =$D25*H25 -> 682647.93 | M25: NON
A26: 2.7 | B26: Béton armé dosé à 350 kg/m³ pour chaînage bas 15 x 20 | C26: m³ | D26: =q_2_7 -> 2.1909 | E26: =SUMIFS('Sous-détails'!$H$5:$H$407,'Sous-détails'!$A$5:$A$407,"Art. "&$A26,'Sous-détails'!$B$5:$B$407,"Matériaux") -> 67450 | F26: =SUMIFS('Sous-détails'!$H$5:$H$407,'Sous-détails'!$A$5:$A$407,"Art. "&$A26,'Sous-détails'!$B$5:$B$407,"Main-d'œuvre") -> 6666.6667 | G26: =SUMIFS('Sous-détails'!$H$5:$H$407,'Sous-détails'!$A$5:$A$407,"Art. "&$A26,'Sous-détails'!$B$5:$B$407,"Matériel") -> 6866.6667 | H26: =E26+F26+G26 -> 80983.333 | I26: =$D26*E26 -> 147776.21 | J26: =$D26*F26 -> 14606 | K26: =$D26*G26 -> 15044.18 | L26: =$D26*H26 -> 177426.39 | M26: NON
A27: 2.8 | B27: Chape d'arase étanche (mortier dosé à 400 kg/m³ + hydrofuge) ép. 3 cm | C27: m² | D27: =q_2_8 -> 10.9545 | E27: =SUMIFS('Sous-détails'!$H$5:$H$407,'Sous-détails'!$A$5:$A$407,"Art. "&$A27,'Sous-détails'!$B$5:$B$407,"Matériaux") -> 2824 | F27: =SUMIFS('Sous-détails'!$H$5:$H$407,'Sous-détails'!$A$5:$A$407,"Art. "&$A27,'Sous-détails'!$B$5:$B$407,"Main-d'œuvre") -> 1000 | G27: =SUMIFS('Sous-détails'!$H$5:$H$407,'Sous-détails'!$A$5:$A$407,"Art. "&$A27,'Sous-détails'!$B$5:$B$407,"Matériel") -> 30 | H27: =E27+F27+G27 -> 3854 | I27: =$D27*E27 -> 30935.508 | J27: =$D27*F27 -> 10954.5 | K27: =$D27*G27 -> 328.635 | L27: =$D27*H27 -> 42218.643 | M27: NON
A28: 2.9 | B28: Coffrage en bois ordinaire (semelles isolées, fûts, chaînage bas) | C28: m² | D28: =q_2_9 -> 68.652 | E28: =SUMIFS('Sous-détails'!$H$5:$H$407,'Sous-détails'!$A$5:$A$407,"Art. "&$A28,'Sous-détails'!$B$5:$B$407,"Matériaux") -> 2125 | F28: =SUMIFS('Sous-détails'!$H$5:$H$407,'Sous-détails'!$A$5:$A$407,"Art. "&$A28,'Sous-détails'!$B$5:$B$407,"Main-d'œuvre") -> 1875 | G28: =SUMIFS('Sous-détails'!$H$5:$H$407,'Sous-détails'!$A$5:$A$407,"Art. "&$A28,'Sous-détails'!$B$5:$B$407,"Matériel") -> 56.25 | H28: =E28+F28+G28 -> 4056.25 | I28: =$D28*E28 -> 145885.5 | J28: =$D28*F28 -> 128722.5 | K28: =$D28*G28 -> 3861.675 | L28: =$D28*H28 -> 278469.67 | M28: NON
A29: 2.10 | B29: Armatures HA12 FeE500 - semelles isolées 80x80 et fûts | C29: kg | D29: =q_2_10 -> 288.48456 | E29: =SUMIFS('Sous-détails'!$H$5:$H$407,'Sous-détails'!$A$5:$A$407,"Art. "&$A29,'Sous-détails'!$B$5:$B$407,"Matériaux") -> 822.5 | F29: =SUMIFS('Sous-détails'!$H$5:$H$407,'Sous-détails'!$A$5:$A$407,"Art. "&$A29,'Sous-détails'!$B$5:$B$407,"Main-d'œuvre") -> 100 | G29: =SUMIFS('Sous-détails'!$H$5:$H$407,'Sous-détails'!$A$5:$A$407,"Art. "&$A29,'Sous-détails'!$B$5:$B$407,"Matériel") -> 3 | H29: =E29+F29+G29 -> 925.5 | I29: =$D29*E29 -> 237278.55 | J29: =$D29*F29 -> 28848.456 | K29: =$D29*G29 -> 865.45368 | L29: =$D29*H29 -> 266992.46 | M29: NON
A30: 2.11 | B30: Armatures HA10 FeE500 - fondations | C30: kg | D30: =q_2_11 -> 445.7208 | E30: =SUMIFS('Sous-détails'!$H$5:$H$407,'Sous-détails'!$A$5:$A$407,"Art. "&$A30,'Sous-détails'!$B$5:$B$407,"Matériaux") -> 832.5 | F30: =SUMIFS('Sous-détails'!$H$5:$H$407,'Sous-détails'!$A$5:$A$407,"Art. "&$A30,'Sous-détails'!$B$5:$B$407,"Main-d'œuvre") -> 100 | G30: =SUMIFS('Sous-détails'!$H$5:$H$407,'Sous-détails'!$A$5:$A$407,"Art. "&$A30,'Sous-détails'!$B$5:$B$407,"Matériel") -> 3 | H30: =E30+F30+G30 -> 935.5 | I30: =$D30*E30 -> 371062.57 | J30: =$D30*F30 -> 44572.08 | K30: =$D30*G30 -> 1337.1624 | L30: =$D30*H30 -> 416971.81 | M30: NON
A31: 2.12 | B31: Armatures HA6 FeE500 - fondations | C31: kg | D31: =q_2_12 -> 136.73646 | E31: =SUMIFS('Sous-détails'!$H$5:$H$407,'Sous-détails'!$A$5:$A$407,"Art. "&$A31,'Sous-détails'!$B$5:$B$407,"Matériaux") -> 887.5 | F31: =SUMIFS('Sous-détails'!$H$5:$H$407,'Sous-détails'!$A$5:$A$407,"Art. "&$A31,'Sous-détails'!$B$5:$B$407,"Main-d'œuvre") -> 100 | G31: =SUMIFS('Sous-détails'!$H$5:$H$407,'Sous-détails'!$A$5:$A$407,"Art. "&$A31,'Sous-détails'!$B$5:$B$407,"Matériel") -> 3 | H31: =E31+F31+G31 -> 990.5 | I31: =$D31*E31 -> 121353.61 | J31: =$D31*F31 -> 13673.646 | K31: =$D31*G31 -> 410.20938 | L31: =$D31*H31 -> 135437.46 | M31: NON
B32: Sous-total déboursé sec lot 2 | I32: =SUM(I20:I31) -> 2810415.5 | J32: =SUM(J20:J31) -> 525414.18 | K32: =SUM(K20:K31) -> 119860.43 | L32: =SUM(L20:L31) -> 3455690.1
A34: LOT 3 | B34: ÉLÉVATION (MAÇONNERIE ET BÉTON ARMÉ)
A35: 3.1 | B35: Maçonnerie d'agglos 15 pleins en élévation, mortier dosé à 300 kg/m³ (y compris pignons) | C35: m² | D35: =q_3_1 -> 373.89259 | E35: =SUMIFS('Sous-détails'!$H$5:$H$407,'Sous-détails'!$A$5:$A$407,"Art. "&$A35,'Sous-détails'!$B$5:$B$407,"Matériaux") -> 7802.5 | F35: =SUMIFS('Sous-détails'!$H$5:$H$407,'Sous-détails'!$A$5:$A$407,"Art. "&$A35,'Sous-détails'!$B$5:$B$407,"Main-d'œuvre") -> 1500 | G35: =SUMIFS('Sous-détails'!$H$5:$H$407,'Sous-détails'!$A$5:$A$407,"Art. "&$A35,'Sous-détails'!$B$5:$B$407,"Matériel") -> 45 | H35: =E35+F35+G35 -> 9347.5 | I35: =$D35*E35 -> 2917296.9 | J35: =$D35*F35 -> 560838.88 | K35: =$D35*G35 -> 16825.166 | L35: =$D35*H35 -> 3494961 | M35: NON
A36: 3.2 | B36: Béton armé dosé à 350 kg/m³ pour poteaux 15 x 15 (2 par pilier IPE), de -0,85 à +6,00 | C36: m³ | D36: =q_3_2 -> 5.28525 | E36: =SUMIFS('Sous-détails'!$H$5:$H$407,'Sous-détails'!$A$5:$A$407,"Art. "&$A36,'Sous-détails'!$B$5:$B$407,"Matériaux") -> 67450 | F36: =SUMIFS('Sous-détails'!$H$5:$H$407,'Sous-détails'!$A$5:$A$407,"Art. "&$A36,'Sous-détails'!$B$5:$B$407,"Main-d'œuvre") -> 10000 | G36: =SUMIFS('Sous-détails'!$H$5:$H$407,'Sous-détails'!$A$5:$A$407,"Art. "&$A36,'Sous-détails'!$B$5:$B$407,"Matériel") -> 10300 | H36: =E36+F36+G36 -> 87750 | I36: =$D36*E36 -> 356490.11 | J36: =$D36*F36 -> 52852.5 | K36: =$D36*G36 -> 54438.075 | L36: =$D36*H36 -> 463780.69 | M36: NON
A37: 3.3 | B37: Béton armé dosé à 350 kg/m³ pour chaînage intermédiaire 15 x 20 à +3,00 | C37: m³ | D37: =q_3_3 -> 2.0109 | E37: =SUMIFS('Sous-détails'!$H$5:$H$407,'Sous-détails'!$A$5:$A$407,"Art. "&$A37,'Sous-détails'!$B$5:$B$407,"Matériaux") -> 67450 | F37: =SUMIFS('Sous-détails'!$H$5:$H$407,'Sous-détails'!$A$5:$A$407,"Art. "&$A37,'Sous-détails'!$B$5:$B$407,"Main-d'œuvre") -> 8000 | G37: =SUMIFS('Sous-détails'!$H$5:$H$407,'Sous-détails'!$A$5:$A$407,"Art. "&$A37,'Sous-détails'!$B$5:$B$407,"Matériel") -> 8240 | H37: =E37+F37+G37 -> 83690 | I37: =$D37*E37 -> 135635.2 | J37: =$D37*F37 -> 16087.2 | K37: =$D37*G37 -> 16569.816 | L37: =$D37*H37 -> 168292.22 | M37: NON
A38: 3.4 | B38: Béton armé dosé à 350 kg/m³ pour chaînage haut 15 x 20 | C38: m³ | D38: =q_3_4 -> 2.1909 | E38: =SUMIFS('Sous-détails'!$H$5:$H$407,'Sous-détails'!$A$5:$A$407,"Art. "&$A38,'Sous-détails'!$B$5:$B$407,"Matériaux") -> 67450 | F38: =SUMIFS('Sous-détails'!$H$5:$H$407,'Sous-détails'!$A$5:$A$407,"Art. "&$A38,'Sous-détails'!$B$5:$B$407,"Main-d'œuvre") -> 8000 | G38: =SUMIFS('Sous-détails'!$H$5:$H$407,'Sous-détails'!$A$5:$A$407,"Art. "&$A38,'Sous-détails'!$B$5:$B$407,"Matériel") -> 8240 | H38: =E38+F38+G38 -> 83690 | I38: =$D38*E38 -> 147776.21 | J38: =$D38*F38 -> 17527.2 | K38: =$D38*G38 -> 18053.016 | L38: =$D38*H38 -> 183356.42 | M38: NON
A39: 3.5 | B39: Béton armé dosé à 350 kg/m³ pour linteau de l'entrée 15 x 40 | C39: m³ | D39: =q_3_5 -> 0.36 | E39: =SUMIFS('Sous-détails'!$H$5:$H$407,'Sous-détails'!$A$5:$A$407,"Art. "&$A39,'Sous-détails'!$B$5:$B$407,"Matériaux") -> 67450 | F39: =SUMIFS('Sous-détails'!$H$5:$H$407,'Sous-détails'!$A$5:$A$407,"Art. "&$A39,'Sous-détails'!$B$5:$B$407,"Main-d'œuvre") -> 10000 | G39: =SUMIFS('Sous-détails'!$H$5:$H$407,'Sous-détails'!$A$5:$A$407,"Art. "&$A39,'Sous-détails'!$B$5:$B$407,"Matériel") -> 10300 | H39: =E39+F39+G39 -> 87750 | I39: =$D39*E39 -> 24282 | J39: =$D39*F39 -> 3600 | K39: =$D39*G39 -> 3708 | L39: =$D39*H39 -> 31590 | M39: NON
A40: 3.6 | B40: Béton armé dosé à 350 kg/m³ pour chaînages rampants 15 x 15 (pente 20 %) | C40: m³ | D40: =q_3_6 -> 0.44091176 | E40: =SUMIFS('Sous-détails'!$H$5:$H$407,'Sous-détails'!$A$5:$A$407,"Art. "&$A40,'Sous-détails'!$B$5:$B$407,"Matériaux") -> 67450 | F40: =SUMIFS('Sous-détails'!$H$5:$H$407,'Sous-détails'!$A$5:$A$407,"Art. "&$A40,'Sous-détails'!$B$5:$B$407,"Main-d'œuvre") -> 10000 | G40: =SUMIFS('Sous-détails'!$H$5:$H$407,'Sous-détails'!$A$5:$A$407,"Art. "&$A40,'Sous-détails'!$B$5:$B$407,"Matériel") -> 10300 | H40: =E40+F40+G40 -> 87750 | I40: =$D40*E40 -> 29739.498 | J40: =$D40*F40 -> 4409.1176 | K40: =$D40*G40 -> 4541.3911 | L40: =$D40*H40 -> 38690.007 | M40: NON
A41: 3.7 | B41: Coffrage en bois ordinaire (poteaux, chaînages, linteau, rampants) | C41: m² | D41: =q_3_7 -> 173.30782 | E41: =SUMIFS('Sous-détails'!$H$5:$H$407,'Sous-détails'!$A$5:$A$407,"Art. "&$A41,'Sous-détails'!$B$5:$B$407,"Matériaux") -> 2125 | F41: =SUMIFS('Sous-détails'!$H$5:$H$407,'Sous-détails'!$A$5:$A$407,"Art. "&$A41,'Sous-détails'!$B$5:$B$407,"Main-d'œuvre") -> 1875 | G41: =SUMIFS('Sous-détails'!$H$5:$H$407,'Sous-détails'!$A$5:$A$407,"Art. "&$A41,'Sous-détails'!$B$5:$B$407,"Matériel") -> 56.25 | H41: =E41+F41+G41 -> 4056.25 | I41: =$D41*E41 -> 368279.12 | J41: =$D41*F41 -> 324952.17 | K41: =$D41*G41 -> 9748.5651 | L41: =$D41*H41 -> 702979.86 | M41: NON
A42: 3.8 | B42: Armatures HA10 FeE500 - élévation | C42: kg | D42: =q_3_8 -> 1202.7612 | E42: =SUMIFS('Sous-détails'!$H$5:$H$407,'Sous-détails'!$A$5:$A$407,"Art. "&$A42,'Sous-détails'!$B$5:$B$407,"Matériaux") -> 832.5 | F42: =SUMIFS('Sous-détails'!$H$5:$H$407,'Sous-détails'!$A$5:$A$407,"Art. "&$A42,'Sous-détails'!$B$5:$B$407,"Main-d'œuvre") -> 100 | G42: =SUMIFS('Sous-détails'!$H$5:$H$407,'Sous-détails'!$A$5:$A$407,"Art. "&$A42,'Sous-détails'!$B$5:$B$407,"Matériel") -> 3 | H42: =E42+F42+G42 -> 935.5 | I42: =$D42*E42 -> 1001298.7 | J42: =$D42*F42 -> 120276.12 | K42: =$D42*G42 -> 3608.2836 | L42: =$D42*H42 -> 1125183.1 | M42: NON
A43: 3.9 | B43: Armatures HA6 FeE500 - élévation | C43: kg | D43: =q_3_9 -> 316.54751 | E43: =SUMIFS('Sous-détails'!$H$5:$H$407,'Sous-détails'!$A$5:$A$407,"Art. "&$A43,'Sous-détails'!$B$5:$B$407,"Matériaux") -> 887.5 | F43: =SUMIFS('Sous-détails'!$H$5:$H$407,'Sous-détails'!$A$5:$A$407,"Art. "&$A43,'Sous-détails'!$B$5:$B$407,"Main-d'œuvre") -> 100 | G43: =SUMIFS('Sous-détails'!$H$5:$H$407,'Sous-détails'!$A$5:$A$407,"Art. "&$A43,'Sous-détails'!$B$5:$B$407,"Matériel") -> 3 | H43: =E43+F43+G43 -> 990.5 | I43: =$D43*E43 -> 280935.92 | J43: =$D43*F43 -> 31654.751 | K43: =$D43*G43 -> 949.64254 | L43: =$D43*H43 -> 313540.31 | M43: NON
B44: Sous-total déboursé sec lot 3 | I44: =SUM(I35:I43) -> 5261733.7 | J44: =SUM(J35:J43) -> 1132197.9 | K44: =SUM(K35:K43) -> 128441.96 | L44: =SUM(L35:L43) -> 6522373.6
...

Sheet DQE
A1: ASSEYA SILVER CONSTRUCTION - Construction métallique et bâtiment - Bouaké - Tél : 07 08 39 02 66 / 05 05 10 76 82 - Email : asseyasilver@gmail.com
A2: Devis quantitatif et estimatif - Bâtiment industriel 30,00 x 10,00 m - 04/10/2026 - établi par Moulo Jean Claude, Technicien Génie Civil BTP - BAEL 91 mod. 99 / EC2
A4: N° | B4: Désignation | C4: U | D4: Quantité | E4: P.U. HT (FCFA) | F4: Montant HT (FCFA) | G4: Option
A5: LOT 0 | B5: INSTALLATION DE CHANTIER ET TRAVAUX PRÉPARATOIRES
A6: 0.1 | B6: Installation et repli de chantier (magasin, clôture provisoire, eau, électricité, panneau) | C6: ft | D6: =q_0_1 -> 1 | E6: =ROUND('Déboursé sec'!H6*p_K/5,0)*5 -> 660190 | F6: =D6*E6 -> 660190 | G6: NON
A7: 0.2 | B7: Débroussaillage et décapage de la terre végétale ép. 10 cm | C7: m² | D7: =q_0_2 -> 476 | E7: =ROUND('Déboursé sec'!H7*p_K/5,0)*5 -> 115 | F7: =D7*E7 -> 54740 | G7: NON
A8: 0.3 | B8: Implantation du bâtiment (chaises, cordeaux, axes et niveaux) | C8: ft | D8: =q_0_3 -> 1 | E8: =ROUND('Déboursé sec'!H8*p_K/5,0)*5 -> 159470 | F8: =D8*E8 -> 159470 | G8: NON
B9: Sous-total lot 0 | F9: =SUM(F6:F8) -> 874400
A11: LOT 1 | B11: TERRASSEMENTS
A12: 1.1 | B12: Fouilles en rigole 0,60 x 1,20 m en terrain latéritique | C12: m³ | D12: =q_1_1 -> 57.6 | E12: =ROUND('Déboursé sec'!H12*p_K/5,0)*5 -> 4505 | F12: =D12*E12 -> 259488 | G12: NON
A13: 1.2 | B13: Fouilles en puits 1,00 x 1,00 x 1,20 m pour semelles isolées 80x80 (complément) | C13: m³ | D13: =q_1_2 -> 8.16 | E13: =ROUND('Déboursé sec'!H13*p_K/5,0)*5 -> 4505 | F13: =D13*E13 -> 36760.8 | G13: NON
A14: 1.3 | B14: Remblai des fouilles avec les terres extraites, compacté par couches de 20 cm | C14: m³ | D14: =q_1_3 -> 41.85525 | E14: =ROUND('Déboursé sec'!H14*p_K/5,0)*5 -> 3000 | F14: =D14*E14 -> 125565.75 | G14: NON
A15: 1.4 | B15: Évacuation des terres excédentaires des fouilles | C15: m³ | D15: =q_1_4 -> 29.880938 | E15: =ROUND('Déboursé sec'!H15*p_K/5,0)*5 -> 4635 | F15: =D15*E15 -> 138498.15 | G15: NON
A16: 1.5 | B16: Traitement anti-termites des fonds de fouilles | C16: m² | D16: =q_1_5 -> 54.8 | E16: =ROUND('Déboursé sec'!H16*p_K/5,0)*5 -> 1845 | F16: =D16*E16 -> 101106 | G16: NON
B17: Sous-total lot 1 | F17: =SUM(F12:F16) -> 661418.7
A19: LOT 2 | B19: FONDATIONS
A20: 2.1 | B20: Béton de propreté dosé à 150 kg/m³, ép. 5 cm | C20: m³ | D20: =q_2_1 -> 2.74 | E20: =ROUND('Déboursé sec'!H20*p_K/5,0)*5 -> 71400 | F20: =D20*E20 -> 195636 | G20: NON
A21: 2.2 | B21: Béton armé dosé à 350 kg/m³ pour semelles isolées 0,80 x 0,80 x 0,30 | C21: m³ | D21: =q_2_2 -> 3.264 | E21: =ROUND('Déboursé sec'!H21*p_K/5,0)*5 -> 109845 | F21: =D21*E21 -> 358534.08 | G21: NON
A22: 2.3 | B22: Béton armé dosé à 350 kg/m³ pour fûts 40 x 40 sous platines des IPE (de -0,85 à ±0,00) | C22: m³ | D22: =q_2_3 -> 2.312 | E22: =ROUND('Déboursé sec'!H22*p_K/5,0)*5 -> 115170 | F22: =D22*E22 -> 266273.04 | G22: NON
A23: 2.4 | B23: Fourniture et scellement des tiges d'ancrage M20 des IPE (gabarit de pose, 4 par pilier) | C23: u | D23: =q_2_4 -> 68 | E23: =ROUND('Déboursé sec'!H23*p_K/5,0)*5 -> 9800 | F23: =D23*E23 -> 666400 | G23: NON
A24: 2.5 | B24: Béton armé dosé à 350 kg/m³ pour semelle filante 0,40 x 0,15 | C24: m³ | D24: =q_2_5 -> 3.984 | E24: =ROUND('Déboursé sec'!H24*p_K/5,0)*5 -> 106290 | F24: =D24*E24 -> 423459.36 | G24: NON
A25: 2.6 | B25: Maçonnerie d'agglos 15 pleins en fondation h = 1,00 m, mortier dosé à 300 kg/m³ | C25: m² | D25: =q_2_6 -> 73.03 | E25: =ROUND('Déboursé sec'!H25*p_K/5,0)*5 -> 12270 | F25: =D25*E25 -> 896078.1 | G25: NON
A26: 2.7 | B26: Béton armé dosé à 350 kg/m³ pour chaînage bas 15 x 20 | C26: m³ | D26: =q_2_7 -> 2.1909 | E26: =ROUND('Déboursé sec'!H26*p_K/5,0)*5 -> 106290 | F26: =D26*E26 -> 232870.76 | G26: NON
A27: 2.8 | B27: Chape d'arase étanche (mortier dosé à 400 kg/m³ + hydrofuge) ép. 3 cm | C27: m² | D27: =q_2_8 -> 10.9545 | E27: =ROUND('Déboursé sec'!H27*p_K/5,0)*5 -> 5060 | F27: =D27*E27 -> 55429.77 | G27: NON
A28: 2.9 | B28: Coffrage en bois ordinaire (semelles isolées, fûts, chaînage bas) | C28: m² | D28: =q_2_9 -> 68.652 | E28: =ROUND('Déboursé sec'!H28*p_K/5,0)*5 -> 5325 | F28: =D28*E28 -> 365571.9 | G28: NON
A29: 2.10 | B29: Armatures HA12 FeE500 - semelles isolées 80x80 et fûts | C29: kg | D29: =q_2_10 -> 288.48456 | E29: =ROUND('Déboursé sec'!H29*p_K/5,0)*5 -> 1215 | F29: =D29*E29 -> 350508.74 | G29: NON
A30: 2.11 | B30: Armatures HA10 FeE500 - fondations | C30: kg | D30: =q_2_11 -> 445.7208 | E30: =ROUND('Déboursé sec'!H30*p_K/5,0)*5 -> 1230 | F30: =D30*E30 -> 548236.58 | G30: NON
A31: 2.12 | B31: Armatures HA6 FeE500 - fondations | C31: kg | D31: =q_2_12 -> 136.73646 | E31: =ROUND('Déboursé sec'!H31*p_K/5,0)*5 -> 1300 | F31: =D31*E31 -> 177757.4 | G31: NON
B32: Sous-total lot 2 | F32: =SUM(F20:F31) -> 4536755.7
A34: LOT 3 | B34: ÉLÉVATION (MAÇONNERIE ET BÉTON ARMÉ)
A35: 3.1 | B35: Maçonnerie d'agglos 15 pleins en élévation, mortier dosé à 300 kg/m³ (y compris pignons) | C35: m² | D35: =q_3_1 -> 373.89259 | E35: =ROUND('Déboursé sec'!H35*p_K/5,0)*5 -> 12270 | F35: =D35*E35 -> 4587662.1 | G35: NON
A36: 3.2 | B36: Béton armé dosé à 350 kg/m³ pour poteaux 15 x 15 (2 par pilier IPE), de -0,85 à +6,00 | C36: m³ | D36: =q_3_2 -> 5.28525 | E36: =ROUND('Déboursé sec'!H36*p_K/5,0)*5 -> 115170 | F36: =D36*E36 -> 608702.24 | G36: NON
A37: 3.3 | B37: Béton armé dosé à 350 kg/m³ pour chaînage intermédiaire 15 x 20 à +3,00 | C37: m³ | D37: =q_3_3 -> 2.0109 | E37: =ROUND('Déboursé sec'!H37*p_K/5,0)*5 -> 109845 | F37: =D37*E37 -> 220887.31 | G37: NON
A38: 3.4 | B38: Béton armé dosé à 350 kg/m³ pour chaînage haut 15 x 20 | C38: m³ | D38: =q_3_4 -> 2.1909 | E38: =ROUND('Déboursé sec'!H38*p_K/5,0)*5 -> 109845 | F38: =D38*E38 -> 240659.41 | G38: NON
A39: 3.5 | B39: Béton armé dosé à 350 kg/m³ pour linteau de l'entrée 15 x 40 | C39: m³ | D39: =q_3_5 -> 0.36 | E39: =ROUND('Déboursé sec'!H39*p_K/5,0)*5 -> 115170 | F39: =D39*E39 -> 41461.2 | G39: NON
A40: 3.6 | B40: Béton armé dosé à 350 kg/m³ pour chaînages rampants 15 x 15 (pente 20 %) | C40: m³ | D40: =q_3_6 -> 0.44091176 | E40: =ROUND('Déboursé sec'!H40*p_K/5,0)*5 -> 115170 | F40: =D40*E40 -> 50779.807 | G40: NON
A41: 3.7 | B41: Coffrage en bois ordinaire (poteaux, chaînages, linteau, rampants) | C41: m² | D41: =q_3_7 -> 173.30782 | E41: =ROUND('Déboursé sec'!H41*p_K/5,0)*5 -> 5325 | F41: =D41*E41 -> 922864.16 | G41: NON
A42: 3.8 | B42: Armatures HA10 FeE500 - élévation | C42: kg | D42: =q_3_8 -> 1202.7612 | E42: =ROUND('Déboursé sec'!H42*p_K/5,0)*5 -> 1230 | F42: =D42*E42 -> 1479396.3 | G42: NON
A43: 3.9 | B43: Armatures HA6 FeE500 - élévation | C43: kg | D43: =q_3_9 -> 316.54751 | E43: =ROUND('Déboursé sec'!H43*p_K/5,0)*5 -> 1300 | F43: =D43*E43 -> 411511.77 | G43: NON
B44: Sous-total lot 3 | F44: =SUM(F35:F43) -> 8563924.3
...

Sheet Matériaux et MO
A1: ASSEYA SILVER CONSTRUCTION - Construction métallique et bâtiment - Bouaké - Tél : 07 08 39 02 66 / 05 05 10 76 82 - Email : asseyasilver@gmail.com
A2: Besoins en matériaux, main-d'œuvre et matériel - Bâtiment industriel 30,00 x 10,00 m - 04/10/2026 - établi par Moulo Jean Claude, Technicien Génie Civil BTP - BAEL 91 mod. 99 / EC2
A4: Code | B4: Désignation | C4: U | D4: Qté gros œuvre | E4: Qté avec options | F4: P.U. (FCFA) | G4: Montant gros œuvre | H4: Montant avec options | I4: Observation
A5: MATÉRIAUX
A6: ciment | B6: Ciment CPJ 42,5 (sac 50 kg) | C6: sac | D6: =SUMIFS('Sous-détails'!$J$5:$J$407,'Sous-détails'!$D$5:$D$407,A6,'Sous-détails'!$K$5:$K$407,"NON") -> 643.791 | E6: =SUMIFS('Sous-détails'!$J$5:$J$407,'Sous-détails'!$D$5:$D$407,A6) -> 764.2022 | F6: =px_ciment -> 5800 | G6: =D6*F6 -> 3733987.8 | H6: =E6*F6 -> 4432372.8 | I6: =ROUND(D6*50/1000,1)&" t (gros œuvre)" -> 32.2 t (gros œuvre)
A7: sable | B7: Sable lavé | C7: m³ | D7: =SUMIFS('Sous-détails'!$J$5:$J$407,'Sous-détails'!$D$5:$D$407,A7,'Sous-détails'!$K$5:$K$407,"NON") -> 51.414552 | E7: =SUMIFS('Sous-détails'!$J$5:$J$407,'Sous-détails'!$D$5:$D$407,A7) -> 74.570552 | F7: =px_sable -> 12000 | G7: =D7*F7 -> 616974.63 | H7: =E7*F7 -> 894846.63
A8: gravier | B8: Gravier concassé 5/15 - 15/25 | C8: m³ | D8: =SUMIFS('Sous-détails'!$J$5:$J$407,'Sous-détails'!$D$5:$D$407,A8,'Sous-détails'!$K$5:$K$407,"NON") -> 71.045857 | E8: =SUMIFS('Sous-détails'!$J$5:$J$407,'Sous-détails'!$D$5:$D$407,A8) -> 71.045857 | F8: =px_gravier -> 25000 | G8: =D8*F8 -> 1776146.4 | H8: =E8*F8 -> 1776146.4
A9: eau | B9: Eau | C9: m³ | D9: =SUMIFS('Sous-détails'!$J$5:$J$407,'Sous-détails'!$D$5:$D$407,A9,'Sous-détails'!$K$5:$K$407,"NON") -> 32.946798 | E9: =SUMIFS('Sous-détails'!$J$5:$J$407,'Sous-détails'!$D$5:$D$407,A9) -> 42.209198 | F9: =px_eau -> 1000 | G9: =D9*F9 -> 32946.798 | H9: =E9*F9 -> 42209.198
A10: agglo | B10: Agglo 15 plein 40x20x15 rendu chantier | C10: u | D10: =SUMIFS('Sous-détails'!$J$5:$J$407,'Sous-détails'!$D$5:$D$407,A10,'Sous-détails'!$K$5:$K$407,"NON") -> 5865.859 | E10: =SUMIFS('Sous-détails'!$J$5:$J$407,'Sous-détails'!$D$5:$D$407,A10) -> 5865.859 | F10: =px_agglo -> 500 | G10: =D10*F10 -> 2932929.5 | H10: =E10*F10 -> 2932929.5 | I10: =ROUNDUP(D10,0)&" agglos (GO)" -> 5866 agglos (GO)
