Workbook

Sheet BPU
A1: REPUBLIQUE DE CÔTE D'IVOIRE — Union - Discipline - Travail
A2: REGION DE LA MÉ — MAIRIE D'ALÉPÉ
A3: Appel d'Offres Ouvert AOO N° T ....../2026 — Financement : Budget d'investissement 2026, Ligne 9101/2220
A4: BORDEREAU DES PRIX UNITAIRES (BPU)
A5: Réalisation de 1700 mètres linéaires de bitume du quartier Château au quartier Comoé extension d'Alépé
A6: Proposition de prix établie par : MOULO Jean Claude, Technicien Génie Civil BTP — Abidjan, septembre 2026 — Montants en FCFA HT
A8: N° | B8: DÉSIGNATION | C8: U | D8: QTÉ (DAO) | E8: PRIX UNIT. EN CHIFFRES (FCFA HT) | F8: PRIX UNIT. EN LETTRES
A9: 000 | B9: Section 0 - Installation de chantier
A10: 001 | B10: Installation de chantier de l'entreprise | C10: Ft | D10: 1 | E10: 12000000 | F10: Douze millions de francs CFA
A11: 100 | B11: Section 1 - Dégagement des emprises
A12: 101 | B12: Dégagement des accotements | C12: m2 | D12: 3000 | E12: 500 | F12: Cinq cents francs CFA
A13: 102 | B13: Dégagement des ordures ménagères | C13: Ft | D13: 1 | E13: 2500000 | F13: Deux millions cinq cent mille francs CFA
A14: 200 | B14: Section 2 - Terrassements généraux
A15: 201 | B15: Remblais provenant d'emprunts y compris distance de transport | C15: m2 | D15: 0 | E15: 6500 | F15: Six mille cinq cents francs CFA
A16: 202 | B16: Démantèlement et enlèvement de dépôt | C16: Ft | D16: 1 | E16: 2000000 | F16: Deux millions de francs CFA
A17: 203 | B17: Décaissement et compactage du fond de décaissement | C17: m2 | D17: 18214 | E17: 1200 | F17: Mille deux cents francs CFA
A18: 300 | B18: Section 3 - Chaussée
B19: Fourniture et mise en œuvre de matériaux graveleux naturels sélectionnés quelle que soit la distance de transport
A20: 301 | B20: Pour la couche de forme (sous-couche de fondation) | C20: m2 | D20: 0 | E20: 3000 | F20: Trois mille francs CFA
A21: 302 | B21: Pour la couche de fondation (ép. 15 cm) | C21: m2 | D21: 0 | E21: 2500 | F21: Deux mille cinq cents francs CFA
A22: 303 | B22: Stabilisation au ciment 4 % de la couche de base | C22: m2 | D22: 0 | E22: 3500 | F22: Trois mille cinq cents francs CFA
A23: 304 | B23: Fourniture, transport et mise en œuvre de granite concassé 0/31,5 pour la couche de base | C23: m2 | D23: 2732.1 | E23: 35000 | F23: Trente-cinq mille francs CFA
A24: 305 | B24: Exécution de l'imprégnation au cut-back de la couche de base (1,2 kg/m2) | C24: m2 | D24: 18214 | E24: 900 | F24: Neuf cents francs CFA
A25: 306 | B25: Couche d'accrochage à l'émulsion de bitume (300 g/m2) | C25: m2 | D25: 18214 | E25: 400 | F25: Quatre cents francs CFA
B26: Fourniture, fabrication et mise en œuvre de revêtement de chaussée en béton bitumineux quelle que soit la distance de transport
A27: 307 | B27: Béton bitumineux d'épaisseur 3 cm | C27: m2 | D27: 5795 | E27: 7000 | F27: Sept mille francs CFA
A28: 308 | B28: Béton bitumineux d'épaisseur 5 cm | C28: m2 | D28: 18214 | E28: 11500 | F28: Onze mille cinq cents francs CFA
A29: 400 | B29: Section 4 - Assainissement - Drainage
A30: 401 | B30: Fourniture, transport et mise en œuvre de buses en béton armé série 90 A Ø 1000, y compris têtes et remblais d'accès | C30: ml | D30: 24 | E30: 250000 | F30: Deux cent cinquante mille francs CFA
A31: 402 | B31: Curage d'ouvrage sanitaire | C31: Ft | D31: 0 | E31: 1500000 | F31: Un million cinq cent mille francs CFA
A32: 700 | B32: Section 7 - Protection de l'environnement
A33: 701 | B33: Régénérescence des zones d'emprunts | C33: m2 | D33: 0 | E33: 300 | F33: Trois cents francs CFA
A35: Légende : cellules jaunes / texte bleu = prix unitaires proposés (saisie). Le DQE est lié automatiquement à ces prix. Si un prix est modifié, mettre à jour le prix en lettres (colonne F).

Sheet DQE
A1: REPUBLIQUE DE CÔTE D'IVOIRE — Union - Discipline - Travail
A2: REGION DE LA MÉ — MAIRIE D'ALÉPÉ
A3: Appel d'Offres Ouvert AOO N° T ....../2026 — Financement : Budget d'investissement 2026, Ligne 9101/2220
A4: DEVIS QUANTITATIF ET ESTIMATIF (DQE)
A5: Réalisation de 1700 mètres linéaires de bitume du quartier Château au quartier Comoé extension d'Alépé
A6: Proposition de prix établie par : MOULO Jean Claude, Technicien Génie Civil BTP — Abidjan, septembre 2026 — Montants en FCFA HT
A8: N° | B8: DÉSIGNATION | C8: UNITÉS | D8: QUANTITÉS | E8: PRIX UNIT. (FCFA HT) | F8: PRIX TOTAL (FCFA HT)
A9: 000 | B9: Section 0 - Installation de chantier
A10: 001 | B10: Installation de chantier de l'entreprise | C10: Ft | D10: 1 | E10: =BPU!$E$10 -> 12000000 | F10: =ROUND(D10*E10,0) -> 12000000
B11: Total Section 0 | F11: =SUM(F10:F10) -> 12000000
A12: 100 | B12: Section 1 - Dégagement des emprises
A13: 101 | B13: Dégagement des accotements | C13: m2 | D13: 3000 | E13: =BPU!$E$12 -> 500 | F13: =ROUND(D13*E13,0) -> 1500000
A14: 102 | B14: Dégagement des ordures ménagères | C14: Ft | D14: 1 | E14: =BPU!$E$13 -> 2500000 | F14: =ROUND(D14*E14,0) -> 2500000
B15: Total Section 1 | F15: =SUM(F13:F14) -> 4000000
A16: 200 | B16: Section 2 - Terrassements généraux
A17: 201 | B17: Remblais provenant d'emprunts y compris distance de transport | C17: m2 | D17: 0 | E17: =BPU!$E$15 -> 6500 | F17: =ROUND(D17*E17,0) -> 0
A18: 202 | B18: Démantèlement et enlèvement de dépôt | C18: Ft | D18: 1 | E18: =BPU!$E$16 -> 2000000 | F18: =ROUND(D18*E18,0) -> 2000000
A19: 203 | B19: Décaissement et compactage du fond de décaissement | C19: m2 | D19: 18214 | E19: =BPU!$E$17 -> 1200 | F19: =ROUND(D19*E19,0) -> 21856800
B20: Total Section 2 | F20: =SUM(F17:F19) -> 23856800
A21: 300 | B21: Section 3 - Chaussée
B22: Fourniture et mise en œuvre de matériaux graveleux naturels sélectionnés quelle que soit la distance de transport
A23: 301 | B23: Pour la couche de forme (sous-couche de fondation) | C23: m2 | D23: 0 | E23: =BPU!$E$20 -> 3000 | F23: =ROUND(D23*E23,0) -> 0
A24: 302 | B24: Pour la couche de fondation (ép. 15 cm) | C24: m2 | D24: 0 | E24: =BPU!$E$21 -> 2500 | F24: =ROUND(D24*E24,0) -> 0
A25: 303 | B25: Stabilisation au ciment 4 % de la couche de base | C25: m2 | D25: 0 | E25: =BPU!$E$22 -> 3500 | F25: =ROUND(D25*E25,0) -> 0
A26: 304 | B26: Fourniture, transport et mise en œuvre de granite concassé 0/31,5 pour la couche de base | C26: m2 | D26: 2732.1 | E26: =BPU!$E$23 -> 35000 | F26: =ROUND(D26*E26,0) -> 95623500
A27: 305 | B27: Exécution de l'imprégnation au cut-back de la couche de base (1,2 kg/m2) | C27: m2 | D27: 18214 | E27: =BPU!$E$24 -> 900 | F27: =ROUND(D27*E27,0) -> 16392600
A28: 306 | B28: Couche d'accrochage à l'émulsion de bitume (300 g/m2) | C28: m2 | D28: 18214 | E28: =BPU!$E$25 -> 400 | F28: =ROUND(D28*E28,0) -> 7285600
B29: Fourniture, fabrication et mise en œuvre de revêtement de chaussée en béton bitumineux quelle que soit la distance de transport
A30: 307 | B30: Béton bitumineux d'épaisseur 3 cm | C30: m2 | D30: 5795 | E30: =BPU!$E$27 -> 7000 | F30: =ROUND(D30*E30,0) -> 40565000
A31: 308 | B31: Béton bitumineux d'épaisseur 5 cm | C31: m2 | D31: 18214 | E31: =BPU!$E$28 -> 11500 | F31: =ROUND(D31*E31,0) -> 209461000
B32: Total Section 3 | F32: =SUM(F22:F31) -> 369327700
A33: 400 | B33: Section 4 - Assainissement - Drainage
A34: 401 | B34: Fourniture, transport et mise en œuvre de buses en béton armé série 90 A Ø 1000, y compris têtes et remblais d'accès | C34: ml | D34: 24 | E34: =BPU!$E$30 -> 250000 | F34: =ROUND(D34*E34,0) -> 6000000
A35: 402 | B35: Curage d'ouvrage sanitaire | C35: Ft | D35: 0 | E35: =BPU!$E$31 -> 1500000 | F35: =ROUND(D35*E35,0) -> 0
B36: Total Section 4 | F36: =SUM(F34:F35) -> 6000000
A37: 700 | B37: Section 7 - Protection de l'environnement
A38: 701 | B38: Régénérescence des zones d'emprunts | C38: m2 | D38: 0 | E38: =BPU!$E$33 -> 300 | F38: =ROUND(D38*E38,0) -> 0
B39: Total Section 7 | F39: =SUM(F38:F38) -> 0
A41: RÉCAPITULATIF PAR SECTION
A42: Section 000 Installation | F42: =F11 -> 12000000
...

Sheet Hypothèses
B1: HYPOTHÈSES DE PRIX ET CONTRÔLES — DAO Mairie d'Alépé 2026
B2: Auteur : Moulo Jean Claude, Technicien Génie Civil BTP — Abidjan, 24/09/2026
B4: Paramètres
B5: Délai d'exécution (DPAO IC 13.2) | C5: 12 mois
B6: Taux de TVA (DAO) | C6: 0.18
B7: Montant total HT proposé | C7: =DQE!$F$48 -> 415184500
B8: Montant total TTC proposé | C8: =DQE!$F$50 -> 489917710
B9: Montant TTC en lettres (contrôle) | C9: Quatre cent quatre-vingt-neuf millions neuf cent dix-sept mille sept cent dix francs CFA TTC
B10: Garantie d'offre exigée (DPAO IC 20.2) | C10: 4200000
B11: Ratio garantie / montant HT | C11: =C10/C7 -> 0.010115985
B12: Coût HT au mètre linéaire (1 700 ml) | C12: =C7/1700 -> 244226.18
B13: Coût HT au m2 de chaussée revêtue (18 214 m2) | C13: =C7/18214 -> 22794.801
B15: Bases de prix (marché ivoirien, septembre 2026, prix HT rendus Alépé ≈ 55 km d'Abidjan) :
B16: • Béton bitumineux (BB) : ≈ 95 000 à 100 000 FCFA/t mis en œuvre (bitume 50/70 importé, granulats granite, centrale d'enrobage Abidjan), densité 2,35 t/m3.
B17: • Granite concassé 0/31,5 (GNT) : ≈ 17 000 FCFA/t carrière + transport ≈ 55 km + mise en œuvre et compactage 95 % OPM → ≈ 35 000 FCFA/m3 compacté.
B18: • Cut-back 0/1 : 1,2 kg/m2 ; émulsion ECR 65 : 0,3 kg/m2 (répandeuse + balayage).
B19: • Sol support latéritique : fond de décaissement compacté à 95 % OPM, CBR plate-forme ≥ 15 à vérifier par essais (Proctor modifié, CBR 96 h imbibition).
B20: • Contexte climatique tropical humide (Sud-Est, deux saisons des pluies) : planning à caler hors mai-juillet pour les enrobés ; drainage provisoire inclus dans les prix.
B21: • Prix fermes et non révisables (DPAO IC 14.5) : aléas de variation bitume/carburant intégrés (≈ 3 %). Frais généraux ≈ 15 % et bénéfice ≈ 10 % inclus.
B23: Incohérences relevées dans le DAO (à signaler par demande d'éclaircissement — IC 7.1) :
B24: 1. Poste 304 (granite concassé) : unité « m2 » mais 2 732,10 = 18 214 × 0,15 → il s'agit de m3. Prix établi au m3.
B25: 2. Poste 305 : « 1200 kg/m3 » → dosage à lire 1,2 kg/m2. Poste 306 : « 300 g/m3 » → lire 300 g/m2.
B26: 3. Postes 201 (remblais) et 303 (stabilisation ciment 4 %) : quantités non renseignées → portées à 0, prix donnés pour mémoire.
B27: 4. Postes 301, 302, 402, 701 : quantités nulles au DAO → prix donnés pour mémoire (IC 14 : tous les postes doivent être prix).
... B32: L'offre est jugée par rapport à l'estimation administrative confidentielle et à la moyenne des offres (seuils anormalement bas/élevés) — éviter les écarts extrêmes.
